package mods.jameslfc19.forest.world;

import java.util.Random;

import cpw.mods.fml.common.IWorldGenerator;

import mods.jameslfc19.forest.JamesForest;
import net.minecraft.block.Block;
import net.minecraft.tileentity.TileEntityChest;
import net.minecraft.tileentity.TileEntityMobSpawner;
import net.minecraft.util.WeightedRandomChestContent;
import net.minecraft.world.World;
import net.minecraft.world.chunk.IChunkProvider;
import net.minecraftforge.common.ChestGenHooks;
import net.minecraftforge.common.DungeonHooks;

public class WorldGenMysticalDungeon implements IWorldGenerator{
	
	public int spawnRateNumerator = 1;
	public int spawnRateDenominator = 300;
	
	public void generate(Random random, int chunkX, int chunkZ, World world, IChunkProvider chunkGenerator, IChunkProvider chunkProvider) {
		
		int chunkYMin = 7;
	    int chunkYMax = 40;
	   
	    int i = chunkX*16 + random.nextInt(16);
	    int chunkYrandom = chunkYMax - chunkYMin;
	    int j = chunkYMin + random.nextInt(chunkYrandom);
	    int k = chunkZ*16 + random.nextInt(16);
	    
	    boolean randomDecide = random.nextInt(spawnRateDenominator) == spawnRateNumerator;
	    
	    if(randomDecide){
	    	System.out.println("New Dungeon at "+i+" "+j+" "+k);
		world.setBlock(i + 0, j + 0, k + 0, JamesForest.superStone.blockID);
		world.setBlock(i + 0, j + 0, k + 1, JamesForest.superStone.blockID);
		world.setBlock(i + 0, j + 0, k + 2, JamesForest.superStone.blockID);
		world.setBlock(i + 0, j + 0, k + 3, JamesForest.superStone.blockID);
		world.setBlock(i + 0, j + 0, k + 4, JamesForest.superStone.blockID);
		world.setBlock(i + 0, j + 0, k + 5, JamesForest.superStone.blockID);
		world.setBlock(i + 0, j + 0, k + 6, JamesForest.superStone.blockID);
		world.setBlock(i + 0, j + 0, k + 7, JamesForest.superStone.blockID);
		world.setBlock(i + 0, j + 0, k + 8, JamesForest.superStone.blockID);
		world.setBlock(i + 0, j + 0, k + 9, JamesForest.superStone.blockID);
		world.setBlock(i + 0, j + 0, k + 10, JamesForest.superStone.blockID);
		world.setBlock(i + 0, j + 1, k + 0, JamesForest.superStone.blockID);
		world.setBlock(i + 0, j + 1, k + 1, JamesForest.superStone.blockID);
		world.setBlock(i + 0, j + 1, k + 2, JamesForest.superStone.blockID);
		world.setBlock(i + 0, j + 1, k + 3, JamesForest.superStone.blockID);
		world.setBlock(i + 0, j + 1, k + 4, JamesForest.superStone.blockID);
		world.setBlock(i + 0, j + 1, k + 5, JamesForest.superStone.blockID);
		world.setBlock(i + 0, j + 1, k + 6, JamesForest.superStone.blockID);
		world.setBlock(i + 0, j + 1, k + 7, JamesForest.superStone.blockID);
		world.setBlock(i + 0, j + 1, k + 8, JamesForest.superStone.blockID);
		world.setBlock(i + 0, j + 1, k + 9, JamesForest.superStone.blockID);
		world.setBlock(i + 0, j + 1, k + 10, JamesForest.superStone.blockID);
		world.setBlock(i + 0, j + 2, k + 0, JamesForest.superStone.blockID);
		world.setBlock(i + 0, j + 2, k + 1, JamesForest.superStone.blockID);
		world.setBlock(i + 0, j + 2, k + 2, JamesForest.superStone.blockID);
		world.setBlock(i + 0, j + 2, k + 3, JamesForest.superStone.blockID);
		world.setBlock(i + 0, j + 2, k + 4, JamesForest.superStone.blockID);
		world.setBlock(i + 0, j + 2, k + 5, JamesForest.superStone.blockID);
		world.setBlock(i + 0, j + 2, k + 6, JamesForest.superStone.blockID);
		world.setBlock(i + 0, j + 2, k + 7, JamesForest.superStone.blockID);
		world.setBlock(i + 0, j + 2, k + 8, JamesForest.superStone.blockID);
		world.setBlock(i + 0, j + 2, k + 9, JamesForest.superStone.blockID);
		world.setBlock(i + 0, j + 2, k + 10, JamesForest.superStone.blockID);
		world.setBlock(i + 0, j + 3, k + 0, JamesForest.superStone.blockID);
		world.setBlock(i + 0, j + 3, k + 1, JamesForest.superStone.blockID);
		world.setBlock(i + 0, j + 3, k + 2, JamesForest.superStone.blockID);
		world.setBlock(i + 0, j + 3, k + 3, JamesForest.superStone.blockID);
		world.setBlock(i + 0, j + 3, k + 4, JamesForest.superStone.blockID);
		world.setBlock(i + 0, j + 3, k + 5, JamesForest.superStone.blockID);
		world.setBlock(i + 0, j + 3, k + 6, JamesForest.superStone.blockID);
		world.setBlock(i + 0, j + 3, k + 7, JamesForest.superStone.blockID);
		world.setBlock(i + 0, j + 3, k + 8, JamesForest.superStone.blockID);
		world.setBlock(i + 0, j + 3, k + 9, JamesForest.superStone.blockID);
		world.setBlock(i + 0, j + 3, k + 10, JamesForest.superStone.blockID);
		world.setBlock(i + 0, j + 4, k + 0, JamesForest.superStone.blockID);
		world.setBlock(i + 0, j + 4, k + 1, JamesForest.superStone.blockID);
		world.setBlock(i + 0, j + 4, k + 2, JamesForest.superStone.blockID);
		world.setBlock(i + 0, j + 4, k + 3, JamesForest.superStone.blockID);
		world.setBlock(i + 0, j + 4, k + 4, JamesForest.superStone.blockID);
		world.setBlock(i + 0, j + 4, k + 5, JamesForest.superStone.blockID);
		world.setBlock(i + 0, j + 4, k + 6, JamesForest.superStone.blockID);
		world.setBlock(i + 0, j + 4, k + 7, JamesForest.superStone.blockID);
		world.setBlock(i + 0, j + 4, k + 8, JamesForest.superStone.blockID);
		world.setBlock(i + 0, j + 4, k + 9, JamesForest.superStone.blockID);
		world.setBlock(i + 0, j + 4, k + 10, JamesForest.superStone.blockID);
		world.setBlock(i + 0, j + 5, k + 0, JamesForest.superStone.blockID);
		world.setBlock(i + 0, j + 5, k + 1, JamesForest.superStone.blockID);
		world.setBlock(i + 0, j + 5, k + 2, JamesForest.superStone.blockID);
		world.setBlock(i + 0, j + 5, k + 3, JamesForest.superStone.blockID);
		world.setBlock(i + 0, j + 5, k + 4, JamesForest.superStone.blockID);
		world.setBlock(i + 0, j + 5, k + 5, JamesForest.superStone.blockID);
		world.setBlock(i + 0, j + 5, k + 6, JamesForest.superStone.blockID);
		world.setBlock(i + 0, j + 5, k + 7, JamesForest.superStone.blockID);
		world.setBlock(i + 0, j + 5, k + 8, JamesForest.superStone.blockID);
		world.setBlock(i + 0, j + 5, k + 9, JamesForest.superStone.blockID);
		world.setBlock(i + 0, j + 5, k + 10, JamesForest.superStone.blockID);
		world.setBlock(i + 1, j + 0, k + 0, JamesForest.superStone.blockID);
		world.setBlock(i + 1, j + 0, k + 1, JamesForest.superStone.blockID);
		world.setBlock(i + 1, j + 0, k + 2, JamesForest.superStone.blockID);
		world.setBlock(i + 1, j + 0, k + 3, JamesForest.superStone.blockID);
		world.setBlock(i + 1, j + 0, k + 4, JamesForest.superStone.blockID);
		world.setBlock(i + 1, j + 0, k + 5, JamesForest.superStone.blockID);
		world.setBlock(i + 1, j + 0, k + 6, JamesForest.superStone.blockID);
		world.setBlock(i + 1, j + 0, k + 7, JamesForest.superStone.blockID);
		world.setBlock(i + 1, j + 0, k + 8, JamesForest.superStone.blockID);
		world.setBlock(i + 1, j + 0, k + 9, JamesForest.superStone.blockID);
		world.setBlock(i + 1, j + 0, k + 10, JamesForest.superStone.blockID);
		world.setBlock(i + 1, j + 1, k + 0, JamesForest.superStone.blockID);
		world.setBlock(i + 1, j + 1, k + 1, 0);
		world.setBlock(i + 1, j + 1, k + 2, 0);
		world.setBlock(i + 1, j + 1, k + 3, 0);
		world.setBlock(i + 1, j + 1, k + 4, 0);
		world.setBlock(i + 1, j + 1, k + 5, Block.chest.blockID, 5, 0);
		world.setBlock(i + 1, j + 1, k + 6, 0);
		world.setBlock(i + 1, j + 1, k + 7, 0);
		world.setBlock(i + 1, j + 1, k + 8, 0);
		world.setBlock(i + 1, j + 1, k + 9, 0);
		world.setBlock(i + 1, j + 1, k + 10, JamesForest.superStone.blockID);
		world.setBlock(i + 1, j + 2, k + 0, JamesForest.superStone.blockID);
		world.setBlock(i + 1, j + 2, k + 1, 0);
		world.setBlock(i + 1, j + 2, k + 2, 0);
		world.setBlock(i + 1, j + 2, k + 3, 0);
		world.setBlock(i + 1, j + 2, k + 4, 0);
		world.setBlock(i + 1, j + 2, k + 6, 0);
		world.setBlock(i + 1, j + 2, k + 7, 0);
		world.setBlock(i + 1, j + 2, k + 8, 0);
		world.setBlock(i + 1, j + 2, k + 9, 0);
		world.setBlock(i + 1, j + 2, k + 10, JamesForest.superStone.blockID);
		world.setBlock(i + 1, j + 3, k + 0, JamesForest.superStone.blockID);
		world.setBlock(i + 1, j + 3, k + 1, 0);
		world.setBlock(i + 1, j + 3, k + 2, 0);
		world.setBlock(i + 1, j + 3, k + 3, 0);
		world.setBlock(i + 1, j + 3, k + 4, 0);
		world.setBlock(i + 1, j + 3, k + 5, 0);
		world.setBlock(i + 1, j + 3, k + 6, 0);
		world.setBlock(i + 1, j + 3, k + 7, 0);
		world.setBlock(i + 1, j + 3, k + 8, 0);
		world.setBlock(i + 1, j + 3, k + 9, 0);
		world.setBlock(i + 1, j + 3, k + 10, JamesForest.superStone.blockID);
		world.setBlock(i + 1, j + 4, k + 0, JamesForest.superStone.blockID);
		world.setBlock(i + 1, j + 4, k + 1, 0);
		world.setBlock(i + 1, j + 4, k + 2, 0);
		world.setBlock(i + 1, j + 4, k + 3, 0);
		world.setBlock(i + 1, j + 4, k + 4, 0);
		world.setBlock(i + 1, j + 4, k + 5, 0);
		world.setBlock(i + 1, j + 4, k + 6, 0);
		world.setBlock(i + 1, j + 4, k + 7, 0);
		world.setBlock(i + 1, j + 4, k + 8, 0);
		world.setBlock(i + 1, j + 4, k + 9, 0);
		world.setBlock(i + 1, j + 4, k + 10, JamesForest.superStone.blockID);
		world.setBlock(i + 1, j + 5, k + 0, JamesForest.superStone.blockID);
		world.setBlock(i + 1, j + 5, k + 1, JamesForest.superStone.blockID);
		world.setBlock(i + 1, j + 5, k + 2, JamesForest.superStone.blockID);
		world.setBlock(i + 1, j + 5, k + 3, JamesForest.superStone.blockID);
		world.setBlock(i + 1, j + 5, k + 4, JamesForest.superStone.blockID);
		world.setBlock(i + 1, j + 5, k + 5, JamesForest.superStone.blockID);
		world.setBlock(i + 1, j + 5, k + 6, JamesForest.superStone.blockID);
		world.setBlock(i + 1, j + 5, k + 7, JamesForest.superStone.blockID);
		world.setBlock(i + 1, j + 5, k + 8, JamesForest.superStone.blockID);
		world.setBlock(i + 1, j + 5, k + 9, JamesForest.superStone.blockID);
		world.setBlock(i + 1, j + 5, k + 10, JamesForest.superStone.blockID);
		world.setBlock(i + 2, j + 0, k + 0, JamesForest.superStone.blockID);
		world.setBlock(i + 2, j + 0, k + 1, JamesForest.superStone.blockID);
		world.setBlock(i + 2, j + 0, k + 2, JamesForest.superStone.blockID);
		world.setBlock(i + 2, j + 0, k + 3, JamesForest.superStone.blockID);
		world.setBlock(i + 2, j + 0, k + 4, JamesForest.superStone.blockID);
		world.setBlock(i + 2, j + 0, k + 5, JamesForest.superStone.blockID);
		world.setBlock(i + 2, j + 0, k + 6, JamesForest.superStone.blockID);
		world.setBlock(i + 2, j + 0, k + 7, JamesForest.superStone.blockID);
		world.setBlock(i + 2, j + 0, k + 8, JamesForest.superStone.blockID);
		world.setBlock(i + 2, j + 0, k + 9, JamesForest.superStone.blockID);
		world.setBlock(i + 2, j + 0, k + 10, JamesForest.superStone.blockID);
		world.setBlock(i + 2, j + 1, k + 0, JamesForest.superStone.blockID);
		world.setBlock(i + 2, j + 1, k + 1, 0);
		world.setBlock(i + 2, j + 1, k + 2, 0);
		world.setBlock(i + 2, j + 1, k + 3, 0);
		world.setBlock(i + 2, j + 1, k + 4, 0);
		world.setBlock(i + 2, j + 1, k + 5, 0);
		world.setBlock(i + 2, j + 1, k + 6, 0);
		world.setBlock(i + 2, j + 1, k + 7, 0);
		world.setBlock(i + 2, j + 1, k + 8, 0);
		world.setBlock(i + 2, j + 1, k + 9, 0);
		world.setBlock(i + 2, j + 1, k + 10, JamesForest.superStone.blockID);
		world.setBlock(i + 2, j + 2, k + 0, JamesForest.superStone.blockID);
		world.setBlock(i + 2, j + 2, k + 1, 0);
		world.setBlock(i + 2, j + 2, k + 2, 0);
		world.setBlock(i + 2, j + 2, k + 3, 0);
		world.setBlock(i + 2, j + 2, k + 4, 0);
		world.setBlock(i + 2, j + 2, k + 5, 0);
		world.setBlock(i + 2, j + 2, k + 6, 0);
		world.setBlock(i + 2, j + 2, k + 7, 0);
		world.setBlock(i + 2, j + 2, k + 8, 0);
		world.setBlock(i + 2, j + 2, k + 9, 0);
		world.setBlock(i + 2, j + 2, k + 10, JamesForest.superStone.blockID);
		world.setBlock(i + 2, j + 3, k + 0, JamesForest.superStone.blockID);
		world.setBlock(i + 2, j + 3, k + 1, 0);
		world.setBlock(i + 2, j + 3, k + 2, 0);
		world.setBlock(i + 2, j + 3, k + 3, 0);
		world.setBlock(i + 2, j + 3, k + 4, 0);
		world.setBlock(i + 2, j + 3, k + 5, 0);
		world.setBlock(i + 2, j + 3, k + 6, 0);
		world.setBlock(i + 2, j + 3, k + 7, 0);
		world.setBlock(i + 2, j + 3, k + 8, 0);
		world.setBlock(i + 2, j + 3, k + 9, 0);
		world.setBlock(i + 2, j + 3, k + 10, JamesForest.superStone.blockID);
		world.setBlock(i + 2, j + 4, k + 0, JamesForest.superStone.blockID);
		world.setBlock(i + 2, j + 4, k + 1, 0);
		world.setBlock(i + 2, j + 4, k + 2, 0);
		world.setBlock(i + 2, j + 4, k + 3, 0);
		world.setBlock(i + 2, j + 4, k + 4, 0);
		world.setBlock(i + 2, j + 4, k + 5, 0);
		world.setBlock(i + 2, j + 4, k + 6, 0);
		world.setBlock(i + 2, j + 4, k + 7, 0);
		world.setBlock(i + 2, j + 4, k + 8, 0);
		world.setBlock(i + 2, j + 4, k + 9, 0);
		world.setBlock(i + 2, j + 4, k + 10, JamesForest.superStone.blockID);
		world.setBlock(i + 2, j + 5, k + 0, JamesForest.superStone.blockID);
		world.setBlock(i + 2, j + 5, k + 1, JamesForest.superStone.blockID);
		world.setBlock(i + 2, j + 5, k + 2, JamesForest.superStone.blockID);
		world.setBlock(i + 2, j + 5, k + 3, JamesForest.superStone.blockID);
		world.setBlock(i + 2, j + 5, k + 4, JamesForest.superStone.blockID);
		world.setBlock(i + 2, j + 5, k + 5, JamesForest.superStone.blockID);
		world.setBlock(i + 2, j + 5, k + 6, JamesForest.superStone.blockID);
		world.setBlock(i + 2, j + 5, k + 7, JamesForest.superStone.blockID);
		world.setBlock(i + 2, j + 5, k + 8, JamesForest.superStone.blockID);
		world.setBlock(i + 2, j + 5, k + 9, JamesForest.superStone.blockID);
		world.setBlock(i + 2, j + 5, k + 10, JamesForest.superStone.blockID);
		world.setBlock(i + 3, j + 0, k + 0, JamesForest.superStone.blockID);
		world.setBlock(i + 3, j + 0, k + 1, JamesForest.superStone.blockID);
		world.setBlock(i + 3, j + 0, k + 2, JamesForest.superStone.blockID);
		world.setBlock(i + 3, j + 0, k + 3, JamesForest.superStone.blockID);
		world.setBlock(i + 3, j + 0, k + 4, JamesForest.superStone.blockID);
		world.setBlock(i + 3, j + 0, k + 5, JamesForest.superStone.blockID);
		world.setBlock(i + 3, j + 0, k + 6, JamesForest.superStone.blockID);
		world.setBlock(i + 3, j + 0, k + 7, JamesForest.superStone.blockID);
		world.setBlock(i + 3, j + 0, k + 8, JamesForest.superStone.blockID);
		world.setBlock(i + 3, j + 0, k + 9, JamesForest.superStone.blockID);
		world.setBlock(i + 3, j + 0, k + 10, JamesForest.superStone.blockID);
		world.setBlock(i + 3, j + 1, k + 0, JamesForest.superStone.blockID);
		world.setBlock(i + 3, j + 1, k + 1, 0);
		world.setBlock(i + 3, j + 1, k + 2, 0);
		world.setBlock(i + 3, j + 1, k + 3, 0);
		world.setBlock(i + 3, j + 1, k + 4, 0);
		world.setBlock(i + 3, j + 1, k + 5, 0);
		world.setBlock(i + 3, j + 1, k + 6, 0);
		world.setBlock(i + 3, j + 1, k + 7, 0);
		world.setBlock(i + 3, j + 1, k + 8, 0);
		world.setBlock(i + 3, j + 1, k + 9, 0);
		world.setBlock(i + 3, j + 1, k + 10, JamesForest.superStone.blockID);
		world.setBlock(i + 3, j + 2, k + 0, JamesForest.superStone.blockID);
		world.setBlock(i + 3, j + 2, k + 1, 0);
		world.setBlock(i + 3, j + 2, k + 2, 0);
		world.setBlock(i + 3, j + 2, k + 3, 0);
		world.setBlock(i + 3, j + 2, k + 4, 0);
		world.setBlock(i + 3, j + 2, k + 5, 0);
		world.setBlock(i + 3, j + 2, k + 6, 0);
		world.setBlock(i + 3, j + 2, k + 7, 0);
		world.setBlock(i + 3, j + 2, k + 8, 0);
		world.setBlock(i + 3, j + 2, k + 9, 0);
		world.setBlock(i + 3, j + 2, k + 10, JamesForest.superStone.blockID);
		world.setBlock(i + 3, j + 3, k + 0, JamesForest.superStone.blockID);
		world.setBlock(i + 3, j + 3, k + 1, 0);
		world.setBlock(i + 3, j + 3, k + 2, 0);
		world.setBlock(i + 3, j + 3, k + 3, 0);
		world.setBlock(i + 3, j + 3, k + 4, 0);
		world.setBlock(i + 3, j + 3, k + 5, 0);
		world.setBlock(i + 3, j + 3, k + 6, 0);
		world.setBlock(i + 3, j + 3, k + 7, 0);
		world.setBlock(i + 3, j + 3, k + 8, 0);
		world.setBlock(i + 3, j + 3, k + 9, 0);
		world.setBlock(i + 3, j + 3, k + 10, JamesForest.superStone.blockID);
		world.setBlock(i + 3, j + 4, k + 0, JamesForest.superStone.blockID);
		world.setBlock(i + 3, j + 4, k + 1, 0);
		world.setBlock(i + 3, j + 4, k + 2, 0);
		world.setBlock(i + 3, j + 4, k + 3, 0);
		world.setBlock(i + 3, j + 4, k + 4, 0);
		world.setBlock(i + 3, j + 4, k + 5, 0);
		world.setBlock(i + 3, j + 4, k + 6, 0);
		world.setBlock(i + 3, j + 4, k + 7, 0);
		world.setBlock(i + 3, j + 4, k + 8, 0);
		world.setBlock(i + 3, j + 4, k + 9, 0);
		world.setBlock(i + 3, j + 4, k + 10, JamesForest.superStone.blockID);
		world.setBlock(i + 3, j + 5, k + 0, JamesForest.superStone.blockID);
		world.setBlock(i + 3, j + 5, k + 1, JamesForest.superStone.blockID);
		world.setBlock(i + 3, j + 5, k + 2, JamesForest.superStone.blockID);
		world.setBlock(i + 3, j + 5, k + 3, JamesForest.superStone.blockID);
		world.setBlock(i + 3, j + 5, k + 4, JamesForest.superStone.blockID);
		world.setBlock(i + 3, j + 5, k + 5, JamesForest.superStone.blockID);
		world.setBlock(i + 3, j + 5, k + 6, JamesForest.superStone.blockID);
		world.setBlock(i + 3, j + 5, k + 7, JamesForest.superStone.blockID);
		world.setBlock(i + 3, j + 5, k + 8, JamesForest.superStone.blockID);
		world.setBlock(i + 3, j + 5, k + 9, JamesForest.superStone.blockID);
		world.setBlock(i + 3, j + 5, k + 10, JamesForest.superStone.blockID);
		world.setBlock(i + 4, j + 0, k + 0, JamesForest.superStone.blockID);
		world.setBlock(i + 4, j + 0, k + 1, JamesForest.superStone.blockID);
		world.setBlock(i + 4, j + 0, k + 2, JamesForest.superStone.blockID);
		world.setBlock(i + 4, j + 0, k + 3, JamesForest.superStone.blockID);
		world.setBlock(i + 4, j + 0, k + 4, JamesForest.superStone.blockID);
		world.setBlock(i + 4, j + 0, k + 5, JamesForest.superStone.blockID);
		world.setBlock(i + 4, j + 0, k + 6, JamesForest.superStone.blockID);
		world.setBlock(i + 4, j + 0, k + 7, JamesForest.superStone.blockID);
		world.setBlock(i + 4, j + 0, k + 8, JamesForest.superStone.blockID);
		world.setBlock(i + 4, j + 0, k + 9, JamesForest.superStone.blockID);
		world.setBlock(i + 4, j + 0, k + 10, JamesForest.superStone.blockID);
		world.setBlock(i + 4, j + 1, k + 0, JamesForest.superStone.blockID);
		world.setBlock(i + 4, j + 1, k + 1, 0);
		world.setBlock(i + 4, j + 1, k + 2, 0);
		world.setBlock(i + 4, j + 1, k + 3, 0);
		world.setBlock(i + 4, j + 1, k + 4, 0);
		world.setBlock(i + 4, j + 1, k + 5, 0);
		world.setBlock(i + 4, j + 1, k + 6, 0);
		world.setBlock(i + 4, j + 1, k + 7, 0);
		world.setBlock(i + 4, j + 1, k + 8, 0);
		world.setBlock(i + 4, j + 1, k + 9, 0);
		world.setBlock(i + 4, j + 1, k + 10, JamesForest.superStone.blockID);
		world.setBlock(i + 4, j + 2, k + 0, JamesForest.superStone.blockID);
		world.setBlock(i + 4, j + 2, k + 1, 0);
		world.setBlock(i + 4, j + 2, k + 2, 0);
		world.setBlock(i + 4, j + 2, k + 3, 0);
		world.setBlock(i + 4, j + 2, k + 4, 0);
		world.setBlock(i + 4, j + 2, k + 5, 0);
		world.setBlock(i + 4, j + 2, k + 6, 0);
		world.setBlock(i + 4, j + 2, k + 7, 0);
		world.setBlock(i + 4, j + 2, k + 8, 0);
		world.setBlock(i + 4, j + 2, k + 9, 0);
		world.setBlock(i + 4, j + 2, k + 10, JamesForest.superStone.blockID);
		world.setBlock(i + 4, j + 3, k + 0, JamesForest.superStone.blockID);
		world.setBlock(i + 4, j + 3, k + 1, 0);
		world.setBlock(i + 4, j + 3, k + 2, 0);
		world.setBlock(i + 4, j + 3, k + 3, 0);
		world.setBlock(i + 4, j + 3, k + 4, 0);
		world.setBlock(i + 4, j + 3, k + 5, 0);
		world.setBlock(i + 4, j + 3, k + 6, 0);
		world.setBlock(i + 4, j + 3, k + 7, 0);
		world.setBlock(i + 4, j + 3, k + 8, 0);
		world.setBlock(i + 4, j + 3, k + 9, 0);
		world.setBlock(i + 4, j + 3, k + 10, JamesForest.superStone.blockID);
		world.setBlock(i + 4, j + 4, k + 0, JamesForest.superStone.blockID);
		world.setBlock(i + 4, j + 4, k + 1, 0);
		world.setBlock(i + 4, j + 4, k + 2, 0);
		world.setBlock(i + 4, j + 4, k + 3, 0);
		world.setBlock(i + 4, j + 4, k + 4, 0);
		world.setBlock(i + 4, j + 4, k + 5, 0);
		world.setBlock(i + 4, j + 4, k + 6, 0);
		world.setBlock(i + 4, j + 4, k + 7, 0);
		world.setBlock(i + 4, j + 4, k + 8, 0);
		world.setBlock(i + 4, j + 4, k + 9, 0);
		world.setBlock(i + 4, j + 4, k + 10, JamesForest.superStone.blockID);
		world.setBlock(i + 4, j + 5, k + 0, JamesForest.superStone.blockID);
		world.setBlock(i + 4, j + 5, k + 1, JamesForest.superStone.blockID);
		world.setBlock(i + 4, j + 5, k + 2, JamesForest.superStone.blockID);
		world.setBlock(i + 4, j + 5, k + 3, JamesForest.superStone.blockID);
		world.setBlock(i + 4, j + 5, k + 4, JamesForest.superStone.blockID);
		world.setBlock(i + 4, j + 5, k + 5, JamesForest.superStone.blockID);
		world.setBlock(i + 4, j + 5, k + 6, JamesForest.superStone.blockID);
		world.setBlock(i + 4, j + 5, k + 7, JamesForest.superStone.blockID);
		world.setBlock(i + 4, j + 5, k + 8, JamesForest.superStone.blockID);
		world.setBlock(i + 4, j + 5, k + 9, JamesForest.superStone.blockID);
		world.setBlock(i + 4, j + 5, k + 10, JamesForest.superStone.blockID);
		world.setBlock(i + 5, j + 0, k + 0, JamesForest.superStone.blockID);
		world.setBlock(i + 5, j + 0, k + 1, JamesForest.superStone.blockID);
		world.setBlock(i + 5, j + 0, k + 2, JamesForest.superStone.blockID);
		world.setBlock(i + 5, j + 0, k + 3, JamesForest.superStone.blockID);
		world.setBlock(i + 5, j + 0, k + 4, JamesForest.superStone.blockID);
		world.setBlock(i + 5, j + 0, k + 5, JamesForest.superStone.blockID);
		world.setBlock(i + 5, j + 0, k + 6, JamesForest.superStone.blockID);
		world.setBlock(i + 5, j + 0, k + 7, JamesForest.superStone.blockID);
		world.setBlock(i + 5, j + 0, k + 8, JamesForest.superStone.blockID);
		world.setBlock(i + 5, j + 0, k + 9, JamesForest.superStone.blockID);
		world.setBlock(i + 5, j + 0, k + 10, JamesForest.superStone.blockID);
		world.setBlock(i + 5, j + 1, k + 0, JamesForest.superStone.blockID);
		world.setBlock(i + 5, j + 1, k + 1, 0);
		world.setBlock(i + 5, j + 1, k + 2, 0);
		world.setBlock(i + 5, j + 1, k + 3, 0);
		world.setBlock(i + 5, j + 1, k + 4, 0);
		world.setBlock(i + 5, j + 1, k + 5, 0);
		world.setBlock(i + 5, j + 1, k + 6, 0);
		world.setBlock(i + 5, j + 1, k + 7, 0);
		world.setBlock(i + 5, j + 1, k + 8, 0);
		world.setBlock(i + 5, j + 1, k + 9, 0);
		world.setBlock(i + 5, j + 1, k + 10, JamesForest.superStone.blockID);
		world.setBlock(i + 5, j + 2, k + 0, JamesForest.superStone.blockID);
		world.setBlock(i + 5, j + 2, k + 1, 0);
		world.setBlock(i + 5, j + 2, k + 2, 0);
		world.setBlock(i + 5, j + 2, k + 3, 0);
		world.setBlock(i + 5, j + 2, k + 4, 0);
		world.setBlock(i + 5, j + 2, k + 5, 0);
		world.setBlock(i + 5, j + 2, k + 6, 0);
		world.setBlock(i + 5, j + 2, k + 7, 0);
		world.setBlock(i + 5, j + 2, k + 8, 0);
		world.setBlock(i + 5, j + 2, k + 9, 0);
		world.setBlock(i + 5, j + 2, k + 10, JamesForest.superStone.blockID);
		world.setBlock(i + 5, j + 3, k + 0, JamesForest.superStone.blockID);
		world.setBlock(i + 5, j + 3, k + 1, 0);
		world.setBlock(i + 5, j + 3, k + 2, 0);
		world.setBlock(i + 5, j + 3, k + 3, 0);
		world.setBlock(i + 5, j + 3, k + 4, 0);
		world.setBlock(i + 5, j + 3, k + 5, 0);
		world.setBlock(i + 5, j + 3, k + 6, 0);
		world.setBlock(i + 5, j + 3, k + 7, 0);
		world.setBlock(i + 5, j + 3, k + 8, 0);
		world.setBlock(i + 5, j + 3, k + 9, 0);
		world.setBlock(i + 5, j + 3, k + 10, JamesForest.superStone.blockID);
		world.setBlock(i + 5, j + 4, k + 0, JamesForest.superStone.blockID);
		world.setBlock(i + 5, j + 4, k + 1, 0);
		world.setBlock(i + 5, j + 4, k + 2, 0);
		world.setBlock(i + 5, j + 4, k + 3, 0);
		world.setBlock(i + 5, j + 4, k + 4, 0);
		world.setBlock(i + 5, j + 4, k + 5, 0);
		world.setBlock(i + 5, j + 4, k + 6, 0);
		world.setBlock(i + 5, j + 4, k + 7, 0);
		world.setBlock(i + 5, j + 4, k + 8, 0);
		world.setBlock(i + 5, j + 4, k + 9, 0);
		world.setBlock(i + 5, j + 4, k + 10, JamesForest.superStone.blockID);
		world.setBlock(i + 5, j + 5, k + 0, JamesForest.superStone.blockID);
		world.setBlock(i + 5, j + 5, k + 1, JamesForest.superStone.blockID);
		world.setBlock(i + 5, j + 5, k + 2, JamesForest.superStone.blockID);
		world.setBlock(i + 5, j + 5, k + 3, JamesForest.superStone.blockID);
		world.setBlock(i + 5, j + 5, k + 4, JamesForest.superStone.blockID);
		world.setBlock(i + 5, j + 5, k + 5, JamesForest.superStone.blockID);
		world.setBlock(i + 5, j + 5, k + 6, JamesForest.superStone.blockID);
		world.setBlock(i + 5, j + 5, k + 7, JamesForest.superStone.blockID);
		world.setBlock(i + 5, j + 5, k + 8, JamesForest.superStone.blockID);
		world.setBlock(i + 5, j + 5, k + 9, JamesForest.superStone.blockID);
		world.setBlock(i + 5, j + 5, k + 10, JamesForest.superStone.blockID);
		world.setBlock(i + 6, j + 0, k + 0, JamesForest.superStone.blockID);
		world.setBlock(i + 6, j + 0, k + 1, JamesForest.superStone.blockID);
		world.setBlock(i + 6, j + 0, k + 2, JamesForest.superStone.blockID);
		world.setBlock(i + 6, j + 0, k + 3, JamesForest.superStone.blockID);
		world.setBlock(i + 6, j + 0, k + 4, JamesForest.superStone.blockID);
		world.setBlock(i + 6, j + 0, k + 5, JamesForest.superStone.blockID);
		world.setBlock(i + 6, j + 0, k + 6, JamesForest.superStone.blockID);
		world.setBlock(i + 6, j + 0, k + 7, JamesForest.superStone.blockID);
		world.setBlock(i + 6, j + 0, k + 8, JamesForest.superStone.blockID);
		world.setBlock(i + 6, j + 0, k + 9, JamesForest.superStone.blockID);
		world.setBlock(i + 6, j + 0, k + 10, JamesForest.superStone.blockID);
		world.setBlock(i + 6, j + 1, k + 0, JamesForest.superStone.blockID);
		world.setBlock(i + 6, j + 1, k + 1, 0);
		world.setBlock(i + 6, j + 1, k + 2, 0);
		world.setBlock(i + 6, j + 1, k + 3, 0);
		world.setBlock(i + 6, j + 1, k + 4, 0);
		world.setBlock(i + 6, j + 1, k + 5, 0);
		world.setBlock(i + 6, j + 1, k + 6, 0);
		world.setBlock(i + 6, j + 1, k + 7, 0);
		world.setBlock(i + 6, j + 1, k + 8, 0);
		world.setBlock(i + 6, j + 1, k + 9, 0);
		world.setBlock(i + 6, j + 1, k + 10, JamesForest.superStone.blockID);
		world.setBlock(i + 6, j + 2, k + 0, JamesForest.superStone.blockID);
		world.setBlock(i + 6, j + 2, k + 1, 0);
		world.setBlock(i + 6, j + 2, k + 2, 0);
		world.setBlock(i + 6, j + 2, k + 3, 0);
		world.setBlock(i + 6, j + 2, k + 4, 0);
		world.setBlock(i + 6, j + 2, k + 5, 0);
		world.setBlock(i + 6, j + 2, k + 6, 0);
		world.setBlock(i + 6, j + 2, k + 7, 0);
		world.setBlock(i + 6, j + 2, k + 8, 0);
		world.setBlock(i + 6, j + 2, k + 9, 0);
		world.setBlock(i + 6, j + 2, k + 10, JamesForest.superStone.blockID);
		world.setBlock(i + 6, j + 3, k + 0, JamesForest.superStone.blockID);
		world.setBlock(i + 6, j + 3, k + 1, 0);
		world.setBlock(i + 6, j + 3, k + 2, 0);
		world.setBlock(i + 6, j + 3, k + 3, 0);
		world.setBlock(i + 6, j + 3, k + 4, 0);
		world.setBlock(i + 6, j + 3, k + 5, 0);
		world.setBlock(i + 6, j + 3, k + 6, 0);
		world.setBlock(i + 6, j + 3, k + 7, 0);
		world.setBlock(i + 6, j + 3, k + 8, 0);
		world.setBlock(i + 6, j + 3, k + 9, 0);
		world.setBlock(i + 6, j + 3, k + 10, JamesForest.superStone.blockID);
		world.setBlock(i + 6, j + 4, k + 0, JamesForest.superStone.blockID);
		world.setBlock(i + 6, j + 4, k + 1, 0);
		world.setBlock(i + 6, j + 4, k + 2, 0);
		world.setBlock(i + 6, j + 4, k + 3, 0);
		world.setBlock(i + 6, j + 4, k + 4, 0);
		world.setBlock(i + 6, j + 4, k + 5, 0);
		world.setBlock(i + 6, j + 4, k + 6, 0);
		world.setBlock(i + 6, j + 4, k + 7, 0);
		world.setBlock(i + 6, j + 4, k + 8, 0);
		world.setBlock(i + 6, j + 4, k + 9, 0);
		world.setBlock(i + 6, j + 4, k + 10, JamesForest.superStone.blockID);
		world.setBlock(i + 6, j + 5, k + 0, JamesForest.superStone.blockID);
		world.setBlock(i + 6, j + 5, k + 1, JamesForest.superStone.blockID);
		world.setBlock(i + 6, j + 5, k + 2, JamesForest.superStone.blockID);
		world.setBlock(i + 6, j + 5, k + 3, JamesForest.superStone.blockID);
		world.setBlock(i + 6, j + 5, k + 4, JamesForest.superStone.blockID);
		world.setBlock(i + 6, j + 5, k + 5, JamesForest.superStone.blockID);
		world.setBlock(i + 6, j + 5, k + 6, JamesForest.superStone.blockID);
		world.setBlock(i + 6, j + 5, k + 7, JamesForest.superStone.blockID);
		world.setBlock(i + 6, j + 5, k + 8, JamesForest.superStone.blockID);
		world.setBlock(i + 6, j + 5, k + 9, JamesForest.superStone.blockID);
		world.setBlock(i + 6, j + 5, k + 10, JamesForest.superStone.blockID);
		world.setBlock(i + 7, j + 0, k + 0, JamesForest.superStone.blockID);
		world.setBlock(i + 7, j + 0, k + 1, JamesForest.superStone.blockID);
		world.setBlock(i + 7, j + 0, k + 2, JamesForest.superStone.blockID);
		world.setBlock(i + 7, j + 0, k + 3, JamesForest.superStone.blockID);
		world.setBlock(i + 7, j + 0, k + 4, JamesForest.superStone.blockID);
		world.setBlock(i + 7, j + 0, k + 5, JamesForest.superStone.blockID);
		world.setBlock(i + 7, j + 0, k + 6, JamesForest.superStone.blockID);
		world.setBlock(i + 7, j + 0, k + 7, JamesForest.superStone.blockID);
		world.setBlock(i + 7, j + 0, k + 8, JamesForest.superStone.blockID);
		world.setBlock(i + 7, j + 0, k + 9, JamesForest.superStone.blockID);
		world.setBlock(i + 7, j + 0, k + 10, JamesForest.superStone.blockID);
		world.setBlock(i + 7, j + 1, k + 0, JamesForest.superStone.blockID);
		world.setBlock(i + 7, j + 1, k + 1, 0);
		world.setBlock(i + 7, j + 1, k + 2, 0);
		world.setBlock(i + 7, j + 1, k + 3, 0);
		world.setBlock(i + 7, j + 1, k + 4, 0);
		world.setBlock(i + 7, j + 1, k + 5, 0);
		world.setBlock(i + 7, j + 1, k + 6, 0);
		world.setBlock(i + 7, j + 1, k + 7, 0);
		world.setBlock(i + 7, j + 1, k + 8, 0);
		world.setBlock(i + 7, j + 1, k + 9, 0);
		world.setBlock(i + 7, j + 1, k + 10, JamesForest.superStone.blockID);
		world.setBlock(i + 7, j + 2, k + 0, JamesForest.superStone.blockID);
		world.setBlock(i + 7, j + 2, k + 1, 0);
		world.setBlock(i + 7, j + 2, k + 2, 0);
		world.setBlock(i + 7, j + 2, k + 3, 0);
		world.setBlock(i + 7, j + 2, k + 4, 0);
		world.setBlock(i + 7, j + 2, k + 5, 0);
		world.setBlock(i + 7, j + 2, k + 6, 0);
		world.setBlock(i + 7, j + 2, k + 7, 0);
		world.setBlock(i + 7, j + 2, k + 8, 0);
		world.setBlock(i + 7, j + 2, k + 9, 0);
		world.setBlock(i + 7, j + 2, k + 10, JamesForest.superStone.blockID);
		world.setBlock(i + 7, j + 3, k + 0, JamesForest.superStone.blockID);
		world.setBlock(i + 7, j + 3, k + 1, 0);
		world.setBlock(i + 7, j + 3, k + 2, 0);
		world.setBlock(i + 7, j + 3, k + 3, 0);
		world.setBlock(i + 7, j + 3, k + 4, 0);
		world.setBlock(i + 7, j + 3, k + 5, 0);
		world.setBlock(i + 7, j + 3, k + 6, 0);
		world.setBlock(i + 7, j + 3, k + 7, 0);
		world.setBlock(i + 7, j + 3, k + 8, 0);
		world.setBlock(i + 7, j + 3, k + 9, 0);
		world.setBlock(i + 7, j + 3, k + 10, JamesForest.superStone.blockID);
		world.setBlock(i + 7, j + 4, k + 0, JamesForest.superStone.blockID);
		world.setBlock(i + 7, j + 4, k + 1, 0);
		world.setBlock(i + 7, j + 4, k + 2, 0);
		world.setBlock(i + 7, j + 4, k + 3, 0);
		world.setBlock(i + 7, j + 4, k + 4, 0);
		world.setBlock(i + 7, j + 4, k + 5, 0);
		world.setBlock(i + 7, j + 4, k + 6, 0);
		world.setBlock(i + 7, j + 4, k + 7, 0);
		world.setBlock(i + 7, j + 4, k + 8, 0);
		world.setBlock(i + 7, j + 4, k + 9, 0);
		world.setBlock(i + 7, j + 4, k + 10, JamesForest.superStone.blockID);
		world.setBlock(i + 7, j + 5, k + 0, JamesForest.superStone.blockID);
		world.setBlock(i + 7, j + 5, k + 1, JamesForest.superStone.blockID);
		world.setBlock(i + 7, j + 5, k + 2, JamesForest.superStone.blockID);
		world.setBlock(i + 7, j + 5, k + 3, JamesForest.superStone.blockID);
		world.setBlock(i + 7, j + 5, k + 4, JamesForest.superStone.blockID);
		world.setBlock(i + 7, j + 5, k + 5, JamesForest.superStone.blockID);
		world.setBlock(i + 7, j + 5, k + 6, JamesForest.superStone.blockID);
		world.setBlock(i + 7, j + 5, k + 7, JamesForest.superStone.blockID);
		world.setBlock(i + 7, j + 5, k + 8, JamesForest.superStone.blockID);
		world.setBlock(i + 7, j + 5, k + 9, JamesForest.superStone.blockID);
		world.setBlock(i + 7, j + 5, k + 10, JamesForest.superStone.blockID);
		world.setBlock(i + 8, j + 0, k + 0, JamesForest.superStone.blockID);
		world.setBlock(i + 8, j + 0, k + 1, JamesForest.superStone.blockID);
		world.setBlock(i + 8, j + 0, k + 2, JamesForest.superStone.blockID);
		world.setBlock(i + 8, j + 0, k + 3, JamesForest.superStone.blockID);
		world.setBlock(i + 8, j + 0, k + 4, JamesForest.superStone.blockID);
		world.setBlock(i + 8, j + 0, k + 5, JamesForest.superStone.blockID);
		world.setBlock(i + 8, j + 0, k + 6, JamesForest.superStone.blockID);
		world.setBlock(i + 8, j + 0, k + 7, JamesForest.superStone.blockID);
		world.setBlock(i + 8, j + 0, k + 8, JamesForest.superStone.blockID);
		world.setBlock(i + 8, j + 0, k + 9, JamesForest.superStone.blockID);
		world.setBlock(i + 8, j + 0, k + 10, JamesForest.superStone.blockID);
		world.setBlock(i + 8, j + 1, k + 0, JamesForest.superStone.blockID);
		world.setBlock(i + 8, j + 1, k + 1, 0);
		world.setBlock(i + 8, j + 1, k + 2, 0);
		world.setBlock(i + 8, j + 1, k + 3, 0);
		world.setBlock(i + 8, j + 1, k + 4, 0);
		world.setBlock(i + 8, j + 1, k + 5, 0);
		world.setBlock(i + 8, j + 1, k + 6, 0);
		world.setBlock(i + 8, j + 1, k + 7, 0);
		world.setBlock(i + 8, j + 1, k + 8, 0);
		world.setBlock(i + 8, j + 1, k + 9, 0);
		world.setBlock(i + 8, j + 1, k + 10, JamesForest.superStone.blockID);
		world.setBlock(i + 8, j + 2, k + 0, JamesForest.superStone.blockID);
		world.setBlock(i + 8, j + 2, k + 1, 0);
		world.setBlock(i + 8, j + 2, k + 2, 0);
		world.setBlock(i + 8, j + 2, k + 3, 0);
		world.setBlock(i + 8, j + 2, k + 4, 0);
		world.setBlock(i + 8, j + 2, k + 5, 0);
		world.setBlock(i + 8, j + 2, k + 6, 0);
		world.setBlock(i + 8, j + 2, k + 7, 0);
		world.setBlock(i + 8, j + 2, k + 8, 0);
		world.setBlock(i + 8, j + 2, k + 9, 0);
		world.setBlock(i + 8, j + 2, k + 10, JamesForest.superStone.blockID);
		world.setBlock(i + 8, j + 3, k + 0, JamesForest.superStone.blockID);
		world.setBlock(i + 8, j + 3, k + 1, 0);
		world.setBlock(i + 8, j + 3, k + 2, 0);
		world.setBlock(i + 8, j + 3, k + 3, 0);
		world.setBlock(i + 8, j + 3, k + 4, 0);
		world.setBlock(i + 8, j + 3, k + 5, 0);
		world.setBlock(i + 8, j + 3, k + 6, 0);
		world.setBlock(i + 8, j + 3, k + 7, 0);
		world.setBlock(i + 8, j + 3, k + 8, 0);
		world.setBlock(i + 8, j + 3, k + 9, 0);
		world.setBlock(i + 8, j + 3, k + 10, JamesForest.superStone.blockID);
		world.setBlock(i + 8, j + 4, k + 0, JamesForest.superStone.blockID);
		world.setBlock(i + 8, j + 4, k + 1, 0);
		world.setBlock(i + 8, j + 4, k + 2, 0);
		world.setBlock(i + 8, j + 4, k + 3, 0);
		world.setBlock(i + 8, j + 4, k + 4, 0);
		world.setBlock(i + 8, j + 4, k + 5, 0);
		world.setBlock(i + 8, j + 4, k + 6, 0);
		world.setBlock(i + 8, j + 4, k + 7, 0);
		world.setBlock(i + 8, j + 4, k + 8, 0);
		world.setBlock(i + 8, j + 4, k + 9, 0);
		world.setBlock(i + 8, j + 4, k + 10, JamesForest.superStone.blockID);
		world.setBlock(i + 8, j + 5, k + 0, JamesForest.superStone.blockID);
		world.setBlock(i + 8, j + 5, k + 1, JamesForest.superStone.blockID);
		world.setBlock(i + 8, j + 5, k + 2, JamesForest.superStone.blockID);
		world.setBlock(i + 8, j + 5, k + 3, JamesForest.superStone.blockID);
		world.setBlock(i + 8, j + 5, k + 4, JamesForest.superStone.blockID);
		world.setBlock(i + 8, j + 5, k + 5, JamesForest.superStone.blockID);
		world.setBlock(i + 8, j + 5, k + 6, JamesForest.superStone.blockID);
		world.setBlock(i + 8, j + 5, k + 7, JamesForest.superStone.blockID);
		world.setBlock(i + 8, j + 5, k + 8, JamesForest.superStone.blockID);
		world.setBlock(i + 8, j + 5, k + 9, JamesForest.superStone.blockID);
		world.setBlock(i + 8, j + 5, k + 10, JamesForest.superStone.blockID);
		world.setBlock(i + 9, j + 0, k + 0, JamesForest.superStone.blockID);
		world.setBlock(i + 9, j + 0, k + 1, JamesForest.superStone.blockID);
		world.setBlock(i + 9, j + 0, k + 2, JamesForest.superStone.blockID);
		world.setBlock(i + 9, j + 0, k + 3, JamesForest.superStone.blockID);
		world.setBlock(i + 9, j + 0, k + 4, JamesForest.superStone.blockID);
		world.setBlock(i + 9, j + 0, k + 5, JamesForest.superStone.blockID);
		world.setBlock(i + 9, j + 0, k + 6, JamesForest.superStone.blockID);
		world.setBlock(i + 9, j + 0, k + 7, JamesForest.superStone.blockID);
		world.setBlock(i + 9, j + 0, k + 8, JamesForest.superStone.blockID);
		world.setBlock(i + 9, j + 0, k + 9, JamesForest.superStone.blockID);
		world.setBlock(i + 9, j + 0, k + 10, JamesForest.superStone.blockID);
		world.setBlock(i + 9, j + 1, k + 0, JamesForest.superStone.blockID);
		world.setBlock(i + 9, j + 1, k + 1, 0);
		world.setBlock(i + 9, j + 1, k + 2, 0);
		world.setBlock(i + 9, j + 1, k + 3, 0);
		world.setBlock(i + 9, j + 1, k + 4, 0);
		world.setBlock(i + 9, j + 1, k + 5, Block.chest.blockID, 4, 0);
		world.setBlock(i + 9, j + 1, k + 6, 0);
		world.setBlock(i + 9, j + 1, k + 7, 0);
		world.setBlock(i + 9, j + 1, k + 8, 0);
		world.setBlock(i + 9, j + 1, k + 9, 0);
		world.setBlock(i + 9, j + 1, k + 10, JamesForest.superStone.blockID);
		world.setBlock(i + 9, j + 2, k + 0, JamesForest.superStone.blockID);
		world.setBlock(i + 9, j + 2, k + 1, 0);
		world.setBlock(i + 9, j + 2, k + 2, 0);
		world.setBlock(i + 9, j + 2, k + 3, 0);
		world.setBlock(i + 9, j + 2, k + 4, 0);
		world.setBlock(i + 9, j + 2, k + 5, Block.cloth.blockID);
		world.setBlock(i + 9, j + 2, k + 6, 0);
		world.setBlock(i + 9, j + 2, k + 7, 0);
		world.setBlock(i + 9, j + 2, k + 8, 0);
		world.setBlock(i + 9, j + 2, k + 9, 0);
		world.setBlock(i + 9, j + 2, k + 10, JamesForest.superStone.blockID);
		world.setBlock(i + 9, j + 3, k + 0, JamesForest.superStone.blockID);
		world.setBlock(i + 9, j + 3, k + 1, 0);
		world.setBlock(i + 9, j + 3, k + 2, 0);
		world.setBlock(i + 9, j + 3, k + 3, 0);
		world.setBlock(i + 9, j + 3, k + 4, 0);
		world.setBlock(i + 9, j + 3, k + 5, 0);
		world.setBlock(i + 9, j + 3, k + 6, 0);
		world.setBlock(i + 9, j + 3, k + 7, 0);
		world.setBlock(i + 9, j + 3, k + 8, 0);
		world.setBlock(i + 9, j + 3, k + 9, 0);
		world.setBlock(i + 9, j + 3, k + 10, JamesForest.superStone.blockID);
		world.setBlock(i + 9, j + 4, k + 0, JamesForest.superStone.blockID);
		world.setBlock(i + 9, j + 4, k + 1, 0);
		world.setBlock(i + 9, j + 4, k + 2, 0);
		world.setBlock(i + 9, j + 4, k + 3, 0);
		world.setBlock(i + 9, j + 4, k + 4, 0);
		world.setBlock(i + 9, j + 4, k + 5, 0);
		world.setBlock(i + 9, j + 4, k + 6, 0);
		world.setBlock(i + 9, j + 4, k + 7, 0);
		world.setBlock(i + 9, j + 4, k + 8, 0);
		world.setBlock(i + 9, j + 4, k + 9, 0);
		world.setBlock(i + 9, j + 4, k + 10, JamesForest.superStone.blockID);
		world.setBlock(i + 9, j + 5, k + 0, JamesForest.superStone.blockID);
		world.setBlock(i + 9, j + 5, k + 1, JamesForest.superStone.blockID);
		world.setBlock(i + 9, j + 5, k + 2, JamesForest.superStone.blockID);
		world.setBlock(i + 9, j + 5, k + 3, JamesForest.superStone.blockID);
		world.setBlock(i + 9, j + 5, k + 4, JamesForest.superStone.blockID);
		world.setBlock(i + 9, j + 5, k + 5, JamesForest.superStone.blockID);
		world.setBlock(i + 9, j + 5, k + 6, JamesForest.superStone.blockID);
		world.setBlock(i + 9, j + 5, k + 7, JamesForest.superStone.blockID);
		world.setBlock(i + 9, j + 5, k + 8, JamesForest.superStone.blockID);
		world.setBlock(i + 9, j + 5, k + 9, JamesForest.superStone.blockID);
		world.setBlock(i + 9, j + 5, k + 10, JamesForest.superStone.blockID);
		world.setBlock(i + 10, j + 0, k + 0, JamesForest.superStone.blockID);
		world.setBlock(i + 10, j + 0, k + 1, JamesForest.superStone.blockID);
		world.setBlock(i + 10, j + 0, k + 2, JamesForest.superStone.blockID);
		world.setBlock(i + 10, j + 0, k + 3, JamesForest.superStone.blockID);
		world.setBlock(i + 10, j + 0, k + 4, JamesForest.superStone.blockID);
		world.setBlock(i + 10, j + 0, k + 5, JamesForest.superStone.blockID);
		world.setBlock(i + 10, j + 0, k + 6, JamesForest.superStone.blockID);
		world.setBlock(i + 10, j + 0, k + 7, JamesForest.superStone.blockID);
		world.setBlock(i + 10, j + 0, k + 8, JamesForest.superStone.blockID);
		world.setBlock(i + 10, j + 0, k + 9, JamesForest.superStone.blockID);
		world.setBlock(i + 10, j + 0, k + 10, JamesForest.superStone.blockID);
		world.setBlock(i + 10, j + 1, k + 0, JamesForest.superStone.blockID);
		world.setBlock(i + 10, j + 1, k + 1, JamesForest.superStone.blockID);
		world.setBlock(i + 10, j + 1, k + 2, JamesForest.superStone.blockID);
		world.setBlock(i + 10, j + 1, k + 3, JamesForest.superStone.blockID);
		world.setBlock(i + 10, j + 1, k + 4, JamesForest.superStone.blockID);
		world.setBlock(i + 10, j + 1, k + 5, JamesForest.superStone.blockID);
		world.setBlock(i + 10, j + 1, k + 6, JamesForest.superStone.blockID);
		world.setBlock(i + 10, j + 1, k + 7, JamesForest.superStone.blockID);
		world.setBlock(i + 10, j + 1, k + 8, JamesForest.superStone.blockID);
		world.setBlock(i + 10, j + 1, k + 9, JamesForest.superStone.blockID);
		world.setBlock(i + 10, j + 1, k + 10, JamesForest.superStone.blockID);
		world.setBlock(i + 10, j + 2, k + 0, JamesForest.superStone.blockID);
		world.setBlock(i + 10, j + 2, k + 1, JamesForest.superStone.blockID);
		world.setBlock(i + 10, j + 2, k + 2, JamesForest.superStone.blockID);
		world.setBlock(i + 10, j + 2, k + 3, JamesForest.superStone.blockID);
		world.setBlock(i + 10, j + 2, k + 4, JamesForest.superStone.blockID);
		world.setBlock(i + 10, j + 2, k + 5, JamesForest.superStone.blockID);
		world.setBlock(i + 10, j + 2, k + 6, JamesForest.superStone.blockID);
		world.setBlock(i + 10, j + 2, k + 7, JamesForest.superStone.blockID);
		world.setBlock(i + 10, j + 2, k + 8, JamesForest.superStone.blockID);
		world.setBlock(i + 10, j + 2, k + 9, JamesForest.superStone.blockID);
		world.setBlock(i + 10, j + 2, k + 10, JamesForest.superStone.blockID);
		world.setBlock(i + 10, j + 3, k + 0, JamesForest.superStone.blockID);
		world.setBlock(i + 10, j + 3, k + 1, JamesForest.superStone.blockID);
		world.setBlock(i + 10, j + 3, k + 2, JamesForest.superStone.blockID);
		world.setBlock(i + 10, j + 3, k + 3, JamesForest.superStone.blockID);
		world.setBlock(i + 10, j + 3, k + 4, JamesForest.superStone.blockID);
		world.setBlock(i + 10, j + 3, k + 5, JamesForest.superStone.blockID);
		world.setBlock(i + 10, j + 3, k + 6, JamesForest.superStone.blockID);
		world.setBlock(i + 10, j + 3, k + 7, JamesForest.superStone.blockID);
		world.setBlock(i + 10, j + 3, k + 8, JamesForest.superStone.blockID);
		world.setBlock(i + 10, j + 3, k + 9, JamesForest.superStone.blockID);
		world.setBlock(i + 10, j + 3, k + 10, JamesForest.superStone.blockID);
		world.setBlock(i + 10, j + 4, k + 0, JamesForest.superStone.blockID);
		world.setBlock(i + 10, j + 4, k + 1, JamesForest.superStone.blockID);
		world.setBlock(i + 10, j + 4, k + 2, JamesForest.superStone.blockID);
		world.setBlock(i + 10, j + 4, k + 3, JamesForest.superStone.blockID);
		world.setBlock(i + 10, j + 4, k + 4, JamesForest.superStone.blockID);
		world.setBlock(i + 10, j + 4, k + 5, JamesForest.superStone.blockID);
		world.setBlock(i + 10, j + 4, k + 6, JamesForest.superStone.blockID);
		world.setBlock(i + 10, j + 4, k + 7, JamesForest.superStone.blockID);
		world.setBlock(i + 10, j + 4, k + 8, JamesForest.superStone.blockID);
		world.setBlock(i + 10, j + 4, k + 9, JamesForest.superStone.blockID);
		world.setBlock(i + 10, j + 4, k + 10, JamesForest.superStone.blockID);
		world.setBlock(i + 10, j + 5, k + 0, JamesForest.superStone.blockID);
		world.setBlock(i + 10, j + 5, k + 1, JamesForest.superStone.blockID);
		world.setBlock(i + 10, j + 5, k + 2, JamesForest.superStone.blockID);
		world.setBlock(i + 10, j + 5, k + 3, JamesForest.superStone.blockID);
		world.setBlock(i + 10, j + 5, k + 4, JamesForest.superStone.blockID);
		world.setBlock(i + 10, j + 5, k + 5, JamesForest.superStone.blockID);
		world.setBlock(i + 10, j + 5, k + 6, JamesForest.superStone.blockID);
		world.setBlock(i + 10, j + 5, k + 7, JamesForest.superStone.blockID);
		world.setBlock(i + 10, j + 5, k + 8, JamesForest.superStone.blockID);
		world.setBlock(i + 10, j + 5, k + 9, JamesForest.superStone.blockID);
		world.setBlock(i + 10, j + 5, k + 10, JamesForest.superStone.blockID);
		
		world.setBlock(i + 1, j + 2, k + 5, Block.mobSpawner.blockID);
	    TileEntityMobSpawner tileentitymobspawner = (TileEntityMobSpawner)world.getBlockTileEntity(i + 1, j + 2, k + 5);

	    if (tileentitymobspawner != null) {
	        tileentitymobspawner.func_98049_a().setMobID(DungeonHooks.getRandomDungeonMob(new Random()));
	    }
	    
		world.setBlock(i + 9, j + 2, k + 5, Block.mobSpawner.blockID);
		TileEntityMobSpawner tileentitymobspawner2 = (TileEntityMobSpawner)world.getBlockTileEntity(i + 9, j + 2, k + 5);

	    if (tileentitymobspawner2 != null) {
	        tileentitymobspawner2.func_98049_a().setMobID(DungeonHooks.getRandomDungeonMob(new Random()));
	    }

		world.setBlock(i + 1, j + 1, k + 5, Block.chest.blockID, 5, 0);
		if(random.nextInt(2) == 1){
	    TileEntityChest tile = (TileEntityChest)world.getBlockTileEntity(i + 1, j + 1, k + 5);
	    if(tile != null) {
	    	Random rand = new Random();
	    	WeightedRandomChestContent.generateChestContents(rand, ChestGenHooks.getItems(ChestGenHooks.PYRAMID_DESERT_CHEST, rand), tile, ChestGenHooks.getCount(ChestGenHooks.DUNGEON_CHEST, rand));
	    }
	    }
		world.setBlock(i + 9, j + 1, k + 5, Block.chest.blockID, 4, 0);
		if(random.nextInt(2) == 1){
	    TileEntityChest tile2 = (TileEntityChest)world.getBlockTileEntity(i + 9, j + 1, k + 5);
	    if(tile2 != null) {
	    	Random rand = new Random();
	    	WeightedRandomChestContent.generateChestContents(rand, ChestGenHooks.getItems(ChestGenHooks.PYRAMID_DESERT_CHEST, rand), tile2, ChestGenHooks.getCount(ChestGenHooks.DUNGEON_CHEST, rand));
	    }
		}
	    
	    }
	}
}
