package mods.jameslfc19.forest.world;

import static net.minecraftforge.common.ChestGenHooks.VILLAGE_BLACKSMITH;

import java.util.Random;

import cpw.mods.fml.common.IWorldGenerator;

import net.minecraft.block.Block;
import net.minecraft.tileentity.TileEntityChest;
import net.minecraft.tileentity.TileEntityMobSpawner;
import net.minecraft.util.WeightedRandomChestContent;
import net.minecraft.world.World;
import net.minecraft.world.biome.BiomeGenBase;
import net.minecraft.world.chunk.IChunkProvider;
import net.minecraftforge.common.ChestGenHooks;
import net.minecraftforge.common.DungeonHooks;

public class WorldGenShrine implements IWorldGenerator {
	
	public int spawnRateNumerator = 1;
	public int spawnRateDenominator = 500;
	
	public boolean isDecentSpawn2(int i, int k, int j, World world) {
        
		if (world.getBlockId(i, j, k) == 0) {
			return false;
		} else if (world.getBlockId(i+6, j, k) == 0){
			return false;
		} else if (world.getBlockId(i, j, k+6) == 0){
			return false;
		} else if (world.getBlockId(i+6, j, k+6) == 0){
			return false;
		} else if (world.getBlockId(i, j-6, k) == 0) {
			return false;
		} else if (world.getBlockId(i+6, j-6, k) == 0){
			return false;
		} else if (world.getBlockId(i, j-6, k+6) == 0){
			return false;
		} else if (world.getBlockId(i+6, j-6, k+6) == 0){
			return false;
		} else {
			return true;
		}
       
}

	@Override
    public void generate(Random random, int chunkX, int chunkZ, World world, IChunkProvider chunkGenerator, IChunkProvider chunkProvider) {

    int chunkYMin = 63;
    int chunkYMax = 100;
   
    int i = chunkX*16 + random.nextInt(16);
    int k = chunkZ*16 + random.nextInt(16);
    int j; //Y Coord.

    BiomeGenBase biome = world.getBiomeGenForCoords(i, k);
    if (biome.biomeID == BiomeGenBase.sky.biomeID || biome.biomeID == BiomeGenBase.hell.biomeID || biome.biomeID == BiomeGenBase.ocean.biomeID || biome.biomeID == BiomeGenBase.jungle.biomeID || biome.biomeID == BiomeGenBase.jungleHills.biomeID )
            return;

    for (j=chunkYMin; j<=chunkYMax; j++){
            int blockidnumber = world.getBlockId(i, j, k);
            if (blockidnumber == 0){
                    break;
            }
    }
    j = j-7;
   
    byte biomeTopBlock = biome.topBlock;
    boolean isDecentSpawn = isDecentSpawn2(i, k, j, world);
    boolean randomDecide = random.nextInt(spawnRateDenominator) == spawnRateNumerator;
   
    if (randomDecide){
		if (isDecentSpawn){
		System.out.println("New Shrine! at "+i+" "+j+" "+k+" ");
	world.setBlock(i + 0, j + 0, k + 0, Block.stoneBrick.blockID);
	world.setBlock(i + 0, j + 0, k + 1, Block.stoneBrick.blockID);
	world.setBlock(i + 0, j + 0, k + 2, Block.stoneBrick.blockID);
	world.setBlock(i + 0, j + 0, k + 3, Block.stoneBrick.blockID);
	world.setBlock(i + 0, j + 0, k + 4, Block.stoneBrick.blockID);
	world.setBlock(i + 0, j + 0, k + 5, Block.stoneBrick.blockID);
	world.setBlock(i + 0, j + 0, k + 6, Block.stoneBrick.blockID);
	world.setBlock(i + 0, j + 1, k + 0, Block.stoneBrick.blockID);
	world.setBlock(i + 0, j + 1, k + 1, Block.stoneBrick.blockID);
	world.setBlock(i + 0, j + 1, k + 2, Block.stoneBrick.blockID);
	world.setBlock(i + 0, j + 1, k + 3, Block.stoneBrick.blockID);
	world.setBlock(i + 0, j + 1, k + 4, Block.stoneBrick.blockID, 1, 0);
	world.setBlock(i + 0, j + 1, k + 5, Block.stoneBrick.blockID, 1, 0);
	world.setBlock(i + 0, j + 1, k + 6, Block.stoneBrick.blockID);
	world.setBlock(i + 0, j + 2, k + 0, Block.stoneBrick.blockID);
	world.setBlock(i + 0, j + 2, k + 1, Block.stoneBrick.blockID);
	world.setBlock(i + 0, j + 2, k + 2, Block.stoneBrick.blockID);
	world.setBlock(i + 0, j + 2, k + 3, Block.stoneBrick.blockID);
	world.setBlock(i + 0, j + 2, k + 4, Block.stoneBrick.blockID);
	world.setBlock(i + 0, j + 2, k + 5, Block.stoneBrick.blockID);
	world.setBlock(i + 0, j + 2, k + 6, Block.stoneBrick.blockID);
	world.setBlock(i + 0, j + 3, k + 0, Block.stoneBrick.blockID);
	world.setBlock(i + 0, j + 3, k + 1, Block.stoneBrick.blockID, 1, 0);
	world.setBlock(i + 0, j + 3, k + 2, Block.stoneBrick.blockID);
	world.setBlock(i + 0, j + 3, k + 3, Block.stoneBrick.blockID);
	world.setBlock(i + 0, j + 3, k + 4, Block.stoneBrick.blockID);
	world.setBlock(i + 0, j + 3, k + 5, Block.stoneBrick.blockID);
	world.setBlock(i + 0, j + 3, k + 6, Block.stoneBrick.blockID);
	world.setBlock(i + 0, j + 4, k + 0, Block.stoneBrick.blockID);
	world.setBlock(i + 0, j + 4, k + 1, Block.stoneBrick.blockID);
	world.setBlock(i + 0, j + 4, k + 2, Block.stoneBrick.blockID);
	world.setBlock(i + 0, j + 4, k + 3, Block.stoneBrick.blockID);
	world.setBlock(i + 0, j + 4, k + 4, Block.stoneBrick.blockID, 1, 0);
	world.setBlock(i + 0, j + 4, k + 5, Block.stoneBrick.blockID);
	world.setBlock(i + 0, j + 4, k + 6, Block.stoneBrick.blockID);
	world.setBlock(i + 0, j + 5, k + 0, Block.dirt.blockID);
	world.setBlock(i + 0, j + 5, k + 1, Block.stoneBrick.blockID);
	world.setBlock(i + 0, j + 5, k + 2, Block.stoneBrick.blockID);
	world.setBlock(i + 0, j + 5, k + 3, Block.stoneBrick.blockID);
	world.setBlock(i + 0, j + 5, k + 4, Block.stoneBrick.blockID);
	world.setBlock(i + 0, j + 5, k + 5, Block.stoneBrick.blockID);
	world.setBlock(i + 0, j + 5, k + 6, Block.dirt.blockID);
	world.setBlock(i + 0, j + 6, k + 0, biomeTopBlock);
	world.setBlock(i + 0, j + 6, k + 1, biomeTopBlock);
	world.setBlock(i + 0, j + 6, k + 2, biomeTopBlock);
	world.setBlock(i + 0, j + 6, k + 3, biomeTopBlock);
	world.setBlock(i + 0, j + 6, k + 4, biomeTopBlock);
	world.setBlock(i + 0, j + 6, k + 5, biomeTopBlock);
	world.setBlock(i + 0, j + 6, k + 6, biomeTopBlock);
	world.setBlock(i + 0, j + 7, k + 0, 0);
	world.setBlock(i + 0, j + 7, k + 1, 0);
	world.setBlock(i + 0, j + 7, k + 2, 0);
	world.setBlock(i + 0, j + 7, k + 3, 0);
	world.setBlock(i + 0, j + 7, k + 4, 0);
	world.setBlock(i + 0, j + 7, k + 5, 0);
	world.setBlock(i + 0, j + 7, k + 6, 0);
	world.setBlock(i + 0, j + 8, k + 0, 0);
	world.setBlock(i + 0, j + 8, k + 1, 0);
	world.setBlock(i + 0, j + 8, k + 2, 0);
	world.setBlock(i + 0, j + 8, k + 3, 0);
	world.setBlock(i + 0, j + 8, k + 4, 0);
	world.setBlock(i + 0, j + 8, k + 5, 0);
	world.setBlock(i + 0, j + 8, k + 6, 0);
	world.setBlock(i + 0, j + 9, k + 0, 0);
	world.setBlock(i + 0, j + 9, k + 1, 0);
	world.setBlock(i + 0, j + 9, k + 2, 0);
	world.setBlock(i + 0, j + 9, k + 3, 0);
	world.setBlock(i + 0, j + 9, k + 4, 0);
	world.setBlock(i + 0, j + 9, k + 5, 0);
	world.setBlock(i + 0, j + 9, k + 6, 0);
	world.setBlock(i + 1, j + 0, k + 0, Block.stoneBrick.blockID);
	world.setBlock(i + 1, j + 0, k + 1, Block.stoneBrick.blockID);
	world.setBlock(i + 1, j + 0, k + 2, Block.stoneBrick.blockID);
	world.setBlock(i + 1, j + 0, k + 3, Block.stoneBrick.blockID);
	world.setBlock(i + 1, j + 0, k + 4, Block.stoneBrick.blockID);
	world.setBlock(i + 1, j + 0, k + 5, Block.stoneBrick.blockID);
	world.setBlock(i + 1, j + 0, k + 6, Block.stoneBrick.blockID);
	world.setBlock(i + 1, j + 1, k + 0, Block.stoneBrick.blockID);
	world.setBlock(i + 1, j + 1, k + 1, 0);
	world.setBlock(i + 1, j + 1, k + 2, 0);
	world.setBlock(i + 1, j + 1, k + 3, 0);
	world.setBlock(i + 1, j + 1, k + 4, 0);
	world.setBlock(i + 1, j + 1, k + 5, 0);
	world.setBlock(i + 1, j + 1, k + 6, Block.stoneBrick.blockID);
	world.setBlock(i + 1, j + 2, k + 0, Block.stoneBrick.blockID);
	world.setBlock(i + 1, j + 2, k + 1, 0);
	world.setBlock(i + 1, j + 2, k + 2, 0);
	world.setBlock(i + 1, j + 2, k + 3, 0);
	world.setBlock(i + 1, j + 2, k + 4, 0);
	world.setBlock(i + 1, j + 2, k + 5, 0);
	world.setBlock(i + 1, j + 2, k + 6, Block.stoneBrick.blockID);
	world.setBlock(i + 1, j + 3, k + 0, Block.stoneBrick.blockID);
	world.setBlock(i + 1, j + 3, k + 1, 0);
	world.setBlock(i + 1, j + 3, k + 2, 0);
	world.setBlock(i + 1, j + 3, k + 3, 0);
	world.setBlock(i + 1, j + 3, k + 4, 0);
	world.setBlock(i + 1, j + 3, k + 5, 0);
	world.setBlock(i + 1, j + 3, k + 6, Block.stoneBrick.blockID);
	world.setBlock(i + 1, j + 4, k + 0, Block.stoneBrick.blockID);
	world.setBlock(i + 1, j + 4, k + 1, 0);
	world.setBlock(i + 1, j + 4, k + 2, 0);
	world.setBlock(i + 1, j + 4, k + 3, 0);
	world.setBlock(i + 1, j + 4, k + 4, 0);
	world.setBlock(i + 1, j + 4, k + 5, 0);
	world.setBlock(i + 1, j + 4, k + 6, Block.stoneBrick.blockID);
	world.setBlock(i + 1, j + 5, k + 0, Block.stoneBrick.blockID);
	world.setBlock(i + 1, j + 5, k + 1, 0);
	world.setBlock(i + 1, j + 5, k + 2, 0);
	world.setBlock(i + 1, j + 5, k + 3, 0);
	world.setBlock(i + 1, j + 5, k + 4, 0);
	world.setBlock(i + 1, j + 5, k + 5, 0);
	world.setBlock(i + 1, j + 5, k + 6, Block.stoneBrick.blockID);
	world.setBlock(i + 1, j + 6, k + 0, biomeTopBlock);
	world.setBlock(i + 1, j + 6, k + 1, biomeTopBlock);
	world.setBlock(i + 1, j + 6, k + 2, biomeTopBlock);
	world.setBlock(i + 1, j + 6, k + 3, biomeTopBlock);
	world.setBlock(i + 1, j + 6, k + 4, biomeTopBlock);
	world.setBlock(i + 1, j + 6, k + 5, biomeTopBlock);
	world.setBlock(i + 1, j + 6, k + 6, biomeTopBlock);
	world.setBlock(i + 1, j + 7, k + 0, 0);
	world.setBlock(i + 1, j + 7, k + 1, 0);
	world.setBlock(i + 1, j + 7, k + 2, 0);
	world.setBlock(i + 1, j + 7, k + 3, 0);
	world.setBlock(i + 1, j + 7, k + 4, 0);
	world.setBlock(i + 1, j + 7, k + 5, 0);
	world.setBlock(i + 1, j + 7, k + 6, 0);
	world.setBlock(i + 1, j + 8, k + 0, 0);
	world.setBlock(i + 1, j + 8, k + 1, 0);
	world.setBlock(i + 1, j + 8, k + 2, 0);
	world.setBlock(i + 1, j + 8, k + 3, 0);
	world.setBlock(i + 1, j + 8, k + 4, 0);
	world.setBlock(i + 1, j + 8, k + 5, 0);
	world.setBlock(i + 1, j + 8, k + 6, 0);
	world.setBlock(i + 1, j + 9, k + 0, 0);
	world.setBlock(i + 1, j + 9, k + 1, 0);
	world.setBlock(i + 1, j + 9, k + 2, 0);
	world.setBlock(i + 1, j + 9, k + 3, 0);
	world.setBlock(i + 1, j + 9, k + 4, 0);
	world.setBlock(i + 1, j + 9, k + 5, 0);
	world.setBlock(i + 1, j + 9, k + 6, 0);
	world.setBlock(i + 2, j + 0, k + 0, Block.stoneBrick.blockID);
	world.setBlock(i + 2, j + 0, k + 1, Block.stoneBrick.blockID);
	world.setBlock(i + 2, j + 0, k + 2, Block.stoneBrick.blockID);
	world.setBlock(i + 2, j + 0, k + 3, Block.stoneBrick.blockID);
	world.setBlock(i + 2, j + 0, k + 4, Block.stoneBrick.blockID);
	world.setBlock(i + 2, j + 0, k + 5, Block.stoneBrick.blockID);
	world.setBlock(i + 2, j + 0, k + 6, Block.stoneBrick.blockID);
	world.setBlock(i + 2, j + 1, k + 0, Block.stoneBrick.blockID);
	world.setBlock(i + 2, j + 1, k + 1, 0);
	world.setBlock(i + 2, j + 1, k + 2, 0);
	world.setBlock(i + 2, j + 1, k + 3, 0);
	world.setBlock(i + 2, j + 1, k + 4, 0);
	world.setBlock(i + 2, j + 1, k + 5, 0);
	world.setBlock(i + 2, j + 1, k + 6, Block.stoneBrick.blockID);
	world.setBlock(i + 2, j + 2, k + 0, Block.stoneBrick.blockID);
	world.setBlock(i + 2, j + 2, k + 1, 0);
	world.setBlock(i + 2, j + 2, k + 2, 0);
	world.setBlock(i + 2, j + 2, k + 3, 0);
	world.setBlock(i + 2, j + 2, k + 4, 0);
	world.setBlock(i + 2, j + 2, k + 5, 0);
	world.setBlock(i + 2, j + 2, k + 6, Block.stoneBrick.blockID);
	world.setBlock(i + 2, j + 3, k + 0, Block.stoneBrick.blockID);
	world.setBlock(i + 2, j + 3, k + 1, 0);
	world.setBlock(i + 2, j + 3, k + 2, 0);
	world.setBlock(i + 2, j + 3, k + 3, 0);
	world.setBlock(i + 2, j + 3, k + 4, 0);
	world.setBlock(i + 2, j + 3, k + 5, 0);
	world.setBlock(i + 2, j + 3, k + 6, Block.stoneBrick.blockID);
	world.setBlock(i + 2, j + 4, k + 0, Block.stoneBrick.blockID, 1, 0);
	world.setBlock(i + 2, j + 4, k + 1, 0);
	world.setBlock(i + 2, j + 4, k + 2, 0);
	world.setBlock(i + 2, j + 4, k + 3, 0);
	world.setBlock(i + 2, j + 4, k + 4, 0);
	world.setBlock(i + 2, j + 4, k + 5, 0);
	world.setBlock(i + 2, j + 4, k + 6, Block.stoneBrick.blockID);
	world.setBlock(i + 2, j + 5, k + 0, Block.stoneBrick.blockID);
	world.setBlock(i + 2, j + 5, k + 1, 0);
	world.setBlock(i + 2, j + 5, k + 2, 0);
	world.setBlock(i + 2, j + 5, k + 3, 0);
	world.setBlock(i + 2, j + 5, k + 4, 0);
	world.setBlock(i + 2, j + 5, k + 5, 0);
	world.setBlock(i + 2, j + 5, k + 6, Block.stoneBrick.blockID);
	world.setBlock(i + 2, j + 6, k + 0, biomeTopBlock);
	world.setBlock(i + 2, j + 6, k + 1, biomeTopBlock);
	world.setBlock(i + 2, j + 6, k + 2, Block.dirt.blockID);
	world.setBlock(i + 2, j + 6, k + 3, Block.stoneBrick.blockID);
	world.setBlock(i + 2, j + 6, k + 4, Block.dirt.blockID);
	world.setBlock(i + 2, j + 6, k + 5, biomeTopBlock);
	world.setBlock(i + 2, j + 6, k + 6, biomeTopBlock);
	world.setBlock(i + 2, j + 7, k + 0, 0);
	world.setBlock(i + 2, j + 7, k + 1, 0);
	world.setBlock(i + 2, j + 7, k + 2, Block.stoneBrick.blockID);
	world.setBlock(i + 2, j + 7, k + 3, 0);
	world.setBlock(i + 2, j + 7, k + 4, Block.stoneBrick.blockID, 1, 0);
	world.setBlock(i + 2, j + 7, k + 5, 0);
	world.setBlock(i + 2, j + 7, k + 6, 0);
	world.setBlock(i + 2, j + 8, k + 0, 0);
	world.setBlock(i + 2, j + 8, k + 1, 0);
	world.setBlock(i + 2, j + 8, k + 2, Block.stoneBrick.blockID);
	world.setBlock(i + 2, j + 8, k + 3, 0);
	world.setBlock(i + 2, j + 8, k + 4, Block.stoneBrick.blockID);
	world.setBlock(i + 2, j + 8, k + 5, 0);
	world.setBlock(i + 2, j + 8, k + 6, 0);
	world.setBlock(i + 2, j + 9, k + 0, 0);
	world.setBlock(i + 2, j + 9, k + 2, Block.stoneBrick.blockID);
	world.setBlock(i + 2, j + 9, k + 3, Block.stoneBrick.blockID, 1, 0);
	world.setBlock(i + 2, j + 9, k + 4, Block.stoneBrick.blockID, 1, 0);
	world.setBlock(i + 2, j + 9, k + 6, 0);
	world.setBlock(i + 3, j + 0, k + 0, Block.stoneBrick.blockID);
	world.setBlock(i + 3, j + 0, k + 1, Block.stoneBrick.blockID);
	world.setBlock(i + 3, j + 0, k + 2, Block.stoneBrick.blockID);
	world.setBlock(i + 3, j + 0, k + 4, Block.stoneBrick.blockID);
	world.setBlock(i + 3, j + 0, k + 5, Block.stoneBrick.blockID);
	world.setBlock(i + 3, j + 0, k + 6, Block.stoneBrick.blockID);
	world.setBlock(i + 3, j + 1, k + 0, Block.stoneBrick.blockID, 1, 0);
	world.setBlock(i + 3, j + 1, k + 1, 0);
	world.setBlock(i + 3, j + 1, k + 2, 0);
	world.setBlock(i + 3, j + 1, k + 4, 0);
	world.setBlock(i + 3, j + 1, k + 5, 0);
	world.setBlock(i + 3, j + 1, k + 6, Block.stoneBrick.blockID);
	world.setBlock(i + 3, j + 2, k + 0, Block.stoneBrick.blockID);
	world.setBlock(i + 3, j + 2, k + 1, 0);
	world.setBlock(i + 3, j + 2, k + 2, 0);
	world.setBlock(i + 3, j + 2, k + 3, 0);
	world.setBlock(i + 3, j + 2, k + 4, 0);
	world.setBlock(i + 3, j + 2, k + 5, 0);
	world.setBlock(i + 3, j + 2, k + 6, Block.stoneBrick.blockID, 1, 0);
	world.setBlock(i + 3, j + 3, k + 0, Block.stoneBrick.blockID);
	world.setBlock(i + 3, j + 3, k + 1, 0);
	world.setBlock(i + 3, j + 3, k + 2, 0);
	world.setBlock(i + 3, j + 3, k + 3, 0);
	world.setBlock(i + 3, j + 3, k + 4, 0);
	world.setBlock(i + 3, j + 3, k + 5, 0);
	world.setBlock(i + 3, j + 3, k + 6, Block.stoneBrick.blockID);
	world.setBlock(i + 3, j + 4, k + 0, Block.stoneBrick.blockID);
	world.setBlock(i + 3, j + 4, k + 1, 0);
	world.setBlock(i + 3, j + 4, k + 2, 0);
	world.setBlock(i + 3, j + 4, k + 3, 0);
	world.setBlock(i + 3, j + 4, k + 4, 0);
	world.setBlock(i + 3, j + 4, k + 5, 0);
	world.setBlock(i + 3, j + 4, k + 6, Block.stoneBrick.blockID, 1, 0);
	world.setBlock(i + 3, j + 5, k + 0, Block.stoneBrick.blockID);
	world.setBlock(i + 3, j + 5, k + 1, 0);
	world.setBlock(i + 3, j + 5, k + 2, 0);
	world.setBlock(i + 3, j + 5, k + 3, 0);
	world.setBlock(i + 3, j + 5, k + 4, 0);
	world.setBlock(i + 3, j + 5, k + 5, 0);
	world.setBlock(i + 3, j + 5, k + 6, Block.stoneBrick.blockID);
	world.setBlock(i + 3, j + 6, k + 0, biomeTopBlock);
	world.setBlock(i + 3, j + 6, k + 1, biomeTopBlock);
	world.setBlock(i + 3, j + 6, k + 2, Block.stoneBrick.blockID);
	world.setBlock(i + 3, j + 6, k + 3, 0);
	world.setBlock(i + 3, j + 6, k + 4, Block.stoneBrick.blockID, 1, 0);
	world.setBlock(i + 3, j + 6, k + 5, biomeTopBlock);
	world.setBlock(i + 3, j + 6, k + 6, biomeTopBlock);
	world.setBlock(i + 3, j + 7, k + 0, 0);
	world.setBlock(i + 3, j + 7, k + 1, 0);
	world.setBlock(i + 3, j + 7, k + 2, 0);
	world.setBlock(i + 3, j + 7, k + 3, 0);
	world.setBlock(i + 3, j + 7, k + 4, 0);
	world.setBlock(i + 3, j + 7, k + 5, 0);
	world.setBlock(i + 3, j + 7, k + 6, 0);
	world.setBlock(i + 3, j + 8, k + 0, 0);
	world.setBlock(i + 3, j + 8, k + 1, 0);
	world.setBlock(i + 3, j + 8, k + 2, 0);
	world.setBlock(i + 3, j + 8, k + 3, 0);
	world.setBlock(i + 3, j + 8, k + 4, 0);
	world.setBlock(i + 3, j + 8, k + 5, 0);
	world.setBlock(i + 3, j + 8, k + 6, 0);
	world.setBlock(i + 3, j + 9, k + 0, 0);
	world.setBlock(i + 3, j + 9, k + 1, 0);
	world.setBlock(i + 3, j + 9, k + 2, Block.stoneBrick.blockID, 1, 0);
	world.setBlock(i + 3, j + 9, k + 3, 0);
	world.setBlock(i + 3, j + 9, k + 4, Block.stoneBrick.blockID);
	world.setBlock(i + 3, j + 9, k + 5, 0);
	world.setBlock(i + 3, j + 9, k + 6, 0);
	world.setBlock(i + 4, j + 0, k + 0, Block.stoneBrick.blockID);
	world.setBlock(i + 4, j + 0, k + 1, Block.stoneBrick.blockID, 1, 0);
	world.setBlock(i + 4, j + 0, k + 2, Block.stoneBrick.blockID);
	world.setBlock(i + 4, j + 0, k + 3, Block.stoneBrick.blockID);
	world.setBlock(i + 4, j + 0, k + 4, Block.stoneBrick.blockID);
	world.setBlock(i + 4, j + 0, k + 5, Block.stoneBrick.blockID);
	world.setBlock(i + 4, j + 0, k + 6, Block.stoneBrick.blockID);
	world.setBlock(i + 4, j + 1, k + 0, Block.stoneBrick.blockID);
	world.setBlock(i + 4, j + 1, k + 1, 0);
	world.setBlock(i + 4, j + 1, k + 2, 0);
	world.setBlock(i + 4, j + 1, k + 3, 0);
	world.setBlock(i + 4, j + 1, k + 4, 0);
	world.setBlock(i + 4, j + 1, k + 5, 0);
	world.setBlock(i + 4, j + 1, k + 6, Block.stoneBrick.blockID);
	world.setBlock(i + 4, j + 2, k + 0, Block.stoneBrick.blockID);
	world.setBlock(i + 4, j + 2, k + 1, 0);
	world.setBlock(i + 4, j + 2, k + 2, 0);
	world.setBlock(i + 4, j + 2, k + 3, 0);
	world.setBlock(i + 4, j + 2, k + 4, 0);
	world.setBlock(i + 4, j + 2, k + 5, 0);
	world.setBlock(i + 4, j + 2, k + 6, Block.stoneBrick.blockID);
	world.setBlock(i + 4, j + 3, k + 0, Block.stoneBrick.blockID);
	world.setBlock(i + 4, j + 3, k + 1, 0);
	world.setBlock(i + 4, j + 3, k + 2, 0);
	world.setBlock(i + 4, j + 3, k + 3, 0);
	world.setBlock(i + 4, j + 3, k + 4, 0);
	world.setBlock(i + 4, j + 3, k + 5, 0);
	world.setBlock(i + 4, j + 3, k + 6, Block.stoneBrick.blockID);
	world.setBlock(i + 4, j + 4, k + 0, Block.stoneBrick.blockID);
	world.setBlock(i + 4, j + 4, k + 1, 0);
	world.setBlock(i + 4, j + 4, k + 2, 0);
	world.setBlock(i + 4, j + 4, k + 3, 0);
	world.setBlock(i + 4, j + 4, k + 4, 0);
	world.setBlock(i + 4, j + 4, k + 5, 0);
	world.setBlock(i + 4, j + 4, k + 6, Block.stoneBrick.blockID, 1, 0);
	world.setBlock(i + 4, j + 5, k + 0, Block.stoneBrick.blockID, 1, 0);
	world.setBlock(i + 4, j + 5, k + 1, 0);
	world.setBlock(i + 4, j + 5, k + 2, 0);
	world.setBlock(i + 4, j + 5, k + 3, 0);
	world.setBlock(i + 4, j + 5, k + 4, 0);
	world.setBlock(i + 4, j + 5, k + 5, 0);
	world.setBlock(i + 4, j + 5, k + 6, Block.stoneBrick.blockID);
	world.setBlock(i + 4, j + 6, k + 0, biomeTopBlock);
	world.setBlock(i + 4, j + 6, k + 1, biomeTopBlock);
	world.setBlock(i + 4, j + 6, k + 2, Block.dirt.blockID);
	world.setBlock(i + 4, j + 6, k + 3, Block.stoneBrick.blockID);
	world.setBlock(i + 4, j + 6, k + 4, Block.dirt.blockID);
	world.setBlock(i + 4, j + 6, k + 5, biomeTopBlock);
	world.setBlock(i + 4, j + 6, k + 6, biomeTopBlock);
	world.setBlock(i + 4, j + 7, k + 0, 0);
	world.setBlock(i + 4, j + 7, k + 1, 0);
	world.setBlock(i + 4, j + 7, k + 2, Block.stoneBrick.blockID);
	world.setBlock(i + 4, j + 7, k + 3, 0);
	world.setBlock(i + 4, j + 7, k + 4, Block.stoneBrick.blockID);
	world.setBlock(i + 4, j + 7, k + 5, 0);
	world.setBlock(i + 4, j + 7, k + 6, 0);
	world.setBlock(i + 4, j + 8, k + 0, 0);
	world.setBlock(i + 4, j + 8, k + 1, 0);
	world.setBlock(i + 4, j + 8, k + 2, Block.stoneBrick.blockID, 1, 0);
	world.setBlock(i + 4, j + 8, k + 3, 0);
	world.setBlock(i + 4, j + 8, k + 4, Block.stoneBrick.blockID, 1, 0);
	world.setBlock(i + 4, j + 8, k + 5, 0);
	world.setBlock(i + 4, j + 8, k + 6, 0);
	world.setBlock(i + 4, j + 9, k + 0, 0);
	world.setBlock(i + 4, j + 9, k + 2, Block.stoneBrick.blockID, 1, 0);
	world.setBlock(i + 4, j + 9, k + 3, Block.stoneBrick.blockID);
	world.setBlock(i + 4, j + 9, k + 4, Block.stoneBrick.blockID);
	world.setBlock(i + 4, j + 9, k + 6, 0);
	world.setBlock(i + 5, j + 0, k + 0, Block.stoneBrick.blockID);
	world.setBlock(i + 5, j + 0, k + 1, Block.stoneBrick.blockID);
	world.setBlock(i + 5, j + 0, k + 2, Block.stoneBrick.blockID);
	world.setBlock(i + 5, j + 0, k + 3, Block.stoneBrick.blockID, 1, 0);
	world.setBlock(i + 5, j + 0, k + 4, Block.stoneBrick.blockID);
	world.setBlock(i + 5, j + 0, k + 5, Block.stoneBrick.blockID);
	world.setBlock(i + 5, j + 0, k + 6, Block.stoneBrick.blockID);
	world.setBlock(i + 5, j + 1, k + 0, Block.stoneBrick.blockID);
	world.setBlock(i + 5, j + 1, k + 1, 0);
	world.setBlock(i + 5, j + 1, k + 2, 0);
	world.setBlock(i + 5, j + 1, k + 3, 0);
	world.setBlock(i + 5, j + 1, k + 4, 0);
	world.setBlock(i + 5, j + 1, k + 5, 0);
	world.setBlock(i + 5, j + 1, k + 6, Block.stoneBrick.blockID);
	world.setBlock(i + 5, j + 2, k + 0, Block.stoneBrick.blockID);
	world.setBlock(i + 5, j + 2, k + 1, 0);
	world.setBlock(i + 5, j + 2, k + 2, 0);
	world.setBlock(i + 5, j + 2, k + 3, 0);
	world.setBlock(i + 5, j + 2, k + 4, 0);
	world.setBlock(i + 5, j + 2, k + 5, 0);
	world.setBlock(i + 5, j + 2, k + 6, Block.stoneBrick.blockID);
	world.setBlock(i + 5, j + 3, k + 0, Block.stoneBrick.blockID);
	world.setBlock(i + 5, j + 3, k + 1, 0);
	world.setBlock(i + 5, j + 3, k + 2, 0);
	world.setBlock(i + 5, j + 3, k + 3, 0);
	world.setBlock(i + 5, j + 3, k + 4, 0);
	world.setBlock(i + 5, j + 3, k + 5, 0);
	world.setBlock(i + 5, j + 3, k + 6, Block.stoneBrick.blockID);
	world.setBlock(i + 5, j + 4, k + 0, Block.stoneBrick.blockID);
	world.setBlock(i + 5, j + 4, k + 1, 0);
	world.setBlock(i + 5, j + 4, k + 2, 0);
	world.setBlock(i + 5, j + 4, k + 3, 0);
	world.setBlock(i + 5, j + 4, k + 4, 0);
	world.setBlock(i + 5, j + 4, k + 5, 0);
	world.setBlock(i + 5, j + 4, k + 6, Block.stoneBrick.blockID);
	world.setBlock(i + 5, j + 5, k + 0, Block.stoneBrick.blockID, 1, 0);
	world.setBlock(i + 5, j + 5, k + 1, 0);
	world.setBlock(i + 5, j + 5, k + 2, 0);
	world.setBlock(i + 5, j + 5, k + 3, 0);
	world.setBlock(i + 5, j + 5, k + 4, 0);
	world.setBlock(i + 5, j + 5, k + 5, 0);
	world.setBlock(i + 5, j + 5, k + 6, Block.stoneBrick.blockID);
	world.setBlock(i + 5, j + 6, k + 0, biomeTopBlock);
	world.setBlock(i + 5, j + 6, k + 1, biomeTopBlock);
	world.setBlock(i + 5, j + 6, k + 2, biomeTopBlock);
	world.setBlock(i + 5, j + 6, k + 3, biomeTopBlock);
	world.setBlock(i + 5, j + 6, k + 4, biomeTopBlock);
	world.setBlock(i + 5, j + 6, k + 5, biomeTopBlock);
	world.setBlock(i + 5, j + 6, k + 6, biomeTopBlock);
	world.setBlock(i + 5, j + 7, k + 0, 0);
	world.setBlock(i + 5, j + 7, k + 1, 0);
	world.setBlock(i + 5, j + 7, k + 2, 0);
	world.setBlock(i + 5, j + 7, k + 3, 0);
	world.setBlock(i + 5, j + 7, k + 4, 0);
	world.setBlock(i + 5, j + 7, k + 5, 0);
	world.setBlock(i + 5, j + 7, k + 6, 0);
	world.setBlock(i + 5, j + 8, k + 0, 0);
	world.setBlock(i + 5, j + 8, k + 1, 0);
	world.setBlock(i + 5, j + 8, k + 2, 0);
	world.setBlock(i + 5, j + 8, k + 3, 0);
	world.setBlock(i + 5, j + 8, k + 4, 0);
	world.setBlock(i + 5, j + 8, k + 5, 0);
	world.setBlock(i + 5, j + 8, k + 6, 0);
	world.setBlock(i + 5, j + 9, k + 0, 0);
	world.setBlock(i + 5, j + 9, k + 1, 0);
	world.setBlock(i + 5, j + 9, k + 2, 0);
	world.setBlock(i + 5, j + 9, k + 3, 0);
	world.setBlock(i + 5, j + 9, k + 4, 0);
	world.setBlock(i + 5, j + 9, k + 5, 0);
	world.setBlock(i + 5, j + 9, k + 6, 0);
	world.setBlock(i + 6, j + 0, k + 0, Block.stoneBrick.blockID);
	world.setBlock(i + 6, j + 0, k + 1, Block.stoneBrick.blockID);
	world.setBlock(i + 6, j + 0, k + 2, Block.stoneBrick.blockID);
	world.setBlock(i + 6, j + 0, k + 3, Block.stoneBrick.blockID);
	world.setBlock(i + 6, j + 0, k + 4, Block.stoneBrick.blockID);
	world.setBlock(i + 6, j + 0, k + 5, Block.stoneBrick.blockID);
	world.setBlock(i + 6, j + 0, k + 6, Block.stoneBrick.blockID);
	world.setBlock(i + 6, j + 1, k + 0, Block.stoneBrick.blockID);
	world.setBlock(i + 6, j + 1, k + 1, Block.stoneBrick.blockID);
	world.setBlock(i + 6, j + 1, k + 2, Block.stoneBrick.blockID);
	world.setBlock(i + 6, j + 1, k + 3, Block.stoneBrick.blockID);
	world.setBlock(i + 6, j + 1, k + 4, Block.stoneBrick.blockID);
	world.setBlock(i + 6, j + 1, k + 5, Block.stoneBrick.blockID);
	world.setBlock(i + 6, j + 1, k + 6, Block.stoneBrick.blockID);
	world.setBlock(i + 6, j + 2, k + 0, Block.stoneBrick.blockID);
	world.setBlock(i + 6, j + 2, k + 1, Block.stoneBrick.blockID);
	world.setBlock(i + 6, j + 2, k + 2, Block.stoneBrick.blockID, 1, 0);
	world.setBlock(i + 6, j + 2, k + 3, Block.stoneBrick.blockID);
	world.setBlock(i + 6, j + 2, k + 4, Block.stoneBrick.blockID);
	world.setBlock(i + 6, j + 2, k + 5, Block.stoneBrick.blockID);
	world.setBlock(i + 6, j + 2, k + 6, Block.stoneBrick.blockID);
	world.setBlock(i + 6, j + 3, k + 0, Block.stoneBrick.blockID);
	world.setBlock(i + 6, j + 3, k + 1, Block.stoneBrick.blockID);
	world.setBlock(i + 6, j + 3, k + 2, Block.stoneBrick.blockID);
	world.setBlock(i + 6, j + 3, k + 3, Block.stoneBrick.blockID);
	world.setBlock(i + 6, j + 3, k + 4, Block.stoneBrick.blockID);
	world.setBlock(i + 6, j + 3, k + 5, Block.stoneBrick.blockID);
	world.setBlock(i + 6, j + 3, k + 6, Block.stoneBrick.blockID);
	world.setBlock(i + 6, j + 4, k + 0, Block.stoneBrick.blockID);
	world.setBlock(i + 6, j + 4, k + 1, Block.stoneBrick.blockID);
	world.setBlock(i + 6, j + 4, k + 2, Block.stoneBrick.blockID, 1, 0);
	world.setBlock(i + 6, j + 4, k + 3, Block.stoneBrick.blockID);
	world.setBlock(i + 6, j + 4, k + 4, Block.stoneBrick.blockID);
	world.setBlock(i + 6, j + 4, k + 5, Block.stoneBrick.blockID);
	world.setBlock(i + 6, j + 4, k + 6, Block.stoneBrick.blockID);
	world.setBlock(i + 6, j + 5, k + 0, Block.dirt.blockID);
	world.setBlock(i + 6, j + 5, k + 1, Block.stoneBrick.blockID);
	world.setBlock(i + 6, j + 5, k + 2, Block.stoneBrick.blockID);
	world.setBlock(i + 6, j + 5, k + 3, Block.stoneBrick.blockID, 1, 0);
	world.setBlock(i + 6, j + 5, k + 4, Block.stoneBrick.blockID);
	world.setBlock(i + 6, j + 5, k + 5, Block.stoneBrick.blockID);
	world.setBlock(i + 6, j + 5, k + 6, Block.dirt.blockID);
	world.setBlock(i + 6, j + 6, k + 0, biomeTopBlock);
	world.setBlock(i + 6, j + 6, k + 1, biomeTopBlock);
	world.setBlock(i + 6, j + 6, k + 2, biomeTopBlock);
	world.setBlock(i + 6, j + 6, k + 3, biomeTopBlock);
	world.setBlock(i + 6, j + 6, k + 4, biomeTopBlock);
	world.setBlock(i + 6, j + 6, k + 5, biomeTopBlock);
	world.setBlock(i + 6, j + 6, k + 6, biomeTopBlock);
	world.setBlock(i + 6, j + 7, k + 0, 0);
	world.setBlock(i + 6, j + 7, k + 1, 0);
	world.setBlock(i + 6, j + 7, k + 2, 0);
	world.setBlock(i + 6, j + 7, k + 3, 0);
	world.setBlock(i + 6, j + 7, k + 4, 0);
	world.setBlock(i + 6, j + 7, k + 5, 0);
	world.setBlock(i + 6, j + 7, k + 6, 0);
	world.setBlock(i + 6, j + 8, k + 0, 0);
	world.setBlock(i + 6, j + 8, k + 1, 0);
	world.setBlock(i + 6, j + 8, k + 2, 0);
	world.setBlock(i + 6, j + 8, k + 3, 0);
	world.setBlock(i + 6, j + 8, k + 4, 0);
	world.setBlock(i + 6, j + 8, k + 5, 0);
	world.setBlock(i + 6, j + 8, k + 6, 0);
	world.setBlock(i + 6, j + 9, k + 0, 0);
	world.setBlock(i + 6, j + 9, k + 1, 0);
	world.setBlock(i + 6, j + 9, k + 2, 0);
	world.setBlock(i + 6, j + 9, k + 3, 0);
	world.setBlock(i + 6, j + 9, k + 4, 0);
	world.setBlock(i + 6, j + 9, k + 5, 0);
	world.setBlock(i + 6, j + 9, k + 6, 0);
	world.setBlockMetadataWithNotify(i + 2, j + 9, k + 1, Block.torchWood.blockID, 4);
	world.setBlockMetadataWithNotify(i + 2, j + 9, k + 5, Block.torchWood.blockID, 3);
	world.setBlockMetadataWithNotify(i + 4, j + 9, k + 1, Block.torchWood.blockID, 4);
	world.setBlockMetadataWithNotify(i + 4, j + 9, k + 5, Block.torchWood.blockID, 3);
	
	world.setBlock(i + 3, k + 3, j + 1, Block.mobSpawner.blockID);
    TileEntityMobSpawner tileentitymobspawner = (TileEntityMobSpawner)world.getBlockTileEntity(i + 3, k + 3, j + 1);

    if (tileentitymobspawner != null) {
        tileentitymobspawner.func_98049_a().setMobID(DungeonHooks.getRandomDungeonMob(new Random()));
    }
	
	world.setBlock(i + 3, k + 3, j + 0, Block.chest.blockID);
    TileEntityChest tile = (TileEntityChest)world.getBlockTileEntity(i + 3, k + 3, j + 0);
    if(tile != null) {
    	Random rand = new Random();
    	WeightedRandomChestContent.generateChestContents(rand, ChestGenHooks.getItems(ChestGenHooks.DUNGEON_CHEST, rand), tile, ChestGenHooks.getCount(ChestGenHooks.DUNGEON_CHEST, rand));
    }
		}
		
	}
	
	}
}
