/*
*** MADE BY MITHION'S .SCHEMATIC TO JAVA CONVERTING TOOL v1.6 ***
*/
/**
package mods.jameslfc19.practise.world.gen;
import java.util.Random;

import net.minecraft.block.Block;
import net.minecraft.world.World;
import net.minecraft.world.gen.feature.WorldGenerator;

public class WorldGenCastle extends WorldGenerator
{
	public WorldGenCastle() { }

	public boolean generate(World world, Random rand, int i, int j, int k) {
		world.setBlock(i + 1, j + 0, k + 0, Block.grass.blockID);
		world.setBlock(i + 1, j + 0, k + 1, Block.grass.blockID);
		world.setBlock(i + 1, j + 0, k + 2, Block.grass.blockID);
		world.setBlock(i + 1, j + 0, k + 3, Block.grass.blockID);
		world.setBlock(i + 1, j + 0, k + 4, Block.grass.blockID);
		world.setBlock(i + 1, j + 0, k + 5, Block.grass.blockID);
		world.setBlock(i + 1, j + 0, k + 6, Block.grass.blockID);
		world.setBlock(i + 1, j + 0, k + 7, Block.grass.blockID);
		world.setBlock(i + 1, j + 0, k + 8, Block.grass.blockID);
		world.setBlock(i + 1, j + 0, k + 9, Block.grass.blockID);
		world.setBlock(i + 1, j + 0, k + 10, Block.grass.blockID);
		world.setBlock(i + 1, j + 0, k + 11, Block.grass.blockID);
		world.setBlock(i + 1, j + 0, k + 12, Block.grass.blockID);
		world.setBlock(i + 1, j + 0, k + 13, Block.grass.blockID);
		world.setBlock(i + 1, j + 0, k + 14, Block.grass.blockID);
		world.setBlock(i + 1, j + 0, k + 15, Block.grass.blockID);
		world.setBlock(i + 1, j + 0, k + 16, Block.grass.blockID);
		world.setBlock(i + 1, j + 0, k + 17, Block.grass.blockID);
		world.setBlock(i + 1, j + 0, k + 18, Block.grass.blockID);
		world.setBlock(i + 1, j + 0, k + 19, Block.grass.blockID);
		world.setBlock(i + 1, j + 0, k + 20, Block.grass.blockID);
		world.setBlock(i + 1, j + 0, k + 21, Block.grass.blockID);
		world.setBlock(i + 1, j + 0, k + 22, Block.grass.blockID);
		world.setBlock(i + 1, j + 0, k + 23, Block.grass.blockID);
		world.setBlock(i + 1, j + 0, k + 24, Block.grass.blockID);
		world.setBlock(i + 1, j + 0, k + 25, Block.grass.blockID);
		world.setBlock(i + 1, j + 0, k + 26, Block.grass.blockID);
		world.setBlock(i + 1, j + 0, k + 27, Block.grass.blockID);
		world.setBlock(i + 1, j + 0, k + 28, Block.grass.blockID);
		world.setBlock(i + 1, j + 0, k + 29, Block.grass.blockID);
		world.setBlock(i + 1, j + 0, k + 30, Block.grass.blockID);
		world.setBlock(i + 1, j + 0, k + 31, Block.grass.blockID);
		world.setBlock(i + 1, j + 0, k + 32, Block.grass.blockID);
		world.setBlock(i + 1, j + 0, k + 33, Block.grass.blockID);
		world.setBlock(i + 1, j + 0, k + 34, Block.grass.blockID);
		world.setBlock(i + 1, j + 0, k + 35, Block.grass.blockID);
		world.setBlock(i + 1, j + 0, k + 36, Block.grass.blockID);
		world.setBlock(i + 1, j + 0, k + 37, Block.grass.blockID);
		world.setBlock(i + 1, j + 0, k + 38, Block.grass.blockID);
		world.setBlock(i + 1, j + 0, k + 39, Block.grass.blockID);
		world.setBlock(i + 1, j + 0, k + 40, Block.grass.blockID);
		world.setBlock(i + 1, j + 0, k + 41, Block.grass.blockID);
		world.setBlock(i + 1, j + 0, k + 42, Block.grass.blockID);
		world.setBlock(i + 1, j + 0, k + 43, Block.grass.blockID);
		world.setBlock(i + 1, j + 0, k + 44, Block.grass.blockID);
		world.setBlock(i + 1, j + 0, k + 45, Block.grass.blockID);
		world.setBlock(i + 1, j + 0, k + 46, Block.grass.blockID);
		world.setBlock(i + 1, j + 0, k + 47, Block.grass.blockID);
		world.setBlock(i + 1, j + 0, k + 48, Block.grass.blockID);
		world.setBlock(i + 1, j + 0, k + 49, Block.grass.blockID);
		world.setBlock(i + 1, j + 0, k + 50, Block.grass.blockID);
		world.setBlock(i + 1, j + 0, k + 51, Block.grass.blockID);
		world.setBlock(i + 2, j + 0, k + 0, Block.grass.blockID);
		world.setBlock(i + 2, j + 0, k + 1, Block.grass.blockID);
		world.setBlock(i + 2, j + 0, k + 2, Block.grass.blockID);
		world.setBlock(i + 2, j + 0, k + 3, Block.grass.blockID);
		world.setBlock(i + 2, j + 0, k + 4, Block.grass.blockID);
		world.setBlock(i + 2, j + 0, k + 5, Block.grass.blockID);
		world.setBlock(i + 2, j + 0, k + 6, Block.grass.blockID);
		world.setBlock(i + 2, j + 0, k + 7, Block.grass.blockID);
		world.setBlock(i + 2, j + 0, k + 8, Block.grass.blockID);
		world.setBlock(i + 2, j + 0, k + 9, Block.grass.blockID);
		world.setBlock(i + 2, j + 0, k + 10, Block.grass.blockID);
		world.setBlock(i + 2, j + 0, k + 11, Block.grass.blockID);
		world.setBlock(i + 2, j + 0, k + 12, Block.grass.blockID);
		world.setBlock(i + 2, j + 0, k + 13, Block.grass.blockID);
		world.setBlock(i + 2, j + 0, k + 14, Block.grass.blockID);
		world.setBlock(i + 2, j + 0, k + 15, Block.grass.blockID);
		world.setBlock(i + 2, j + 0, k + 16, Block.grass.blockID);
		world.setBlock(i + 2, j + 0, k + 17, Block.grass.blockID);
		world.setBlock(i + 2, j + 0, k + 18, Block.grass.blockID);
		world.setBlock(i + 2, j + 0, k + 19, Block.grass.blockID);
		world.setBlock(i + 2, j + 0, k + 20, Block.grass.blockID);
		world.setBlock(i + 2, j + 0, k + 21, Block.grass.blockID);
		world.setBlock(i + 2, j + 0, k + 22, Block.grass.blockID);
		world.setBlock(i + 2, j + 0, k + 23, Block.grass.blockID);
		world.setBlock(i + 2, j + 0, k + 24, Block.grass.blockID);
		world.setBlock(i + 2, j + 0, k + 25, Block.grass.blockID);
		world.setBlock(i + 2, j + 0, k + 26, Block.grass.blockID);
		world.setBlock(i + 2, j + 0, k + 27, Block.grass.blockID);
		world.setBlock(i + 2, j + 0, k + 28, Block.grass.blockID);
		world.setBlock(i + 2, j + 0, k + 29, Block.grass.blockID);
		world.setBlock(i + 2, j + 0, k + 30, Block.grass.blockID);
		world.setBlock(i + 2, j + 0, k + 31, Block.grass.blockID);
		world.setBlock(i + 2, j + 0, k + 32, Block.grass.blockID);
		world.setBlock(i + 2, j + 0, k + 33, Block.grass.blockID);
		world.setBlock(i + 2, j + 0, k + 34, Block.grass.blockID);
		world.setBlock(i + 2, j + 0, k + 35, Block.grass.blockID);
		world.setBlock(i + 2, j + 0, k + 36, Block.grass.blockID);
		world.setBlock(i + 2, j + 0, k + 37, Block.grass.blockID);
		world.setBlock(i + 2, j + 0, k + 38, Block.grass.blockID);
		world.setBlock(i + 2, j + 0, k + 39, Block.grass.blockID);
		world.setBlock(i + 2, j + 0, k + 40, Block.grass.blockID);
		world.setBlock(i + 2, j + 0, k + 41, Block.grass.blockID);
		world.setBlock(i + 2, j + 0, k + 42, Block.grass.blockID);
		world.setBlock(i + 2, j + 0, k + 43, Block.grass.blockID);
		world.setBlock(i + 2, j + 0, k + 44, Block.grass.blockID);
		world.setBlock(i + 2, j + 0, k + 45, Block.grass.blockID);
		world.setBlock(i + 2, j + 0, k + 46, Block.grass.blockID);
		world.setBlock(i + 2, j + 0, k + 47, Block.grass.blockID);
		world.setBlock(i + 2, j + 0, k + 48, Block.grass.blockID);
		world.setBlock(i + 2, j + 0, k + 49, Block.grass.blockID);
		world.setBlock(i + 2, j + 0, k + 50, Block.grass.blockID);
		world.setBlock(i + 2, j + 0, k + 51, Block.grass.blockID);
		world.setBlock(i + 3, j + 0, k + 0, Block.grass.blockID);
		world.setBlock(i + 3, j + 0, k + 1, Block.grass.blockID);
		world.setBlock(i + 3, j + 0, k + 2, Block.grass.blockID);
		world.setBlock(i + 3, j + 0, k + 3, Block.grass.blockID);
		world.setBlock(i + 3, j + 0, k + 4, Block.grass.blockID);
		world.setBlock(i + 3, j + 0, k + 5, Block.grass.blockID);
		world.setBlock(i + 3, j + 0, k + 6, Block.grass.blockID);
		world.setBlock(i + 3, j + 0, k + 7, Block.grass.blockID);
		world.setBlock(i + 3, j + 0, k + 8, Block.grass.blockID);
		world.setBlock(i + 3, j + 0, k + 9, Block.grass.blockID);
		world.setBlock(i + 3, j + 0, k + 10, Block.grass.blockID);
		world.setBlock(i + 3, j + 0, k + 11, Block.grass.blockID);
		world.setBlock(i + 3, j + 0, k + 12, Block.grass.blockID);
		world.setBlock(i + 3, j + 0, k + 13, Block.grass.blockID);
		world.setBlock(i + 3, j + 0, k + 14, Block.grass.blockID);
		world.setBlock(i + 3, j + 0, k + 15, Block.grass.blockID);
		world.setBlock(i + 3, j + 0, k + 16, Block.grass.blockID);
		world.setBlock(i + 3, j + 0, k + 17, Block.grass.blockID);
		world.setBlock(i + 3, j + 0, k + 18, Block.grass.blockID);
		world.setBlock(i + 3, j + 0, k + 19, Block.grass.blockID);
		world.setBlock(i + 3, j + 0, k + 20, Block.grass.blockID);
		world.setBlock(i + 3, j + 0, k + 21, Block.grass.blockID);
		world.setBlock(i + 3, j + 0, k + 22, Block.grass.blockID);
		world.setBlock(i + 3, j + 0, k + 23, Block.grass.blockID);
		world.setBlock(i + 3, j + 0, k + 24, Block.grass.blockID);
		world.setBlock(i + 3, j + 0, k + 25, Block.grass.blockID);
		world.setBlock(i + 3, j + 0, k + 26, Block.grass.blockID);
		world.setBlock(i + 3, j + 0, k + 27, Block.grass.blockID);
		world.setBlock(i + 3, j + 0, k + 28, Block.grass.blockID);
		world.setBlock(i + 3, j + 0, k + 29, Block.grass.blockID);
		world.setBlock(i + 3, j + 0, k + 30, Block.grass.blockID);
		world.setBlock(i + 3, j + 0, k + 31, Block.grass.blockID);
		world.setBlock(i + 3, j + 0, k + 32, Block.grass.blockID);
		world.setBlock(i + 3, j + 0, k + 33, Block.grass.blockID);
		world.setBlock(i + 3, j + 0, k + 34, Block.grass.blockID);
		world.setBlock(i + 3, j + 0, k + 35, Block.grass.blockID);
		world.setBlock(i + 3, j + 0, k + 36, Block.grass.blockID);
		world.setBlock(i + 3, j + 0, k + 37, Block.grass.blockID);
		world.setBlock(i + 3, j + 0, k + 38, Block.grass.blockID);
		world.setBlock(i + 3, j + 0, k + 39, Block.grass.blockID);
		world.setBlock(i + 3, j + 0, k + 40, Block.grass.blockID);
		world.setBlock(i + 3, j + 0, k + 41, Block.grass.blockID);
		world.setBlock(i + 3, j + 0, k + 42, Block.grass.blockID);
		world.setBlock(i + 3, j + 0, k + 43, Block.grass.blockID);
		world.setBlock(i + 3, j + 0, k + 44, Block.grass.blockID);
		world.setBlock(i + 3, j + 0, k + 45, Block.grass.blockID);
		world.setBlock(i + 3, j + 0, k + 46, Block.grass.blockID);
		world.setBlock(i + 3, j + 0, k + 47, Block.grass.blockID);
		world.setBlock(i + 3, j + 0, k + 48, Block.grass.blockID);
		world.setBlock(i + 3, j + 0, k + 49, Block.grass.blockID);
		world.setBlock(i + 3, j + 0, k + 50, Block.grass.blockID);
		world.setBlock(i + 3, j + 0, k + 51, Block.grass.blockID);
		world.setBlock(i + 4, j + 0, k + 0, Block.grass.blockID);
		world.setBlock(i + 4, j + 0, k + 1, Block.grass.blockID);
		world.setBlock(i + 4, j + 0, k + 2, Block.grass.blockID);
		world.setBlock(i + 4, j + 0, k + 3, Block.grass.blockID);
		world.setBlock(i + 4, j + 0, k + 4, Block.grass.blockID);
		world.setBlock(i + 4, j + 0, k + 5, Block.grass.blockID);
		world.setBlock(i + 4, j + 0, k + 6, Block.grass.blockID);
		world.setBlock(i + 4, j + 0, k + 7, Block.grass.blockID);
		world.setBlock(i + 4, j + 0, k + 8, Block.grass.blockID);
		world.setBlock(i + 4, j + 0, k + 9, Block.grass.blockID);
		world.setBlock(i + 4, j + 0, k + 10, Block.grass.blockID);
		world.setBlock(i + 4, j + 0, k + 11, Block.grass.blockID);
		world.setBlock(i + 4, j + 0, k + 12, Block.grass.blockID);
		world.setBlock(i + 4, j + 0, k + 13, Block.grass.blockID);
		world.setBlock(i + 4, j + 0, k + 14, Block.grass.blockID);
		world.setBlock(i + 4, j + 0, k + 15, Block.grass.blockID);
		world.setBlock(i + 4, j + 0, k + 16, Block.grass.blockID);
		world.setBlock(i + 4, j + 0, k + 17, Block.grass.blockID);
		world.setBlock(i + 4, j + 0, k + 18, Block.grass.blockID);
		world.setBlock(i + 4, j + 0, k + 19, Block.grass.blockID);
		world.setBlock(i + 4, j + 0, k + 20, Block.grass.blockID);
		world.setBlock(i + 4, j + 0, k + 21, Block.grass.blockID);
		world.setBlock(i + 4, j + 0, k + 22, Block.grass.blockID);
		world.setBlock(i + 4, j + 0, k + 23, Block.grass.blockID);
		world.setBlock(i + 4, j + 0, k + 24, Block.grass.blockID);
		world.setBlock(i + 4, j + 0, k + 25, Block.grass.blockID);
		world.setBlock(i + 4, j + 0, k + 26, Block.grass.blockID);
		world.setBlock(i + 4, j + 0, k + 27, Block.grass.blockID);
		world.setBlock(i + 4, j + 0, k + 28, Block.grass.blockID);
		world.setBlock(i + 4, j + 0, k + 29, Block.grass.blockID);
		world.setBlock(i + 4, j + 0, k + 30, Block.grass.blockID);
		world.setBlock(i + 4, j + 0, k + 31, Block.grass.blockID);
		world.setBlock(i + 4, j + 0, k + 32, Block.grass.blockID);
		world.setBlock(i + 4, j + 0, k + 33, Block.grass.blockID);
		world.setBlock(i + 4, j + 0, k + 34, Block.grass.blockID);
		world.setBlock(i + 4, j + 0, k + 35, Block.grass.blockID);
		world.setBlock(i + 4, j + 0, k + 36, Block.grass.blockID);
		world.setBlock(i + 4, j + 0, k + 37, Block.grass.blockID);
		world.setBlock(i + 4, j + 0, k + 38, Block.grass.blockID);
		world.setBlock(i + 4, j + 0, k + 39, Block.grass.blockID);
		world.setBlock(i + 4, j + 0, k + 40, Block.grass.blockID);
		world.setBlock(i + 4, j + 0, k + 41, Block.grass.blockID);
		world.setBlock(i + 4, j + 0, k + 42, Block.grass.blockID);
		world.setBlock(i + 4, j + 0, k + 43, Block.grass.blockID);
		world.setBlock(i + 4, j + 0, k + 44, Block.grass.blockID);
		world.setBlock(i + 4, j + 0, k + 45, Block.grass.blockID);
		world.setBlock(i + 4, j + 0, k + 46, Block.grass.blockID);
		world.setBlock(i + 4, j + 0, k + 47, Block.grass.blockID);
		world.setBlock(i + 4, j + 0, k + 48, Block.grass.blockID);
		world.setBlock(i + 4, j + 0, k + 49, Block.grass.blockID);
		world.setBlock(i + 4, j + 0, k + 50, Block.grass.blockID);
		world.setBlock(i + 4, j + 0, k + 51, Block.grass.blockID);
		world.setBlock(i + 5, j + 0, k + 0, Block.grass.blockID);
		world.setBlock(i + 5, j + 0, k + 1, Block.grass.blockID);
		world.setBlock(i + 5, j + 0, k + 2, Block.grass.blockID);
		world.setBlock(i + 5, j + 0, k + 3, Block.grass.blockID);
		world.setBlock(i + 5, j + 0, k + 4, Block.cobblestone.blockID);
		world.setBlock(i + 5, j + 0, k + 5, Block.cobblestone.blockID);
		world.setBlock(i + 5, j + 0, k + 6, Block.cobblestone.blockID);
		world.setBlock(i + 5, j + 0, k + 7, Block.cobblestone.blockID);
		world.setBlock(i + 5, j + 0, k + 8, Block.cobblestone.blockID);
		world.setBlock(i + 5, j + 0, k + 9, Block.cobblestone.blockID);
		world.setBlock(i + 5, j + 0, k + 10, Block.cobblestone.blockID);
		world.setBlock(i + 5, j + 0, k + 11, Block.cobblestone.blockID);
		world.setBlock(i + 5, j + 0, k + 12, Block.cobblestone.blockID);
		world.setBlock(i + 5, j + 0, k + 13, Block.cobblestone.blockID);
		world.setBlock(i + 5, j + 0, k + 14, Block.cobblestone.blockID);
		world.setBlock(i + 5, j + 0, k + 15, Block.cobblestone.blockID);
		world.setBlock(i + 5, j + 0, k + 16, Block.cobblestone.blockID);
		world.setBlock(i + 5, j + 0, k + 17, Block.cobblestone.blockID);
		world.setBlock(i + 5, j + 0, k + 18, Block.cobblestone.blockID);
		world.setBlock(i + 5, j + 0, k + 19, Block.cobblestone.blockID);
		world.setBlock(i + 5, j + 0, k + 20, Block.cobblestone.blockID);
		world.setBlock(i + 5, j + 0, k + 21, Block.cobblestone.blockID);
		world.setBlock(i + 5, j + 0, k + 22, Block.cobblestone.blockID);
		world.setBlock(i + 5, j + 0, k + 23, Block.cobblestone.blockID);
		world.setBlock(i + 5, j + 0, k + 24, Block.cobblestone.blockID);
		world.setBlock(i + 5, j + 0, k + 25, Block.cobblestone.blockID);
		world.setBlock(i + 5, j + 0, k + 26, Block.cobblestone.blockID);
		world.setBlock(i + 5, j + 0, k + 27, Block.cobblestone.blockID);
		world.setBlock(i + 5, j + 0, k + 28, Block.cobblestone.blockID);
		world.setBlock(i + 5, j + 0, k + 29, Block.cobblestone.blockID);
		world.setBlock(i + 5, j + 0, k + 30, Block.cobblestone.blockID);
		world.setBlock(i + 5, j + 0, k + 31, Block.cobblestone.blockID);
		world.setBlock(i + 5, j + 0, k + 32, Block.cobblestone.blockID);
		world.setBlock(i + 5, j + 0, k + 33, Block.cobblestone.blockID);
		world.setBlock(i + 5, j + 0, k + 34, Block.cobblestone.blockID);
		world.setBlock(i + 5, j + 0, k + 35, Block.cobblestone.blockID);
		world.setBlock(i + 5, j + 0, k + 36, Block.cobblestone.blockID);
		world.setBlock(i + 5, j + 0, k + 37, Block.cobblestone.blockID);
		world.setBlock(i + 5, j + 0, k + 38, Block.cobblestone.blockID);
		world.setBlock(i + 5, j + 0, k + 39, Block.cobblestone.blockID);
		world.setBlock(i + 5, j + 0, k + 40, Block.cobblestone.blockID);
		world.setBlock(i + 5, j + 0, k + 41, Block.cobblestone.blockID);
		world.setBlock(i + 5, j + 0, k + 42, Block.cobblestone.blockID);
		world.setBlock(i + 5, j + 0, k + 43, Block.cobblestone.blockID);
		world.setBlock(i + 5, j + 0, k + 44, Block.cobblestone.blockID);
		world.setBlock(i + 5, j + 0, k + 45, Block.cobblestone.blockID);
		world.setBlock(i + 5, j + 0, k + 46, Block.cobblestone.blockID);
		world.setBlock(i + 5, j + 0, k + 47, Block.cobblestone.blockID);
		world.setBlock(i + 5, j + 0, k + 48, Block.grass.blockID);
		world.setBlock(i + 5, j + 0, k + 49, Block.grass.blockID);
		world.setBlock(i + 5, j + 0, k + 50, Block.grass.blockID);
		world.setBlock(i + 5, j + 0, k + 51, Block.grass.blockID);
		world.setBlock(i + 6, j + 0, k + 0, Block.grass.blockID);
		world.setBlock(i + 6, j + 0, k + 1, Block.grass.blockID);
		world.setBlock(i + 6, j + 0, k + 2, Block.grass.blockID);
		world.setBlock(i + 6, j + 0, k + 3, Block.grass.blockID);
		world.setBlock(i + 6, j + 0, k + 4, Block.cobblestone.blockID);
		world.setBlock(i + 6, j + 0, k + 47, Block.cobblestone.blockID);
		world.setBlock(i + 6, j + 0, k + 48, Block.grass.blockID);
		world.setBlock(i + 6, j + 0, k + 49, Block.grass.blockID);
		world.setBlock(i + 6, j + 0, k + 50, Block.grass.blockID);
		world.setBlock(i + 6, j + 0, k + 51, Block.grass.blockID);
		world.setBlock(i + 6, j + 5, k + 5, Block.cobblestone.blockID);
		world.setBlock(i + 6, j + 5, k + 6, Block.cobblestone.blockID);
		world.setBlock(i + 6, j + 5, k + 7, Block.cobblestone.blockID);
		world.setBlock(i + 6, j + 5, k + 8, Block.cobblestone.blockID);
		world.setBlock(i + 6, j + 5, k + 9, Block.cobblestone.blockID);
		world.setBlock(i + 6, j + 5, k + 10, Block.cobblestone.blockID);
		world.setBlock(i + 6, j + 5, k + 11, Block.cobblestone.blockID);
		world.setBlock(i + 6, j + 5, k + 12, Block.cobblestone.blockID);
		world.setBlock(i + 6, j + 5, k + 13, Block.cobblestone.blockID);
		world.setBlock(i + 6, j + 5, k + 14, Block.cobblestone.blockID);
		world.setBlock(i + 6, j + 5, k + 15, Block.cobblestone.blockID);
		world.setBlock(i + 6, j + 5, k + 36, Block.cobblestone.blockID);
		world.setBlock(i + 6, j + 5, k + 37, Block.cobblestone.blockID);
		world.setBlock(i + 6, j + 5, k + 38, Block.cobblestone.blockID);
		world.setBlock(i + 6, j + 5, k + 39, Block.cobblestone.blockID);
		world.setBlock(i + 6, j + 5, k + 40, Block.cobblestone.blockID);
		world.setBlock(i + 6, j + 5, k + 41, Block.cobblestone.blockID);
		world.setBlock(i + 6, j + 5, k + 42, Block.cobblestone.blockID);
		world.setBlock(i + 6, j + 5, k + 43, Block.cobblestone.blockID);
		world.setBlock(i + 6, j + 5, k + 44, Block.cobblestone.blockID);
		world.setBlock(i + 6, j + 5, k + 45, Block.cobblestone.blockID);
		world.setBlock(i + 6, j + 5, k + 46, Block.cobblestone.blockID);
		world.setBlock(i + 6, j + 6, k + 5, Block.cobblestone.blockID);
		world.setBlock(i + 6, j + 6, k + 6, Block.cobblestone.blockID);
		world.setBlock(i + 6, j + 6, k + 7, Block.cobblestone.blockID);
		world.setBlock(i + 6, j + 6, k + 8, Block.cobblestone.blockID);
		world.setBlock(i + 6, j + 6, k + 9, Block.cobblestone.blockID);
		world.setBlock(i + 6, j + 6, k + 10, Block.cobblestone.blockID);
		world.setBlock(i + 6, j + 6, k + 11, Block.cobblestone.blockID);
		world.setBlock(i + 6, j + 6, k + 12, Block.cobblestone.blockID);
		world.setBlock(i + 6, j + 6, k + 13, Block.cobblestone.blockID);
		world.setBlock(i + 6, j + 6, k + 14, Block.cobblestone.blockID);
		world.setBlock(i + 6, j + 6, k + 15, Block.cobblestone.blockID);
		world.setBlock(i + 6, j + 6, k + 36, Block.cobblestone.blockID);
		world.setBlock(i + 6, j + 6, k + 37, Block.cobblestone.blockID);
		world.setBlock(i + 6, j + 6, k + 38, Block.cobblestone.blockID);
		world.setBlock(i + 6, j + 6, k + 39, Block.cobblestone.blockID);
		world.setBlock(i + 6, j + 6, k + 40, Block.cobblestone.blockID);
		world.setBlock(i + 6, j + 6, k + 41, Block.cobblestone.blockID);
		world.setBlock(i + 6, j + 6, k + 42, Block.cobblestone.blockID);
		world.setBlock(i + 6, j + 6, k + 43, Block.cobblestone.blockID);
		world.setBlock(i + 6, j + 6, k + 44, Block.cobblestone.blockID);
		world.setBlock(i + 6, j + 6, k + 45, Block.cobblestone.blockID);
		world.setBlock(i + 6, j + 6, k + 46, Block.cobblestone.blockID);
		world.setBlock(i + 6, j + 7, k + 5, Block.cobblestone.blockID);
		world.setBlock(i + 6, j + 7, k + 6, Block.cobblestone.blockID);
		world.setBlock(i + 6, j + 7, k + 8, Block.cobblestone.blockID);
		world.setBlock(i + 6, j + 7, k + 10, Block.cobblestone.blockID);
		world.setBlock(i + 6, j + 7, k + 12, Block.cobblestone.blockID);
		world.setBlock(i + 6, j + 7, k + 14, Block.cobblestone.blockID);
		world.setBlock(i + 6, j + 7, k + 15, Block.cobblestone.blockID);
		world.setBlock(i + 6, j + 7, k + 36, Block.cobblestone.blockID);
		world.setBlock(i + 6, j + 7, k + 37, Block.cobblestone.blockID);
		world.setBlock(i + 6, j + 7, k + 39, Block.cobblestone.blockID);
		world.setBlock(i + 6, j + 7, k + 41, Block.cobblestone.blockID);
		world.setBlock(i + 6, j + 7, k + 43, Block.cobblestone.blockID);
		world.setBlock(i + 6, j + 7, k + 45, Block.cobblestone.blockID);
		world.setBlock(i + 6, j + 7, k + 46, Block.cobblestone.blockID);
		world.setBlock(i + 6, j + 8, k + 5, Block.cobblestone.blockID);
		world.setBlock(i + 6, j + 8, k + 6, Block.cobblestone.blockID);
		world.setBlock(i + 6, j + 8, k + 7, Block.cobblestone.blockID);
		world.setBlock(i + 6, j + 8, k + 8, Block.cobblestone.blockID);
		world.setBlock(i + 6, j + 8, k + 9, Block.cobblestone.blockID);
		world.setBlock(i + 6, j + 8, k + 10, Block.cobblestone.blockID);
		world.setBlock(i + 6, j + 8, k + 11, Block.cobblestone.blockID);
		world.setBlock(i + 6, j + 8, k + 12, Block.cobblestone.blockID);
		world.setBlock(i + 6, j + 8, k + 13, Block.cobblestone.blockID);
		world.setBlock(i + 6, j + 8, k + 14, Block.cobblestone.blockID);
		world.setBlock(i + 6, j + 8, k + 15, Block.cobblestone.blockID);
		world.setBlock(i + 6, j + 8, k + 36, Block.cobblestone.blockID);
		world.setBlock(i + 6, j + 8, k + 37, Block.cobblestone.blockID);
		world.setBlock(i + 6, j + 8, k + 38, Block.cobblestone.blockID);
		world.setBlock(i + 6, j + 8, k + 39, Block.cobblestone.blockID);
		world.setBlock(i + 6, j + 8, k + 40, Block.cobblestone.blockID);
		world.setBlock(i + 6, j + 8, k + 41, Block.cobblestone.blockID);
		world.setBlock(i + 6, j + 8, k + 42, Block.cobblestone.blockID);
		world.setBlock(i + 6, j + 8, k + 43, Block.cobblestone.blockID);
		world.setBlock(i + 6, j + 8, k + 44, Block.cobblestone.blockID);
		world.setBlock(i + 6, j + 8, k + 45, Block.cobblestone.blockID);
		world.setBlock(i + 6, j + 8, k + 46, Block.cobblestone.blockID);
		world.setBlock(i + 6, j + 9, k + 5, Block.cobblestone.blockID);
		world.setBlock(i + 6, j + 9, k + 6, Block.cobblestone.blockID);
		world.setBlock(i + 6, j + 9, k + 7, Block.cobblestone.blockID);
		world.setBlock(i + 6, j + 9, k + 8, Block.cobblestone.blockID);
		world.setBlock(i + 6, j + 9, k + 9, Block.cobblestone.blockID);
		world.setBlock(i + 6, j + 9, k + 10, Block.cobblestone.blockID);
		world.setBlock(i + 6, j + 9, k + 11, Block.cobblestone.blockID);
		world.setBlock(i + 6, j + 9, k + 12, Block.cobblestone.blockID);
		world.setBlock(i + 6, j + 9, k + 13, Block.cobblestone.blockID);
		world.setBlock(i + 6, j + 9, k + 14, Block.cobblestone.blockID);
		world.setBlock(i + 6, j + 9, k + 15, Block.cobblestone.blockID);
		world.setBlock(i + 6, j + 9, k + 36, Block.cobblestone.blockID);
		world.setBlock(i + 6, j + 9, k + 37, Block.cobblestone.blockID);
		world.setBlock(i + 6, j + 9, k + 38, Block.cobblestone.blockID);
		world.setBlock(i + 6, j + 9, k + 39, Block.cobblestone.blockID);
		world.setBlock(i + 6, j + 9, k + 40, Block.cobblestone.blockID);
		world.setBlock(i + 6, j + 9, k + 41, Block.cobblestone.blockID);
		world.setBlock(i + 6, j + 9, k + 42, Block.cobblestone.blockID);
		world.setBlock(i + 6, j + 9, k + 43, Block.cobblestone.blockID);
		world.setBlock(i + 6, j + 9, k + 44, Block.cobblestone.blockID);
		world.setBlock(i + 6, j + 9, k + 45, Block.cobblestone.blockID);
		world.setBlock(i + 6, j + 9, k + 46, Block.cobblestone.blockID);
		world.setBlock(i + 6, j + 10, k + 5, Block.cobblestone.blockID);
		world.setBlock(i + 6, j + 10, k + 6, Block.cobblestone.blockID);
		world.setBlock(i + 6, j + 10, k + 8, Block.cobblestone.blockID);
		world.setBlock(i + 6, j + 10, k + 10, Block.cobblestone.blockID);
		world.setBlock(i + 6, j + 10, k + 12, Block.cobblestone.blockID);
		world.setBlock(i + 6, j + 10, k + 14, Block.cobblestone.blockID);
		world.setBlock(i + 6, j + 10, k + 15, Block.cobblestone.blockID);
		world.setBlock(i + 6, j + 10, k + 36, Block.cobblestone.blockID);
		world.setBlock(i + 6, j + 10, k + 37, Block.cobblestone.blockID);
		world.setBlock(i + 6, j + 10, k + 39, Block.cobblestone.blockID);
		world.setBlock(i + 6, j + 10, k + 41, Block.cobblestone.blockID);
		world.setBlock(i + 6, j + 10, k + 43, Block.cobblestone.blockID);
		world.setBlock(i + 6, j + 10, k + 45, Block.cobblestone.blockID);
		world.setBlock(i + 6, j + 10, k + 46, Block.cobblestone.blockID);
		world.setBlock(i + 6, j + 11, k + 5, Block.cobblestone.blockID);
		world.setBlock(i + 6, j + 11, k + 6, Block.cobblestone.blockID);
		world.setBlock(i + 6, j + 11, k + 7, Block.cobblestone.blockID);
		world.setBlock(i + 6, j + 11, k + 8, Block.cobblestone.blockID);
		world.setBlock(i + 6, j + 11, k + 9, Block.cobblestone.blockID);
		world.setBlock(i + 6, j + 11, k + 10, Block.cobblestone.blockID);
		world.setBlock(i + 6, j + 11, k + 11, Block.cobblestone.blockID);
		world.setBlock(i + 6, j + 11, k + 12, Block.cobblestone.blockID);
		world.setBlock(i + 6, j + 11, k + 13, Block.cobblestone.blockID);
		world.setBlock(i + 6, j + 11, k + 14, Block.cobblestone.blockID);
		world.setBlock(i + 6, j + 11, k + 15, Block.cobblestone.blockID);
		world.setBlock(i + 6, j + 11, k + 36, Block.cobblestone.blockID);
		world.setBlock(i + 6, j + 11, k + 37, Block.cobblestone.blockID);
		world.setBlock(i + 6, j + 11, k + 38, Block.cobblestone.blockID);
		world.setBlock(i + 6, j + 11, k + 39, Block.cobblestone.blockID);
		world.setBlock(i + 6, j + 11, k + 40, Block.cobblestone.blockID);
		world.setBlock(i + 6, j + 11, k + 41, Block.cobblestone.blockID);
		world.setBlock(i + 6, j + 11, k + 42, Block.cobblestone.blockID);
		world.setBlock(i + 6, j + 11, k + 43, Block.cobblestone.blockID);
		world.setBlock(i + 6, j + 11, k + 44, Block.cobblestone.blockID);
		world.setBlock(i + 6, j + 11, k + 45, Block.cobblestone.blockID);
		world.setBlock(i + 6, j + 11, k + 46, Block.cobblestone.blockID);
		world.setBlock(i + 6, j + 12, k + 5, Block.cobblestone.blockID);
		world.setBlock(i + 6, j + 12, k + 6, Block.cobblestone.blockID);
		world.setBlock(i + 6, j + 12, k + 7, Block.cobblestone.blockID);
		world.setBlock(i + 6, j + 12, k + 8, Block.cobblestone.blockID);
		world.setBlock(i + 6, j + 12, k + 9, Block.cobblestone.blockID);
		world.setBlock(i + 6, j + 12, k + 10, Block.cobblestone.blockID);
		world.setBlock(i + 6, j + 12, k + 11, Block.cobblestone.blockID);
		world.setBlock(i + 6, j + 12, k + 12, Block.cobblestone.blockID);
		world.setBlock(i + 6, j + 12, k + 13, Block.cobblestone.blockID);
		world.setBlock(i + 6, j + 12, k + 14, Block.cobblestone.blockID);
		world.setBlock(i + 6, j + 12, k + 15, Block.cobblestone.blockID);
		world.setBlock(i + 6, j + 12, k + 36, Block.cobblestone.blockID);
		world.setBlock(i + 6, j + 12, k + 37, Block.cobblestone.blockID);
		world.setBlock(i + 6, j + 12, k + 38, Block.cobblestone.blockID);
		world.setBlock(i + 6, j + 12, k + 39, Block.cobblestone.blockID);
		world.setBlock(i + 6, j + 12, k + 40, Block.cobblestone.blockID);
		world.setBlock(i + 6, j + 12, k + 41, Block.cobblestone.blockID);
		world.setBlock(i + 6, j + 12, k + 42, Block.cobblestone.blockID);
		world.setBlock(i + 6, j + 12, k + 43, Block.cobblestone.blockID);
		world.setBlock(i + 6, j + 12, k + 44, Block.cobblestone.blockID);
		world.setBlock(i + 6, j + 12, k + 45, Block.cobblestone.blockID);
		world.setBlock(i + 6, j + 12, k + 46, Block.cobblestone.blockID);
		world.setBlock(i + 6, j + 13, k + 5, Block.cobblestone.blockID);
		world.setBlock(i + 6, j + 13, k + 6, Block.cobblestone.blockID);
		world.setBlock(i + 6, j + 13, k + 8, Block.cobblestone.blockID);
		world.setBlock(i + 6, j + 13, k + 10, Block.cobblestone.blockID);
		world.setBlock(i + 6, j + 13, k + 12, Block.cobblestone.blockID);
		world.setBlock(i + 6, j + 13, k + 14, Block.cobblestone.blockID);
		world.setBlock(i + 6, j + 13, k + 15, Block.cobblestone.blockID);
		world.setBlock(i + 6, j + 13, k + 36, Block.cobblestone.blockID);
		world.setBlock(i + 6, j + 13, k + 37, Block.cobblestone.blockID);
		world.setBlock(i + 6, j + 13, k + 39, Block.cobblestone.blockID);
		world.setBlock(i + 6, j + 13, k + 41, Block.cobblestone.blockID);
		world.setBlock(i + 6, j + 13, k + 43, Block.cobblestone.blockID);
		world.setBlock(i + 6, j + 13, k + 45, Block.cobblestone.blockID);
		world.setBlock(i + 6, j + 13, k + 46, Block.cobblestone.blockID);
		world.setBlock(i + 7, j + 0, k + 0, Block.grass.blockID);
		world.setBlock(i + 7, j + 0, k + 1, Block.grass.blockID);
		world.setBlock(i + 7, j + 0, k + 2, Block.grass.blockID);
		world.setBlock(i + 7, j + 0, k + 3, Block.grass.blockID);
		world.setBlock(i + 7, j + 0, k + 4, Block.cobblestone.blockID);
		world.setBlock(i + 7, j + 0, k + 47, Block.cobblestone.blockID);
		world.setBlock(i + 7, j + 0, k + 48, Block.grass.blockID);
		world.setBlock(i + 7, j + 0, k + 49, Block.grass.blockID);
		world.setBlock(i + 7, j + 0, k + 50, Block.grass.blockID);
		world.setBlock(i + 7, j + 0, k + 51, Block.grass.blockID);
		world.setBlock(i + 7, j + 5, k + 5, Block.cobblestone.blockID);
		world.setBlock(i + 7, j + 5, k + 6, Block.cobblestone.blockID);
		world.setBlock(i + 7, j + 5, k + 7, Block.cobblestone.blockID);
		world.setBlock(i + 7, j + 5, k + 8, Block.cobblestone.blockID);
		world.setBlock(i + 7, j + 5, k + 9, Block.cobblestone.blockID);
		world.setBlock(i + 7, j + 5, k + 10, Block.cobblestone.blockID);
		world.setBlock(i + 7, j + 5, k + 11, Block.cobblestone.blockID);
		world.setBlock(i + 7, j + 5, k + 12, Block.cobblestone.blockID);
		world.setBlock(i + 7, j + 5, k + 13, Block.cobblestone.blockID);
		world.setBlock(i + 7, j + 5, k + 14, Block.cobblestone.blockID);
		world.setBlock(i + 7, j + 5, k + 15, Block.cobblestone.blockID);
		world.setBlock(i + 7, j + 5, k + 36, Block.cobblestone.blockID);
		world.setBlock(i + 7, j + 5, k + 37, Block.cobblestone.blockID);
		world.setBlock(i + 7, j + 5, k + 38, Block.cobblestone.blockID);
		world.setBlock(i + 7, j + 5, k + 39, Block.cobblestone.blockID);
		world.setBlock(i + 7, j + 5, k + 40, Block.cobblestone.blockID);
		world.setBlock(i + 7, j + 5, k + 41, Block.cobblestone.blockID);
		world.setBlock(i + 7, j + 5, k + 42, Block.cobblestone.blockID);
		world.setBlock(i + 7, j + 5, k + 43, Block.cobblestone.blockID);
		world.setBlock(i + 7, j + 5, k + 44, Block.cobblestone.blockID);
		world.setBlock(i + 7, j + 5, k + 45, Block.cobblestone.blockID);
		world.setBlock(i + 7, j + 5, k + 46, Block.cobblestone.blockID);
		world.setBlock(i + 7, j + 6, k + 5, Block.cobblestone.blockID);
		world.setBlock(i + 7, j + 6, k + 6, Block.cobblestone.blockID);
		world.setBlock(i + 7, j + 6, k + 8, Block.cobblestone.blockID);
		world.setBlock(i + 7, j + 6, k + 10, Block.cobblestone.blockID);
		world.setBlock(i + 7, j + 6, k + 12, Block.cobblestone.blockID);
		world.setBlock(i + 7, j + 6, k + 14, Block.cobblestone.blockID);
		world.setBlock(i + 7, j + 6, k + 15, Block.cobblestone.blockID);
		world.setBlock(i + 7, j + 6, k + 36, Block.cobblestone.blockID);
		world.setBlock(i + 7, j + 6, k + 37, Block.cobblestone.blockID);
		world.setBlock(i + 7, j + 6, k + 39, Block.cobblestone.blockID);
		world.setBlock(i + 7, j + 6, k + 41, Block.cobblestone.blockID);
		world.setBlock(i + 7, j + 6, k + 43, Block.cobblestone.blockID);
		world.setBlock(i + 7, j + 6, k + 45, Block.cobblestone.blockID);
		world.setBlock(i + 7, j + 6, k + 46, Block.cobblestone.blockID);
		world.setBlock(i + 7, j + 7, k + 5, Block.cobblestone.blockID);
		world.setBlock(i + 7, j + 7, k + 6, Block.cobblestone.blockID);
		world.setBlock(i + 7, j + 7, k + 8, Block.cobblestone.blockID);
		world.setBlock(i + 7, j + 7, k + 10, Block.cobblestone.blockID);
		world.setBlock(i + 7, j + 7, k + 12, Block.cobblestone.blockID);
		world.setBlock(i + 7, j + 7, k + 14, Block.cobblestone.blockID);
		world.setBlock(i + 7, j + 7, k + 15, Block.cobblestone.blockID);
		world.setBlock(i + 7, j + 7, k + 36, Block.cobblestone.blockID);
		world.setBlock(i + 7, j + 7, k + 37, Block.cobblestone.blockID);
		world.setBlock(i + 7, j + 7, k + 39, Block.cobblestone.blockID);
		world.setBlock(i + 7, j + 7, k + 41, Block.cobblestone.blockID);
		world.setBlock(i + 7, j + 7, k + 43, Block.cobblestone.blockID);
		world.setBlock(i + 7, j + 7, k + 45, Block.cobblestone.blockID);
		world.setBlock(i + 7, j + 7, k + 46, Block.cobblestone.blockID);
		world.setBlock(i + 7, j + 8, k + 5, Block.cobblestone.blockID);
		world.setBlock(i + 7, j + 8, k + 6, Block.cobblestone.blockID);
		world.setBlock(i + 7, j + 8, k + 7, Block.cobblestone.blockID);
		world.setBlock(i + 7, j + 8, k + 8, Block.cobblestone.blockID);
		world.setBlock(i + 7, j + 8, k + 9, Block.cobblestone.blockID);
		world.setBlock(i + 7, j + 8, k + 10, Block.cobblestone.blockID);
		world.setBlock(i + 7, j + 8, k + 11, Block.cobblestone.blockID);
		world.setBlock(i + 7, j + 8, k + 12, Block.cobblestone.blockID);
		world.setBlock(i + 7, j + 8, k + 13, Block.cobblestone.blockID);
		world.setBlock(i + 7, j + 8, k + 14, Block.cobblestone.blockID);
		world.setBlock(i + 7, j + 8, k + 15, Block.cobblestone.blockID);
		world.setBlock(i + 7, j + 8, k + 36, Block.cobblestone.blockID);
		world.setBlock(i + 7, j + 8, k + 37, Block.cobblestone.blockID);
		world.setBlock(i + 7, j + 8, k + 38, Block.cobblestone.blockID);
		world.setBlock(i + 7, j + 8, k + 39, Block.cobblestone.blockID);
		world.setBlock(i + 7, j + 8, k + 40, Block.cobblestone.blockID);
		world.setBlock(i + 7, j + 8, k + 41, Block.cobblestone.blockID);
		world.setBlock(i + 7, j + 8, k + 42, Block.cobblestone.blockID);
		world.setBlock(i + 7, j + 8, k + 43, Block.cobblestone.blockID);
		world.setBlock(i + 7, j + 8, k + 44, Block.cobblestone.blockID);
		world.setBlock(i + 7, j + 8, k + 45, Block.cobblestone.blockID);
		world.setBlock(i + 7, j + 8, k + 46, Block.cobblestone.blockID);
		world.setBlock(i + 7, j + 9, k + 5, Block.cobblestone.blockID);
		world.setBlock(i + 7, j + 9, k + 6, Block.cobblestone.blockID);
		world.setBlock(i + 7, j + 9, k + 8, Block.cobblestone.blockID);
		world.setBlock(i + 7, j + 9, k + 10, Block.cobblestone.blockID);
		world.setBlock(i + 7, j + 9, k + 12, Block.cobblestone.blockID);
		world.setBlock(i + 7, j + 9, k + 14, Block.cobblestone.blockID);
		world.setBlock(i + 7, j + 9, k + 15, Block.cobblestone.blockID);
		world.setBlock(i + 7, j + 9, k + 36, Block.cobblestone.blockID);
		world.setBlock(i + 7, j + 9, k + 37, Block.cobblestone.blockID);
		world.setBlock(i + 7, j + 9, k + 39, Block.cobblestone.blockID);
		world.setBlock(i + 7, j + 9, k + 41, Block.cobblestone.blockID);
		world.setBlock(i + 7, j + 9, k + 43, Block.cobblestone.blockID);
		world.setBlock(i + 7, j + 9, k + 45, Block.cobblestone.blockID);
		world.setBlock(i + 7, j + 9, k + 46, Block.cobblestone.blockID);
		world.setBlock(i + 7, j + 10, k + 5, Block.cobblestone.blockID);
		world.setBlock(i + 7, j + 10, k + 6, Block.cobblestone.blockID);
		world.setBlock(i + 7, j + 10, k + 8, Block.cobblestone.blockID);
		world.setBlock(i + 7, j + 10, k + 10, Block.cobblestone.blockID);
		world.setBlock(i + 7, j + 10, k + 12, Block.cobblestone.blockID);
		world.setBlock(i + 7, j + 10, k + 14, Block.cobblestone.blockID);
		world.setBlock(i + 7, j + 10, k + 15, Block.cobblestone.blockID);
		world.setBlock(i + 7, j + 10, k + 36, Block.cobblestone.blockID);
		world.setBlock(i + 7, j + 10, k + 37, Block.cobblestone.blockID);
		world.setBlock(i + 7, j + 10, k + 39, Block.cobblestone.blockID);
		world.setBlock(i + 7, j + 10, k + 41, Block.cobblestone.blockID);
		world.setBlock(i + 7, j + 10, k + 43, Block.cobblestone.blockID);
		world.setBlock(i + 7, j + 10, k + 45, Block.cobblestone.blockID);
		world.setBlock(i + 7, j + 10, k + 46, Block.cobblestone.blockID);
		world.setBlock(i + 7, j + 11, k + 5, Block.cobblestone.blockID);
		world.setBlock(i + 7, j + 11, k + 6, Block.cobblestone.blockID);
		world.setBlock(i + 7, j + 11, k + 7, Block.cobblestone.blockID);
		world.setBlock(i + 7, j + 11, k + 8, Block.cobblestone.blockID);
		world.setBlock(i + 7, j + 11, k + 9, Block.cobblestone.blockID);
		world.setBlock(i + 7, j + 11, k + 10, Block.cobblestone.blockID);
		world.setBlock(i + 7, j + 11, k + 11, Block.cobblestone.blockID);
		world.setBlock(i + 7, j + 11, k + 12, Block.cobblestone.blockID);
		world.setBlock(i + 7, j + 11, k + 13, Block.cobblestone.blockID);
		world.setBlock(i + 7, j + 11, k + 14, Block.cobblestone.blockID);
		world.setBlock(i + 7, j + 11, k + 15, Block.cobblestone.blockID);
		world.setBlock(i + 7, j + 11, k + 36, Block.cobblestone.blockID);
		world.setBlock(i + 7, j + 11, k + 37, Block.cobblestone.blockID);
		world.setBlock(i + 7, j + 11, k + 38, Block.cobblestone.blockID);
		world.setBlock(i + 7, j + 11, k + 39, Block.cobblestone.blockID);
		world.setBlock(i + 7, j + 11, k + 40, Block.cobblestone.blockID);
		world.setBlock(i + 7, j + 11, k + 41, Block.cobblestone.blockID);
		world.setBlock(i + 7, j + 11, k + 42, Block.cobblestone.blockID);
		world.setBlock(i + 7, j + 11, k + 43, Block.cobblestone.blockID);
		world.setBlock(i + 7, j + 11, k + 44, Block.cobblestone.blockID);
		world.setBlock(i + 7, j + 11, k + 45, Block.cobblestone.blockID);
		world.setBlock(i + 7, j + 11, k + 46, Block.cobblestone.blockID);
		world.setBlock(i + 7, j + 12, k + 5, Block.cobblestone.blockID);
		world.setBlock(i + 7, j + 12, k + 6, Block.cobblestone.blockID);
		world.setBlock(i + 7, j + 12, k + 8, Block.cobblestone.blockID);
		world.setBlock(i + 7, j + 12, k + 10, Block.cobblestone.blockID);
		world.setBlock(i + 7, j + 12, k + 12, Block.cobblestone.blockID);
		world.setBlock(i + 7, j + 12, k + 14, Block.cobblestone.blockID);
		world.setBlock(i + 7, j + 12, k + 15, Block.cobblestone.blockID);
		world.setBlock(i + 7, j + 12, k + 36, Block.cobblestone.blockID);
		world.setBlock(i + 7, j + 12, k + 37, Block.cobblestone.blockID);
		world.setBlock(i + 7, j + 12, k + 39, Block.cobblestone.blockID);
		world.setBlock(i + 7, j + 12, k + 41, Block.cobblestone.blockID);
		world.setBlock(i + 7, j + 12, k + 43, Block.cobblestone.blockID);
		world.setBlock(i + 7, j + 12, k + 45, Block.cobblestone.blockID);
		world.setBlock(i + 7, j + 12, k + 46, Block.cobblestone.blockID);
		world.setBlock(i + 7, j + 13, k + 5, Block.cobblestone.blockID);
		world.setBlock(i + 7, j + 13, k + 6, Block.cobblestone.blockID);
		world.setBlock(i + 7, j + 13, k + 8, Block.cobblestone.blockID);
		world.setBlock(i + 7, j + 13, k + 10, Block.cobblestone.blockID);
		world.setBlock(i + 7, j + 13, k + 12, Block.cobblestone.blockID);
		world.setBlock(i + 7, j + 13, k + 14, Block.cobblestone.blockID);
		world.setBlock(i + 7, j + 13, k + 15, Block.cobblestone.blockID);
		world.setBlock(i + 7, j + 13, k + 36, Block.cobblestone.blockID);
		world.setBlock(i + 7, j + 13, k + 37, Block.cobblestone.blockID);
		world.setBlock(i + 7, j + 13, k + 39, Block.cobblestone.blockID);
		world.setBlock(i + 7, j + 13, k + 41, Block.cobblestone.blockID);
		world.setBlock(i + 7, j + 13, k + 43, Block.cobblestone.blockID);
		world.setBlock(i + 7, j + 13, k + 45, Block.cobblestone.blockID);
		world.setBlock(i + 7, j + 13, k + 46, Block.cobblestone.blockID);
		world.setBlock(i + 7, j + 22, k + 7, Block.stairsWoodOak.blockID);
		world.setBlock(i + 7, j + 22, k + 8, Block.stairsWoodOak.blockID);
		world.setBlock(i + 7, j + 22, k + 9, Block.stairsWoodOak.blockID);
		world.setBlock(i + 7, j + 22, k + 10, Block.stairsWoodOak.blockID);
		world.setBlock(i + 7, j + 22, k + 11, Block.stairsWoodOak.blockID);
		world.setBlock(i + 7, j + 22, k + 12, Block.stairsWoodOak.blockID);
		world.setBlock(i + 7, j + 22, k + 13, Block.stairsWoodOak.blockID);
		world.setBlock(i + 7, j + 22, k + 37, Block.stairsWoodOak.blockID);
		world.setBlock(i + 7, j + 22, k + 38, Block.stairsWoodOak.blockID);
		world.setBlock(i + 7, j + 22, k + 39, Block.stairsWoodOak.blockID);
		world.setBlock(i + 7, j + 22, k + 40, Block.stairsWoodOak.blockID);
		world.setBlock(i + 7, j + 22, k + 41, Block.stairsWoodOak.blockID);
		world.setBlock(i + 7, j + 22, k + 42, Block.stairsWoodOak.blockID);
		world.setBlock(i + 7, j + 22, k + 43, Block.stairsWoodOak.blockID);
		world.setBlock(i + 7, j + 22, k + 44, Block.stairsWoodOak.blockID);
		world.setBlock(i + 8, j + 0, k + 0, Block.grass.blockID);
		world.setBlock(i + 8, j + 0, k + 1, Block.grass.blockID);
		world.setBlock(i + 8, j + 0, k + 2, Block.grass.blockID);
		world.setBlock(i + 8, j + 0, k + 3, Block.grass.blockID);
		world.setBlock(i + 8, j + 0, k + 4, Block.cobblestone.blockID);
		world.setBlock(i + 8, j + 0, k + 47, Block.cobblestone.blockID);
		world.setBlock(i + 8, j + 0, k + 48, Block.grass.blockID);
		world.setBlock(i + 8, j + 0, k + 49, Block.grass.blockID);
		world.setBlock(i + 8, j + 0, k + 50, Block.grass.blockID);
		world.setBlock(i + 8, j + 0, k + 51, Block.grass.blockID);
		world.setBlock(i + 8, j + 3, k + 7, Block.cobblestone.blockID);
		world.setBlock(i + 8, j + 3, k + 8, Block.cobblestone.blockID);
		world.setBlock(i + 8, j + 3, k + 9, Block.cobblestone.blockID);
		world.setBlock(i + 8, j + 3, k + 10, Block.cobblestone.blockID);
		world.setBlock(i + 8, j + 3, k + 11, Block.cobblestone.blockID);
		world.setBlock(i + 8, j + 3, k + 12, Block.cobblestone.blockID);
		world.setBlock(i + 8, j + 3, k + 13, Block.cobblestone.blockID);
		world.setBlock(i + 8, j + 3, k + 38, Block.cobblestone.blockID);
		world.setBlock(i + 8, j + 3, k + 39, Block.cobblestone.blockID);
		world.setBlock(i + 8, j + 3, k + 40, Block.cobblestone.blockID);
		world.setBlock(i + 8, j + 3, k + 41, Block.cobblestone.blockID);
		world.setBlock(i + 8, j + 3, k + 42, Block.cobblestone.blockID);
		world.setBlock(i + 8, j + 3, k + 43, Block.cobblestone.blockID);
		world.setBlock(i + 8, j + 3, k + 44, Block.cobblestone.blockID);
		world.setBlock(i + 8, j + 4, k + 7, Block.cobblestone.blockID);
		world.setBlock(i + 8, j + 4, k + 8, Block.cobblestone.blockID);
		world.setBlock(i + 8, j + 4, k + 9, Block.cobblestone.blockID);
		world.setBlock(i + 8, j + 4, k + 10, Block.cobblestone.blockID);
		world.setBlock(i + 8, j + 4, k + 11, Block.cobblestone.blockID);
		world.setBlock(i + 8, j + 4, k + 12, Block.cobblestone.blockID);
		world.setBlock(i + 8, j + 4, k + 13, Block.cobblestone.blockID);
		world.setBlock(i + 8, j + 4, k + 38, Block.cobblestone.blockID);
		world.setBlock(i + 8, j + 4, k + 39, Block.cobblestone.blockID);
		world.setBlock(i + 8, j + 4, k + 40, Block.cobblestone.blockID);
		world.setBlock(i + 8, j + 4, k + 41, Block.cobblestone.blockID);
		world.setBlock(i + 8, j + 4, k + 42, Block.cobblestone.blockID);
		world.setBlock(i + 8, j + 4, k + 43, Block.cobblestone.blockID);
		world.setBlock(i + 8, j + 4, k + 44, Block.cobblestone.blockID);
		world.setBlock(i + 8, j + 5, k + 5, Block.cobblestone.blockID);
		world.setBlock(i + 8, j + 5, k + 6, Block.cobblestone.blockID);
		world.setBlock(i + 8, j + 5, k + 7, Block.planks.blockID);
		world.setBlock(i + 8, j + 5, k + 8, Block.planks.blockID);
		world.setBlock(i + 8, j + 5, k + 9, Block.planks.blockID);
		world.setBlock(i + 8, j + 5, k + 10, Block.planks.blockID);
		world.setBlock(i + 8, j + 5, k + 11, Block.planks.blockID);
		world.setBlock(i + 8, j + 5, k + 12, Block.planks.blockID);
		world.setBlock(i + 8, j + 5, k + 13, Block.planks.blockID);
		world.setBlock(i + 8, j + 5, k + 14, Block.cobblestone.blockID);
		world.setBlock(i + 8, j + 5, k + 15, Block.cobblestone.blockID);
		world.setBlock(i + 8, j + 5, k + 36, Block.cobblestone.blockID);
		world.setBlock(i + 8, j + 5, k + 37, Block.cobblestone.blockID);
		world.setBlock(i + 8, j + 5, k + 38, Block.planks.blockID);
		world.setBlock(i + 8, j + 5, k + 39, Block.planks.blockID);
		world.setBlock(i + 8, j + 5, k + 40, Block.planks.blockID);
		world.setBlock(i + 8, j + 5, k + 41, Block.planks.blockID);
		world.setBlock(i + 8, j + 5, k + 42, Block.planks.blockID);
		world.setBlock(i + 8, j + 5, k + 43, Block.planks.blockID);
		world.setBlock(i + 8, j + 5, k + 44, Block.planks.blockID);
		world.setBlock(i + 8, j + 5, k + 45, Block.cobblestone.blockID);
		world.setBlock(i + 8, j + 5, k + 46, Block.cobblestone.blockID);
		world.setBlock(i + 8, j + 6, k + 5, Block.cobblestone.blockID);
		world.setBlock(i + 8, j + 6, k + 15, Block.cobblestone.blockID);
		world.setBlock(i + 8, j + 6, k + 36, Block.cobblestone.blockID);
		world.setBlock(i + 8, j + 6, k + 46, Block.cobblestone.blockID);
		world.setBlock(i + 8, j + 8, k + 5, Block.cobblestone.blockID);
		world.setBlock(i + 8, j + 8, k + 6, Block.cobblestone.blockID);
		world.setBlock(i + 8, j + 8, k + 7, Block.cobblestone.blockID);
		world.setBlock(i + 8, j + 8, k + 8, Block.cobblestone.blockID);
		world.setBlock(i + 8, j + 8, k + 9, Block.cobblestone.blockID);
		world.setBlock(i + 8, j + 8, k + 10, Block.cobblestone.blockID);
		world.setBlock(i + 8, j + 8, k + 11, Block.cobblestone.blockID);
		world.setBlock(i + 8, j + 8, k + 12, Block.cobblestone.blockID);
		world.setBlock(i + 8, j + 8, k + 13, Block.cobblestone.blockID);
		world.setBlock(i + 8, j + 8, k + 14, Block.cobblestone.blockID);
		world.setBlock(i + 8, j + 8, k + 15, Block.cobblestone.blockID);
		world.setBlock(i + 8, j + 8, k + 36, Block.cobblestone.blockID);
		world.setBlock(i + 8, j + 8, k + 37, Block.cobblestone.blockID);
		world.setBlock(i + 8, j + 8, k + 38, Block.cobblestone.blockID);
		world.setBlock(i + 8, j + 8, k + 39, Block.cobblestone.blockID);
		world.setBlock(i + 8, j + 8, k + 40, Block.cobblestone.blockID);
		world.setBlock(i + 8, j + 8, k + 41, Block.cobblestone.blockID);
		world.setBlock(i + 8, j + 8, k + 42, Block.cobblestone.blockID);
		world.setBlock(i + 8, j + 8, k + 43, Block.cobblestone.blockID);
		world.setBlock(i + 8, j + 8, k + 44, Block.cobblestone.blockID);
		world.setBlock(i + 8, j + 8, k + 45, Block.cobblestone.blockID);
		world.setBlock(i + 8, j + 8, k + 46, Block.cobblestone.blockID);
		world.setBlock(i + 8, j + 9, k + 5, Block.cobblestone.blockID);
		world.setBlock(i + 8, j + 9, k + 15, Block.cobblestone.blockID);
		world.setBlock(i + 8, j + 9, k + 36, Block.cobblestone.blockID);
		world.setBlock(i + 8, j + 9, k + 46, Block.cobblestone.blockID);
		world.setBlock(i + 8, j + 11, k + 5, Block.cobblestone.blockID);
		world.setBlock(i + 8, j + 11, k + 6, Block.cobblestone.blockID);
		world.setBlock(i + 8, j + 11, k + 7, Block.cobblestone.blockID);
		world.setBlock(i + 8, j + 11, k + 8, Block.cobblestone.blockID);
		world.setBlock(i + 8, j + 11, k + 9, Block.cobblestone.blockID);
		world.setBlock(i + 8, j + 11, k + 10, Block.cobblestone.blockID);
		world.setBlock(i + 8, j + 11, k + 11, Block.cobblestone.blockID);
		world.setBlock(i + 8, j + 11, k + 12, Block.cobblestone.blockID);
		world.setBlock(i + 8, j + 11, k + 13, Block.cobblestone.blockID);
		world.setBlock(i + 8, j + 11, k + 14, Block.cobblestone.blockID);
		world.setBlock(i + 8, j + 11, k + 15, Block.cobblestone.blockID);
		world.setBlock(i + 8, j + 11, k + 36, Block.cobblestone.blockID);
		world.setBlock(i + 8, j + 11, k + 37, Block.cobblestone.blockID);
		world.setBlock(i + 8, j + 11, k + 38, Block.cobblestone.blockID);
		world.setBlock(i + 8, j + 11, k + 39, Block.cobblestone.blockID);
		world.setBlock(i + 8, j + 11, k + 40, Block.cobblestone.blockID);
		world.setBlock(i + 8, j + 11, k + 41, Block.cobblestone.blockID);
		world.setBlock(i + 8, j + 11, k + 42, Block.cobblestone.blockID);
		world.setBlock(i + 8, j + 11, k + 43, Block.cobblestone.blockID);
		world.setBlock(i + 8, j + 11, k + 44, Block.cobblestone.blockID);
		world.setBlock(i + 8, j + 11, k + 45, Block.cobblestone.blockID);
		world.setBlock(i + 8, j + 11, k + 46, Block.cobblestone.blockID);
		world.setBlock(i + 8, j + 12, k + 5, Block.cobblestone.blockID);
		world.setBlock(i + 8, j + 12, k + 15, Block.cobblestone.blockID);
		world.setBlock(i + 8, j + 12, k + 36, Block.cobblestone.blockID);
		world.setBlock(i + 8, j + 12, k + 46, Block.cobblestone.blockID);
		world.setBlock(i + 8, j + 19, k + 7, Block.planks.blockID);
		world.setBlock(i + 8, j + 19, k + 8, Block.planks.blockID);
		world.setBlock(i + 8, j + 19, k + 9, Block.planks.blockID);
		world.setBlock(i + 8, j + 19, k + 10, Block.planks.blockID);
		world.setBlock(i + 8, j + 19, k + 11, Block.planks.blockID);
		world.setBlock(i + 8, j + 19, k + 12, Block.planks.blockID);
		world.setBlock(i + 8, j + 19, k + 13, Block.planks.blockID);
		world.setBlock(i + 8, j + 19, k + 37, Block.planks.blockID);
		world.setBlock(i + 8, j + 19, k + 38, Block.planks.blockID);
		world.setBlock(i + 8, j + 19, k + 39, Block.planks.blockID);
		world.setBlock(i + 8, j + 19, k + 40, Block.planks.blockID);
		world.setBlock(i + 8, j + 19, k + 41, Block.planks.blockID);
		world.setBlock(i + 8, j + 19, k + 42, Block.planks.blockID);
		world.setBlock(i + 8, j + 19, k + 43, Block.planks.blockID);
		world.setBlock(i + 8, j + 19, k + 44, Block.planks.blockID);
		world.setBlock(i + 8, j + 20, k + 7, Block.cobblestone.blockID);
		world.setBlock(i + 8, j + 20, k + 8, Block.stoneSingleSlab.blockID);
		world.setBlock(i + 8, j + 20, k + 9, Block.cobblestone.blockID);
		world.setBlock(i + 8, j + 20, k + 10, Block.stoneSingleSlab.blockID);
		world.setBlock(i + 8, j + 20, k + 11, Block.cobblestone.blockID);
		world.setBlock(i + 8, j + 20, k + 12, Block.stoneSingleSlab.blockID);
		world.setBlock(i + 8, j + 20, k + 13, Block.cobblestone.blockID);
		world.setBlock(i + 8, j + 20, k + 37, Block.cobblestone.blockID);
		world.setBlock(i + 8, j + 20, k + 38, Block.stoneSingleSlab.blockID);
		world.setBlock(i + 8, j + 20, k + 39, Block.cobblestone.blockID);
		world.setBlock(i + 8, j + 20, k + 40, Block.stoneSingleSlab.blockID);
		world.setBlock(i + 8, j + 20, k + 41, Block.stoneSingleSlab.blockID);
		world.setBlock(i + 8, j + 20, k + 42, Block.cobblestone.blockID);
		world.setBlock(i + 8, j + 20, k + 43, Block.stoneSingleSlab.blockID);
		world.setBlock(i + 8, j + 20, k + 44, Block.cobblestone.blockID);
		world.setBlock(i + 8, j + 21, k + 7, Block.cobblestone.blockID);
		world.setBlock(i + 8, j + 21, k + 9, Block.cobblestone.blockID);
		world.setBlock(i + 8, j + 21, k + 11, Block.cobblestone.blockID);
		world.setBlock(i + 8, j + 21, k + 13, Block.cobblestone.blockID);
		world.setBlock(i + 8, j + 21, k + 37, Block.cobblestone.blockID);
		world.setBlock(i + 8, j + 21, k + 39, Block.cobblestone.blockID);
		world.setBlock(i + 8, j + 21, k + 42, Block.cobblestone.blockID);
		world.setBlock(i + 8, j + 21, k + 44, Block.cobblestone.blockID);
		world.setBlock(i + 8, j + 22, k + 6, Block.stairsWoodOak.blockID);
		world.setBlock(i + 8, j + 22, k + 7, Block.planks.blockID);
		world.setBlock(i + 8, j + 22, k + 8, Block.cobblestone.blockID);
		world.setBlock(i + 8, j + 22, k + 9, Block.cobblestone.blockID);
		world.setBlock(i + 8, j + 22, k + 10, Block.cobblestone.blockID);
		world.setBlock(i + 8, j + 22, k + 11, Block.cobblestone.blockID);
		world.setBlock(i + 8, j + 22, k + 12, Block.cobblestone.blockID);
		world.setBlock(i + 8, j + 22, k + 13, Block.planks.blockID);
		world.setBlock(i + 8, j + 22, k + 14, Block.stairsWoodOak.blockID);
		world.setBlock(i + 8, j + 22, k + 36, Block.stairsWoodOak.blockID);
		world.setBlock(i + 8, j + 22, k + 37, Block.planks.blockID);
		world.setBlock(i + 8, j + 22, k + 38, Block.cobblestone.blockID);
		world.setBlock(i + 8, j + 22, k + 39, Block.cobblestone.blockID);
		world.setBlock(i + 8, j + 22, k + 40, Block.cobblestone.blockID);
		world.setBlock(i + 8, j + 22, k + 41, Block.cobblestone.blockID);
		world.setBlock(i + 8, j + 22, k + 42, Block.cobblestone.blockID);
		world.setBlock(i + 8, j + 22, k + 43, Block.cobblestone.blockID);
		world.setBlock(i + 8, j + 22, k + 44, Block.planks.blockID);
		world.setBlock(i + 8, j + 22, k + 45, Block.stairsWoodOak.blockID);
		world.setBlock(i + 8, j + 23, k + 8, Block.stairsWoodOak.blockID);
		world.setBlock(i + 8, j + 23, k + 9, Block.stairsWoodOak.blockID);
		world.setBlock(i + 8, j + 23, k + 10, Block.stairsWoodOak.blockID);
		world.setBlock(i + 8, j + 23, k + 11, Block.stairsWoodOak.blockID);
		world.setBlock(i + 8, j + 23, k + 12, Block.stairsWoodOak.blockID);
		world.setBlock(i + 8, j + 23, k + 38, Block.stairsWoodOak.blockID);
		world.setBlock(i + 8, j + 23, k + 39, Block.stairsWoodOak.blockID);
		world.setBlock(i + 8, j + 23, k + 40, Block.stairsWoodOak.blockID);
		world.setBlock(i + 8, j + 23, k + 41, Block.stairsWoodOak.blockID);
		world.setBlock(i + 8, j + 23, k + 42, Block.stairsWoodOak.blockID);
		world.setBlock(i + 8, j + 23, k + 43, Block.stairsWoodOak.blockID);
		world.setBlock(i + 9, j + 0, k + 0, Block.grass.blockID);
		world.setBlock(i + 9, j + 0, k + 1, Block.grass.blockID);
		world.setBlock(i + 9, j + 0, k + 2, Block.grass.blockID);
		world.setBlock(i + 9, j + 0, k + 3, Block.grass.blockID);
		world.setBlock(i + 9, j + 0, k + 4, Block.cobblestone.blockID);
		world.setBlock(i + 9, j + 0, k + 8, Block.cobblestone.blockID);
		world.setBlock(i + 9, j + 0, k + 9, Block.cobblestone.blockID);
		world.setBlock(i + 9, j + 0, k + 10, Block.cobblestone.blockID);
		world.setBlock(i + 9, j + 0, k + 11, Block.cobblestone.blockID);
		world.setBlock(i + 9, j + 0, k + 12, Block.cobblestone.blockID);
		world.setBlock(i + 9, j + 0, k + 39, Block.cobblestone.blockID);
		world.setBlock(i + 9, j + 0, k + 40, Block.cobblestone.blockID);
		world.setBlock(i + 9, j + 0, k + 41, Block.cobblestone.blockID);
		world.setBlock(i + 9, j + 0, k + 42, Block.cobblestone.blockID);
		world.setBlock(i + 9, j + 0, k + 43, Block.cobblestone.blockID);
		world.setBlock(i + 9, j + 0, k + 47, Block.cobblestone.blockID);
		world.setBlock(i + 9, j + 0, k + 48, Block.grass.blockID);
		world.setBlock(i + 9, j + 0, k + 49, Block.grass.blockID);
		world.setBlock(i + 9, j + 0, k + 50, Block.grass.blockID);
		world.setBlock(i + 9, j + 0, k + 51, Block.grass.blockID);
		world.setBlock(i + 9, j + 1, k + 8, Block.cobblestone.blockID);
		world.setBlock(i + 9, j + 1, k + 9, Block.cobblestone.blockID);
		world.setBlock(i + 9, j + 1, k + 10, Block.cobblestone.blockID);
		world.setBlock(i + 9, j + 1, k + 11, Block.cobblestone.blockID);
		world.setBlock(i + 9, j + 1, k + 12, Block.cobblestone.blockID);
		world.setBlock(i + 9, j + 1, k + 39, Block.cobblestone.blockID);
		world.setBlock(i + 9, j + 1, k + 40, Block.cobblestone.blockID);
		world.setBlock(i + 9, j + 1, k + 41, Block.cobblestone.blockID);
		world.setBlock(i + 9, j + 1, k + 42, Block.cobblestone.blockID);
		world.setBlock(i + 9, j + 1, k + 43, Block.cobblestone.blockID);
		world.setBlock(i + 9, j + 2, k + 8, Block.cobblestone.blockID);
		world.setBlock(i + 9, j + 2, k + 9, Block.cobblestone.blockID);
		world.setBlock(i + 9, j + 2, k + 10, Block.cobblestone.blockID);
		world.setBlock(i + 9, j + 2, k + 11, Block.cobblestone.blockID);
		world.setBlock(i + 9, j + 2, k + 12, Block.cobblestone.blockID);
		world.setBlock(i + 9, j + 2, k + 39, Block.cobblestone.blockID);
		world.setBlock(i + 9, j + 2, k + 40, Block.cobblestone.blockID);
		world.setBlock(i + 9, j + 2, k + 41, Block.cobblestone.blockID);
		world.setBlock(i + 9, j + 2, k + 42, Block.cobblestone.blockID);
		world.setBlock(i + 9, j + 2, k + 43, Block.cobblestone.blockID);
		world.setBlock(i + 9, j + 3, k + 7, Block.cobblestone.blockID);
		world.setBlock(i + 9, j + 3, k + 8, Block.cobblestone.blockID);
		world.setBlock(i + 9, j + 3, k + 9, Block.cobblestone.blockID);
		world.setBlock(i + 9, j + 3, k + 10, Block.cobblestone.blockID);
		world.setBlock(i + 9, j + 3, k + 11, Block.cobblestone.blockID);
		world.setBlock(i + 9, j + 3, k + 12, Block.cobblestone.blockID);
		world.setBlock(i + 9, j + 3, k + 13, Block.cobblestone.blockID);
		world.setBlock(i + 9, j + 3, k + 38, Block.cobblestone.blockID);
		world.setBlock(i + 9, j + 3, k + 39, Block.cobblestone.blockID);
		world.setBlock(i + 9, j + 3, k + 40, Block.cobblestone.blockID);
		world.setBlock(i + 9, j + 3, k + 41, Block.cobblestone.blockID);
		world.setBlock(i + 9, j + 3, k + 42, Block.cobblestone.blockID);
		world.setBlock(i + 9, j + 3, k + 43, Block.cobblestone.blockID);
		world.setBlock(i + 9, j + 3, k + 44, Block.cobblestone.blockID);
		world.setBlock(i + 9, j + 4, k + 7, Block.cobblestone.blockID);
		world.setBlock(i + 9, j + 4, k + 8, Block.cobblestone.blockID);
		world.setBlock(i + 9, j + 4, k + 9, Block.cobblestone.blockID);
		world.setBlock(i + 9, j + 4, k + 10, Block.cobblestone.blockID);
		world.setBlock(i + 9, j + 4, k + 11, Block.cobblestone.blockID);
		world.setBlock(i + 9, j + 4, k + 12, Block.cobblestone.blockID);
		world.setBlock(i + 9, j + 4, k + 13, Block.cobblestone.blockID);
		world.setBlock(i + 9, j + 4, k + 38, Block.cobblestone.blockID);
		world.setBlock(i + 9, j + 4, k + 39, Block.cobblestone.blockID);
		world.setBlock(i + 9, j + 4, k + 40, Block.cobblestone.blockID);
		world.setBlock(i + 9, j + 4, k + 41, Block.cobblestone.blockID);
		world.setBlock(i + 9, j + 4, k + 42, Block.cobblestone.blockID);
		world.setBlock(i + 9, j + 4, k + 43, Block.cobblestone.blockID);
		world.setBlock(i + 9, j + 4, k + 44, Block.cobblestone.blockID);
		world.setBlock(i + 9, j + 5, k + 5, Block.cobblestone.blockID);
		world.setBlock(i + 9, j + 5, k + 6, Block.cobblestone.blockID);
		world.setBlock(i + 9, j + 5, k + 7, Block.planks.blockID);
		world.setBlock(i + 9, j + 5, k + 8, Block.planks.blockID);
		world.setBlock(i + 9, j + 5, k + 9, Block.planks.blockID);
		world.setBlock(i + 9, j + 5, k + 10, Block.planks.blockID);
		world.setBlock(i + 9, j + 5, k + 11, Block.planks.blockID);
		world.setBlock(i + 9, j + 5, k + 12, Block.planks.blockID);
		world.setBlock(i + 9, j + 5, k + 13, Block.planks.blockID);
		world.setBlock(i + 9, j + 5, k + 14, Block.cobblestone.blockID);
		world.setBlock(i + 9, j + 5, k + 15, Block.cobblestone.blockID);
		world.setBlock(i + 9, j + 5, k + 16, Block.cobblestone.blockID);
		world.setBlock(i + 9, j + 5, k + 17, Block.cobblestone.blockID);
		world.setBlock(i + 9, j + 5, k + 18, Block.cobblestone.blockID);
		world.setBlock(i + 9, j + 5, k + 19, Block.cobblestone.blockID);
		world.setBlock(i + 9, j + 5, k + 20, Block.cobblestone.blockID);
		world.setBlock(i + 9, j + 5, k + 21, Block.cobblestone.blockID);
		world.setBlock(i + 9, j + 5, k + 22, Block.cobblestone.blockID);
		world.setBlock(i + 9, j + 5, k + 23, Block.cobblestone.blockID);
		world.setBlock(i + 9, j + 5, k + 24, Block.cobblestone.blockID);
		world.setBlock(i + 9, j + 5, k + 25, Block.cobblestone.blockID);
		world.setBlock(i + 9, j + 5, k + 26, Block.cobblestone.blockID);
		world.setBlock(i + 9, j + 5, k + 27, Block.cobblestone.blockID);
		world.setBlock(i + 9, j + 5, k + 28, Block.cobblestone.blockID);
		world.setBlock(i + 9, j + 5, k + 29, Block.cobblestone.blockID);
		world.setBlock(i + 9, j + 5, k + 30, Block.cobblestone.blockID);
		world.setBlock(i + 9, j + 5, k + 31, Block.cobblestone.blockID);
		world.setBlock(i + 9, j + 5, k + 32, Block.cobblestone.blockID);
		world.setBlock(i + 9, j + 5, k + 33, Block.cobblestone.blockID);
		world.setBlock(i + 9, j + 5, k + 34, Block.cobblestone.blockID);
		world.setBlock(i + 9, j + 5, k + 35, Block.cobblestone.blockID);
		world.setBlock(i + 9, j + 5, k + 36, Block.cobblestone.blockID);
		world.setBlock(i + 9, j + 5, k + 37, Block.cobblestone.blockID);
		world.setBlock(i + 9, j + 5, k + 38, Block.planks.blockID);
		world.setBlock(i + 9, j + 5, k + 39, Block.planks.blockID);
		world.setBlock(i + 9, j + 5, k + 40, Block.planks.blockID);
		world.setBlock(i + 9, j + 5, k + 41, Block.planks.blockID);
		world.setBlock(i + 9, j + 5, k + 42, Block.planks.blockID);
		world.setBlock(i + 9, j + 5, k + 43, Block.planks.blockID);
		world.setBlock(i + 9, j + 5, k + 44, Block.planks.blockID);
		world.setBlock(i + 9, j + 5, k + 45, Block.cobblestone.blockID);
		world.setBlock(i + 9, j + 5, k + 46, Block.cobblestone.blockID);
		world.setBlock(i + 9, j + 6, k + 5, Block.cobblestone.blockID);
		world.setBlock(i + 9, j + 6, k + 6, Block.cobblestone.blockID);
		world.setBlock(i + 9, j + 6, k + 14, Block.cobblestone.blockID);
		world.setBlock(i + 9, j + 6, k + 15, Block.cobblestone.blockID);
		world.setBlock(i + 9, j + 6, k + 16, Block.cobblestone.blockID);
		world.setBlock(i + 9, j + 6, k + 17, Block.cobblestone.blockID);
		world.setBlock(i + 9, j + 6, k + 19, Block.cobblestone.blockID);
		world.setBlock(i + 9, j + 6, k + 20, Block.cobblestone.blockID);
		world.setBlock(i + 9, j + 6, k + 21, Block.cobblestone.blockID);
		world.setBlock(i + 9, j + 6, k + 23, Block.cobblestone.blockID);
		world.setBlock(i + 9, j + 6, k + 24, Block.cobblestone.blockID);
		world.setBlock(i + 9, j + 6, k + 25, Block.cobblestone.blockID);
		world.setBlock(i + 9, j + 6, k + 27, Block.cobblestone.blockID);
		world.setBlock(i + 9, j + 6, k + 28, Block.cobblestone.blockID);
		world.setBlock(i + 9, j + 6, k + 29, Block.cobblestone.blockID);
		world.setBlock(i + 9, j + 6, k + 31, Block.cobblestone.blockID);
		world.setBlock(i + 9, j + 6, k + 32, Block.cobblestone.blockID);
		world.setBlock(i + 9, j + 6, k + 33, Block.cobblestone.blockID);
		world.setBlock(i + 9, j + 6, k + 35, Block.cobblestone.blockID);
		world.setBlock(i + 9, j + 6, k + 36, Block.cobblestone.blockID);
		world.setBlock(i + 9, j + 6, k + 37, Block.cobblestone.blockID);
		world.setBlock(i + 9, j + 6, k + 45, Block.cobblestone.blockID);
		world.setBlock(i + 9, j + 6, k + 46, Block.cobblestone.blockID);
		world.setBlock(i + 9, j + 7, k + 5, Block.cobblestone.blockID);
		world.setBlock(i + 9, j + 7, k + 6, Block.cobblestone.blockID);
		world.setBlock(i + 9, j + 7, k + 14, Block.cobblestone.blockID);
		world.setBlock(i + 9, j + 7, k + 15, Block.cobblestone.blockID);
		world.setBlock(i + 9, j + 7, k + 16, Block.cobblestone.blockID);
		world.setBlock(i + 9, j + 7, k + 17, Block.cobblestone.blockID);
		world.setBlock(i + 9, j + 7, k + 18, Block.cobblestone.blockID);
		world.setBlock(i + 9, j + 7, k + 19, Block.cobblestone.blockID);
		world.setBlock(i + 9, j + 7, k + 20, Block.cobblestone.blockID);
		world.setBlock(i + 9, j + 7, k + 21, Block.cobblestone.blockID);
		world.setBlock(i + 9, j + 7, k + 22, Block.cobblestone.blockID);
		world.setBlock(i + 9, j + 7, k + 23, Block.cobblestone.blockID);
		world.setBlock(i + 9, j + 7, k + 24, Block.cobblestone.blockID);
		world.setBlock(i + 9, j + 7, k + 25, Block.cobblestone.blockID);
		world.setBlock(i + 9, j + 7, k + 26, Block.cobblestone.blockID);
		world.setBlock(i + 9, j + 7, k + 27, Block.cobblestone.blockID);
		world.setBlock(i + 9, j + 7, k + 28, Block.cobblestone.blockID);
		world.setBlock(i + 9, j + 7, k + 29, Block.cobblestone.blockID);
		world.setBlock(i + 9, j + 7, k + 30, Block.cobblestone.blockID);
		world.setBlock(i + 9, j + 7, k + 31, Block.cobblestone.blockID);
		world.setBlock(i + 9, j + 7, k + 32, Block.cobblestone.blockID);
		world.setBlock(i + 9, j + 7, k + 33, Block.cobblestone.blockID);
		world.setBlock(i + 9, j + 7, k + 34, Block.cobblestone.blockID);
		world.setBlock(i + 9, j + 7, k + 35, Block.cobblestone.blockID);
		world.setBlock(i + 9, j + 7, k + 36, Block.cobblestone.blockID);
		world.setBlock(i + 9, j + 7, k + 37, Block.cobblestone.blockID);
		world.setBlock(i + 9, j + 7, k + 45, Block.cobblestone.blockID);
		world.setBlock(i + 9, j + 7, k + 46, Block.cobblestone.blockID);
		world.setBlock(i + 9, j + 8, k + 5, Block.cobblestone.blockID);
		world.setBlock(i + 9, j + 8, k + 6, Block.cobblestone.blockID);
		world.setBlock(i + 9, j + 8, k + 7, Block.cobblestone.blockID);
		world.setBlock(i + 9, j + 8, k + 8, Block.cobblestone.blockID);
		world.setBlock(i + 9, j + 8, k + 9, Block.cobblestone.blockID);
		world.setBlock(i + 9, j + 8, k + 10, Block.cobblestone.blockID);
		world.setBlock(i + 9, j + 8, k + 11, Block.cobblestone.blockID);
		world.setBlock(i + 9, j + 8, k + 12, Block.cobblestone.blockID);
		world.setBlock(i + 9, j + 8, k + 13, Block.cobblestone.blockID);
		world.setBlock(i + 9, j + 8, k + 14, Block.cobblestone.blockID);
		world.setBlock(i + 9, j + 8, k + 15, Block.cobblestone.blockID);
		world.setBlock(i + 9, j + 8, k + 16, Block.cobblestone.blockID);
		world.setBlock(i + 9, j + 8, k + 17, Block.cobblestone.blockID);
		world.setBlock(i + 9, j + 8, k + 18, Block.cobblestone.blockID);
		world.setBlock(i + 9, j + 8, k + 19, Block.cobblestone.blockID);
		world.setBlock(i + 9, j + 8, k + 20, Block.cobblestone.blockID);
		world.setBlock(i + 9, j + 8, k + 21, Block.cobblestone.blockID);
		world.setBlock(i + 9, j + 8, k + 22, Block.cobblestone.blockID);
		world.setBlock(i + 9, j + 8, k + 23, Block.cobblestone.blockID);
		world.setBlock(i + 9, j + 8, k + 24, Block.cobblestone.blockID);
		world.setBlock(i + 9, j + 8, k + 25, Block.cobblestone.blockID);
		world.setBlock(i + 9, j + 8, k + 26, Block.cobblestone.blockID);
		world.setBlock(i + 9, j + 8, k + 27, Block.cobblestone.blockID);
		world.setBlock(i + 9, j + 8, k + 28, Block.cobblestone.blockID);
		world.setBlock(i + 9, j + 8, k + 29, Block.cobblestone.blockID);
		world.setBlock(i + 9, j + 8, k + 30, Block.cobblestone.blockID);
		world.setBlock(i + 9, j + 8, k + 31, Block.cobblestone.blockID);
		world.setBlock(i + 9, j + 8, k + 32, Block.cobblestone.blockID);
		world.setBlock(i + 9, j + 8, k + 33, Block.cobblestone.blockID);
		world.setBlock(i + 9, j + 8, k + 34, Block.cobblestone.blockID);
		world.setBlock(i + 9, j + 8, k + 35, Block.cobblestone.blockID);
		world.setBlock(i + 9, j + 8, k + 36, Block.cobblestone.blockID);
		world.setBlock(i + 9, j + 8, k + 37, Block.cobblestone.blockID);
		world.setBlock(i + 9, j + 8, k + 38, Block.cobblestone.blockID);
		world.setBlock(i + 9, j + 8, k + 39, Block.cobblestone.blockID);
		world.setBlock(i + 9, j + 8, k + 40, Block.cobblestone.blockID);
		world.setBlock(i + 9, j + 8, k + 41, Block.cobblestone.blockID);
		world.setBlock(i + 9, j + 8, k + 42, Block.cobblestone.blockID);
		world.setBlock(i + 9, j + 8, k + 43, Block.cobblestone.blockID);
		world.setBlock(i + 9, j + 8, k + 44, Block.cobblestone.blockID);
		world.setBlock(i + 9, j + 8, k + 45, Block.cobblestone.blockID);
		world.setBlock(i + 9, j + 8, k + 46, Block.cobblestone.blockID);
		world.setBlock(i + 9, j + 9, k + 5, Block.cobblestone.blockID);
		world.setBlock(i + 9, j + 9, k + 6, Block.cobblestone.blockID);
		world.setBlock(i + 9, j + 9, k + 13, Block.cobblestone.blockID);
		world.setBlock(i + 9, j + 9, k + 14, Block.cobblestone.blockID);
		world.setBlock(i + 9, j + 9, k + 15, Block.cobblestone.blockID);
		world.setBlock(i + 9, j + 9, k + 16, Block.cobblestone.blockID);
		world.setBlock(i + 9, j + 9, k + 17, Block.cobblestone.blockID);
		world.setBlock(i + 9, j + 9, k + 18, Block.cobblestone.blockID);
		world.setBlock(i + 9, j + 9, k + 19, Block.cobblestone.blockID);
		world.setBlock(i + 9, j + 9, k + 20, Block.cobblestone.blockID);
		world.setBlock(i + 9, j + 9, k + 21, Block.cobblestone.blockID);
		world.setBlock(i + 9, j + 9, k + 22, Block.cobblestone.blockID);
		world.setBlock(i + 9, j + 9, k + 23, Block.cobblestone.blockID);
		world.setBlock(i + 9, j + 9, k + 24, Block.cobblestone.blockID);
		world.setBlock(i + 9, j + 9, k + 25, Block.cobblestone.blockID);
		world.setBlock(i + 9, j + 9, k + 26, Block.cobblestone.blockID);
		world.setBlock(i + 9, j + 9, k + 27, Block.cobblestone.blockID);
		world.setBlock(i + 9, j + 9, k + 28, Block.cobblestone.blockID);
		world.setBlock(i + 9, j + 9, k + 29, Block.cobblestone.blockID);
		world.setBlock(i + 9, j + 9, k + 30, Block.cobblestone.blockID);
		world.setBlock(i + 9, j + 9, k + 31, Block.cobblestone.blockID);
		world.setBlock(i + 9, j + 9, k + 32, Block.cobblestone.blockID);
		world.setBlock(i + 9, j + 9, k + 33, Block.cobblestone.blockID);
		world.setBlock(i + 9, j + 9, k + 34, Block.cobblestone.blockID);
		world.setBlock(i + 9, j + 9, k + 35, Block.cobblestone.blockID);
		world.setBlock(i + 9, j + 9, k + 36, Block.cobblestone.blockID);
		world.setBlock(i + 9, j + 9, k + 37, Block.cobblestone.blockID);
		world.setBlock(i + 9, j + 9, k + 38, Block.cobblestone.blockID);
		world.setBlock(i + 9, j + 9, k + 45, Block.cobblestone.blockID);
		world.setBlock(i + 9, j + 9, k + 46, Block.cobblestone.blockID);
		world.setBlock(i + 9, j + 10, k + 5, Block.cobblestone.blockID);
		world.setBlock(i + 9, j + 10, k + 6, Block.cobblestone.blockID);
		world.setBlock(i + 9, j + 10, k + 13, Block.cobblestone.blockID);
		world.setBlock(i + 9, j + 10, k + 14, Block.cobblestone.blockID);
		world.setBlock(i + 9, j + 10, k + 15, Block.cobblestone.blockID);
		world.setBlock(i + 9, j + 10, k + 16, Block.cobblestone.blockID);
		world.setBlock(i + 9, j + 10, k + 17, Block.cobblestone.blockID);
		world.setBlock(i + 9, j + 10, k + 18, Block.cobblestone.blockID);
		world.setBlock(i + 9, j + 10, k + 19, Block.cobblestone.blockID);
		world.setBlock(i + 9, j + 10, k + 20, Block.cobblestone.blockID);
		world.setBlock(i + 9, j + 10, k + 21, Block.cobblestone.blockID);
		world.setBlock(i + 9, j + 10, k + 22, Block.cobblestone.blockID);
		world.setBlock(i + 9, j + 10, k + 23, Block.cobblestone.blockID);
		world.setBlock(i + 9, j + 10, k + 24, Block.cobblestone.blockID);
		world.setBlock(i + 9, j + 10, k + 25, Block.cobblestone.blockID);
		world.setBlock(i + 9, j + 10, k + 26, Block.cobblestone.blockID);
		world.setBlock(i + 9, j + 10, k + 27, Block.cobblestone.blockID);
		world.setBlock(i + 9, j + 10, k + 28, Block.cobblestone.blockID);
		world.setBlock(i + 9, j + 10, k + 29, Block.cobblestone.blockID);
		world.setBlock(i + 9, j + 10, k + 30, Block.cobblestone.blockID);
		world.setBlock(i + 9, j + 10, k + 31, Block.cobblestone.blockID);
		world.setBlock(i + 9, j + 10, k + 32, Block.cobblestone.blockID);
		world.setBlock(i + 9, j + 10, k + 33, Block.cobblestone.blockID);
		world.setBlock(i + 9, j + 10, k + 34, Block.cobblestone.blockID);
		world.setBlock(i + 9, j + 10, k + 35, Block.cobblestone.blockID);
		world.setBlock(i + 9, j + 10, k + 36, Block.cobblestone.blockID);
		world.setBlock(i + 9, j + 10, k + 37, Block.cobblestone.blockID);
		world.setBlock(i + 9, j + 10, k + 38, Block.cobblestone.blockID);
		world.setBlock(i + 9, j + 10, k + 45, Block.cobblestone.blockID);
		world.setBlock(i + 9, j + 10, k + 46, Block.cobblestone.blockID);
		world.setBlock(i + 9, j + 11, k + 5, Block.cobblestone.blockID);
		world.setBlock(i + 9, j + 11, k + 6, Block.cobblestone.blockID);
		world.setBlock(i + 9, j + 11, k + 7, Block.cobblestone.blockID);
		world.setBlock(i + 9, j + 11, k + 8, Block.cobblestone.blockID);
		world.setBlock(i + 9, j + 11, k + 9, Block.cobblestone.blockID);
		world.setBlock(i + 9, j + 11, k + 10, Block.cobblestone.blockID);
		world.setBlock(i + 9, j + 11, k + 11, Block.cobblestone.blockID);
		world.setBlock(i + 9, j + 11, k + 12, Block.cobblestone.blockID);
		world.setBlock(i + 9, j + 11, k + 13, Block.cobblestone.blockID);
		world.setBlock(i + 9, j + 11, k + 14, Block.cobblestone.blockID);
		world.setBlock(i + 9, j + 11, k + 15, Block.cobblestone.blockID);
		world.setBlock(i + 9, j + 11, k + 16, Block.cobblestone.blockID);
		world.setBlock(i + 9, j + 11, k + 17, Block.cobblestone.blockID);
		world.setBlock(i + 9, j + 11, k + 18, Block.cobblestone.blockID);
		world.setBlock(i + 9, j + 11, k + 19, Block.cobblestone.blockID);
		world.setBlock(i + 9, j + 11, k + 20, Block.cobblestone.blockID);
		world.setBlock(i + 9, j + 11, k + 21, Block.cobblestone.blockID);
		world.setBlock(i + 9, j + 11, k + 22, Block.cobblestone.blockID);
		world.setBlock(i + 9, j + 11, k + 23, Block.cobblestone.blockID);
		world.setBlock(i + 9, j + 11, k + 24, Block.cobblestone.blockID);
		world.setBlock(i + 9, j + 11, k + 25, Block.cobblestone.blockID);
		world.setBlock(i + 9, j + 11, k + 26, Block.cobblestone.blockID);
		world.setBlock(i + 9, j + 11, k + 27, Block.cobblestone.blockID);
		world.setBlock(i + 9, j + 11, k + 28, Block.cobblestone.blockID);
		world.setBlock(i + 9, j + 11, k + 29, Block.cobblestone.blockID);
		world.setBlock(i + 9, j + 11, k + 30, Block.cobblestone.blockID);
		world.setBlock(i + 9, j + 11, k + 31, Block.cobblestone.blockID);
		world.setBlock(i + 9, j + 11, k + 32, Block.cobblestone.blockID);
		world.setBlock(i + 9, j + 11, k + 33, Block.cobblestone.blockID);
		world.setBlock(i + 9, j + 11, k + 34, Block.cobblestone.blockID);
		world.setBlock(i + 9, j + 11, k + 35, Block.cobblestone.blockID);
		world.setBlock(i + 9, j + 11, k + 36, Block.cobblestone.blockID);
		world.setBlock(i + 9, j + 11, k + 37, Block.cobblestone.blockID);
		world.setBlock(i + 9, j + 11, k + 38, Block.cobblestone.blockID);
		world.setBlock(i + 9, j + 11, k + 39, Block.cobblestone.blockID);
		world.setBlock(i + 9, j + 11, k + 40, Block.cobblestone.blockID);
		world.setBlock(i + 9, j + 11, k + 41, Block.cobblestone.blockID);
		world.setBlock(i + 9, j + 11, k + 42, Block.cobblestone.blockID);
		world.setBlock(i + 9, j + 11, k + 43, Block.cobblestone.blockID);
		world.setBlock(i + 9, j + 11, k + 44, Block.cobblestone.blockID);
		world.setBlock(i + 9, j + 11, k + 45, Block.cobblestone.blockID);
		world.setBlock(i + 9, j + 11, k + 46, Block.cobblestone.blockID);
		world.setBlock(i + 9, j + 12, k + 5, Block.cobblestone.blockID);
		world.setBlock(i + 9, j + 12, k + 6, Block.cobblestone.blockID);
		world.setBlock(i + 9, j + 12, k + 8, Block.cobblestone.blockID);
		world.setBlock(i + 9, j + 12, k + 9, Block.cobblestone.blockID);
		world.setBlock(i + 9, j + 12, k + 10, Block.cobblestone.blockID);
		world.setBlock(i + 9, j + 12, k + 11, Block.cobblestone.blockID);
		world.setBlock(i + 9, j + 12, k + 12, Block.cobblestone.blockID);
		world.setBlock(i + 9, j + 12, k + 15, Block.cobblestone.blockID);
		world.setBlock(i + 9, j + 12, k + 16, Block.cobblestone.blockID);
		world.setBlock(i + 9, j + 12, k + 17, Block.cobblestone.blockID);
		world.setBlock(i + 9, j + 12, k + 18, Block.cobblestone.blockID);
		world.setBlock(i + 9, j + 12, k + 19, Block.cobblestone.blockID);
		world.setBlock(i + 9, j + 12, k + 20, Block.cobblestone.blockID);
		world.setBlock(i + 9, j + 12, k + 21, Block.cobblestone.blockID);
		world.setBlock(i + 9, j + 12, k + 22, Block.cobblestone.blockID);
		world.setBlock(i + 9, j + 12, k + 23, Block.cobblestone.blockID);
		world.setBlock(i + 9, j + 12, k + 24, Block.cobblestone.blockID);
		world.setBlock(i + 9, j + 12, k + 25, Block.cobblestone.blockID);
		world.setBlock(i + 9, j + 12, k + 26, Block.cobblestone.blockID);
		world.setBlock(i + 9, j + 12, k + 27, Block.cobblestone.blockID);
		world.setBlock(i + 9, j + 12, k + 28, Block.cobblestone.blockID);
		world.setBlock(i + 9, j + 12, k + 29, Block.cobblestone.blockID);
		world.setBlock(i + 9, j + 12, k + 30, Block.cobblestone.blockID);
		world.setBlock(i + 9, j + 12, k + 31, Block.cobblestone.blockID);
		world.setBlock(i + 9, j + 12, k + 32, Block.cobblestone.blockID);
		world.setBlock(i + 9, j + 12, k + 33, Block.cobblestone.blockID);
		world.setBlock(i + 9, j + 12, k + 34, Block.cobblestone.blockID);
		world.setBlock(i + 9, j + 12, k + 35, Block.cobblestone.blockID);
		world.setBlock(i + 9, j + 12, k + 36, Block.cobblestone.blockID);
		world.setBlock(i + 9, j + 12, k + 38, Block.cobblestone.blockID);
		world.setBlock(i + 9, j + 12, k + 39, Block.cobblestone.blockID);
		world.setBlock(i + 9, j + 12, k + 40, Block.cobblestone.blockID);
		world.setBlock(i + 9, j + 12, k + 41, Block.cobblestone.blockID);
		world.setBlock(i + 9, j + 12, k + 42, Block.cobblestone.blockID);
		world.setBlock(i + 9, j + 12, k + 43, Block.cobblestone.blockID);
		world.setBlock(i + 9, j + 12, k + 45, Block.cobblestone.blockID);
		world.setBlock(i + 9, j + 12, k + 46, Block.cobblestone.blockID);
		world.setBlock(i + 9, j + 13, k + 5, Block.cobblestone.blockID);
		world.setBlock(i + 9, j + 13, k + 6, Block.cobblestone.blockID);
		world.setBlock(i + 9, j + 13, k + 8, Block.cobblestone.blockID);
		world.setBlock(i + 9, j + 13, k + 9, Block.cobblestone.blockID);
		world.setBlock(i + 9, j + 13, k + 10, Block.cobblestone.blockID);
		world.setBlock(i + 9, j + 13, k + 11, Block.cobblestone.blockID);
		world.setBlock(i + 9, j + 13, k + 12, Block.cobblestone.blockID);
		world.setBlock(i + 9, j + 13, k + 15, Block.cobblestone.blockID);
		world.setBlock(i + 9, j + 13, k + 17, Block.cobblestone.blockID);
		world.setBlock(i + 9, j + 13, k + 19, Block.cobblestone.blockID);
		world.setBlock(i + 9, j + 13, k + 21, Block.cobblestone.blockID);
		world.setBlock(i + 9, j + 13, k + 23, Block.cobblestone.blockID);
		world.setBlock(i + 9, j + 13, k + 25, Block.cobblestone.blockID);
		world.setBlock(i + 9, j + 13, k + 26, Block.cobblestone.blockID);
		world.setBlock(i + 9, j + 13, k + 28, Block.cobblestone.blockID);
		world.setBlock(i + 9, j + 13, k + 30, Block.cobblestone.blockID);
		world.setBlock(i + 9, j + 13, k + 32, Block.cobblestone.blockID);
		world.setBlock(i + 9, j + 13, k + 34, Block.cobblestone.blockID);
		world.setBlock(i + 9, j + 13, k + 36, Block.cobblestone.blockID);
		world.setBlock(i + 9, j + 13, k + 38, Block.cobblestone.blockID);
		world.setBlock(i + 9, j + 13, k + 39, Block.cobblestone.blockID);
		world.setBlock(i + 9, j + 13, k + 40, Block.cobblestone.blockID);
		world.setBlock(i + 9, j + 13, k + 41, Block.cobblestone.blockID);
		world.setBlock(i + 9, j + 13, k + 42, Block.cobblestone.blockID);
		world.setBlock(i + 9, j + 13, k + 43, Block.cobblestone.blockID);
		world.setBlock(i + 9, j + 13, k + 45, Block.cobblestone.blockID);
		world.setBlock(i + 9, j + 13, k + 46, Block.cobblestone.blockID);
		world.setBlock(i + 9, j + 14, k + 8, Block.cobblestone.blockID);
		world.setBlock(i + 9, j + 14, k + 9, Block.cobblestone.blockID);
		world.setBlock(i + 9, j + 14, k + 10, Block.cobblestone.blockID);
		world.setBlock(i + 9, j + 14, k + 11, Block.cobblestone.blockID);
		world.setBlock(i + 9, j + 14, k + 12, Block.cobblestone.blockID);
		world.setBlock(i + 9, j + 14, k + 38, Block.cobblestone.blockID);
		world.setBlock(i + 9, j + 14, k + 39, Block.cobblestone.blockID);
		world.setBlock(i + 9, j + 14, k + 40, Block.cobblestone.blockID);
		world.setBlock(i + 9, j + 14, k + 41, Block.cobblestone.blockID);
		world.setBlock(i + 9, j + 14, k + 42, Block.cobblestone.blockID);
		world.setBlock(i + 9, j + 14, k + 43, Block.cobblestone.blockID);
		world.setBlock(i + 9, j + 15, k + 8, Block.cobblestone.blockID);
		world.setBlock(i + 9, j + 15, k + 9, Block.cobblestone.blockID);
		world.setBlock(i + 9, j + 15, k + 10, Block.cobblestone.blockID);
		world.setBlock(i + 9, j + 15, k + 11, Block.cobblestone.blockID);
		world.setBlock(i + 9, j + 15, k + 12, Block.cobblestone.blockID);
		world.setBlock(i + 9, j + 15, k + 38, Block.cobblestone.blockID);
		world.setBlock(i + 9, j + 15, k + 39, Block.cobblestone.blockID);
		world.setBlock(i + 9, j + 15, k + 40, Block.cobblestone.blockID);
		world.setBlock(i + 9, j + 15, k + 41, Block.cobblestone.blockID);
		world.setBlock(i + 9, j + 15, k + 42, Block.cobblestone.blockID);
		world.setBlock(i + 9, j + 15, k + 43, Block.cobblestone.blockID);
		world.setBlock(i + 9, j + 16, k + 8, Block.cobblestone.blockID);
		world.setBlock(i + 9, j + 16, k + 9, Block.cobblestone.blockID);
		world.setBlock(i + 9, j + 16, k + 10, Block.cobblestone.blockID);
		world.setBlock(i + 9, j + 16, k + 11, Block.cobblestone.blockID);
		world.setBlock(i + 9, j + 16, k + 12, Block.cobblestone.blockID);
		world.setBlock(i + 9, j + 16, k + 38, Block.cobblestone.blockID);
		world.setBlock(i + 9, j + 16, k + 39, Block.cobblestone.blockID);
		world.setBlock(i + 9, j + 16, k + 40, Block.cobblestone.blockID);
		world.setBlock(i + 9, j + 16, k + 41, Block.cobblestone.blockID);
		world.setBlock(i + 9, j + 16, k + 42, Block.cobblestone.blockID);
		world.setBlock(i + 9, j + 16, k + 43, Block.cobblestone.blockID);
		world.setBlock(i + 9, j + 17, k + 8, Block.cobblestone.blockID);
		world.setBlock(i + 9, j + 17, k + 9, Block.cobblestone.blockID);
		world.setBlock(i + 9, j + 17, k + 10, Block.cobblestone.blockID);
		world.setBlock(i + 9, j + 17, k + 11, Block.cobblestone.blockID);
		world.setBlock(i + 9, j + 17, k + 12, Block.cobblestone.blockID);
		world.setBlock(i + 9, j + 17, k + 38, Block.cobblestone.blockID);
		world.setBlock(i + 9, j + 17, k + 39, Block.cobblestone.blockID);
		world.setBlock(i + 9, j + 17, k + 40, Block.cobblestone.blockID);
		world.setBlock(i + 9, j + 17, k + 41, Block.cobblestone.blockID);
		world.setBlock(i + 9, j + 17, k + 42, Block.cobblestone.blockID);
		world.setBlock(i + 9, j + 17, k + 43, Block.cobblestone.blockID);
		world.setBlock(i + 9, j + 18, k + 8, Block.cobblestone.blockID);
		world.setBlock(i + 9, j + 18, k + 9, Block.cobblestone.blockID);
		world.setBlock(i + 9, j + 18, k + 10, Block.cobblestone.blockID);
		world.setBlock(i + 9, j + 18, k + 11, Block.cobblestone.blockID);
		world.setBlock(i + 9, j + 18, k + 12, Block.cobblestone.blockID);
		world.setBlock(i + 9, j + 18, k + 38, Block.cobblestone.blockID);
		world.setBlock(i + 9, j + 18, k + 39, Block.cobblestone.blockID);
		world.setBlock(i + 9, j + 18, k + 40, Block.cobblestone.blockID);
		world.setBlock(i + 9, j + 18, k + 41, Block.cobblestone.blockID);
		world.setBlock(i + 9, j + 18, k + 42, Block.cobblestone.blockID);
		world.setBlock(i + 9, j + 18, k + 43, Block.cobblestone.blockID);
		world.setBlock(i + 9, j + 19, k + 7, Block.planks.blockID);
		world.setBlock(i + 9, j + 19, k + 8, Block.planks.blockID);
		world.setBlock(i + 9, j + 19, k + 9, Block.planks.blockID);
		world.setBlock(i + 9, j + 19, k + 10, Block.planks.blockID);
		world.setBlock(i + 9, j + 19, k + 11, Block.planks.blockID);
		world.setBlock(i + 9, j + 19, k + 12, Block.planks.blockID);
		world.setBlock(i + 9, j + 19, k + 13, Block.planks.blockID);
		world.setBlock(i + 9, j + 19, k + 37, Block.planks.blockID);
		world.setBlock(i + 9, j + 19, k + 38, Block.planks.blockID);
		world.setBlock(i + 9, j + 19, k + 39, Block.planks.blockID);
		world.setBlock(i + 9, j + 19, k + 40, Block.planks.blockID);
		world.setBlock(i + 9, j + 19, k + 41, Block.planks.blockID);
		world.setBlock(i + 9, j + 19, k + 42, Block.planks.blockID);
		world.setBlock(i + 9, j + 19, k + 43, Block.planks.blockID);
		world.setBlock(i + 9, j + 19, k + 44, Block.planks.blockID);
		world.setBlockAndMetadata(i + 9, j + 20, k + 7, Block.stoneSingleSlab.blockID, 3);
		world.setBlockAndMetadata(i + 9, j + 20, k + 13, Block.stoneSingleSlab.blockID, 3);
		world.setBlockAndMetadata(i + 9, j + 20, k + 37, Block.stoneSingleSlab.blockID, 3);
		world.setBlockAndMetadata(i + 9, j + 20, k + 44, Block.stoneSingleSlab.blockID, 3);
		world.setBlockAndMetadata(i + 9, j + 22, k + 6, Block.stairsWoodOak.blockID, 2);
		world.setBlock(i + 9, j + 22, k + 7, Block.cobblestone.blockID);
		world.setBlock(i + 9, j + 22, k + 8, Block.cobblestone.blockID);
		world.setBlock(i + 9, j + 22, k + 9, Block.cobblestone.blockID);
		world.setBlock(i + 9, j + 22, k + 10, Block.cobblestone.blockID);
		world.setBlock(i + 9, j + 22, k + 11, Block.cobblestone.blockID);
		world.setBlock(i + 9, j + 22, k + 12, Block.cobblestone.blockID);
		world.setBlock(i + 9, j + 22, k + 13, Block.cobblestone.blockID);
		world.setBlockAndMetadata(i + 9, j + 22, k + 14, Block.stairsWoodOak.blockID, 3);
		world.setBlockAndMetadata(i + 9, j + 22, k + 36, Block.stairsWoodOak.blockID, 2);
		world.setBlock(i + 9, j + 22, k + 37, Block.cobblestone.blockID);
		world.setBlock(i + 9, j + 22, k + 38, Block.cobblestone.blockID);
		world.setBlock(i + 9, j + 22, k + 39, Block.cobblestone.blockID);
		world.setBlock(i + 9, j + 22, k + 40, Block.cobblestone.blockID);
		world.setBlock(i + 9, j + 22, k + 41, Block.cobblestone.blockID);
		world.setBlock(i + 9, j + 22, k + 42, Block.cobblestone.blockID);
		world.setBlock(i + 9, j + 22, k + 43, Block.cobblestone.blockID);
		world.setBlock(i + 9, j + 22, k + 44, Block.cobblestone.blockID);
		world.setBlockAndMetadata(i + 9, j + 22, k + 45, Block.stairsWoodOak.blockID, 3);
		world.setBlockAndMetadata(i + 9, j + 23, k + 7, Block.stairsWoodOak.blockID, 2);
		world.setBlock(i + 9, j + 23, k + 8, Block.planks.blockID);
		world.setBlock(i + 9, j + 23, k + 9, Block.sandStone.blockID);
		world.setBlock(i + 9, j + 23, k + 10, Block.sandStone.blockID);
		world.setBlock(i + 9, j + 23, k + 11, Block.sandStone.blockID);
		world.setBlock(i + 9, j + 23, k + 12, Block.planks.blockID);
		world.setBlockAndMetadata(i + 9, j + 23, k + 13, Block.stairsWoodOak.blockID, 3);
		world.setBlockAndMetadata(i + 9, j + 23, k + 37, Block.stairsWoodOak.blockID, 2);
		world.setBlock(i + 9, j + 23, k + 38, Block.planks.blockID);
		world.setBlock(i + 9, j + 23, k + 39, Block.sandStone.blockID);
		world.setBlock(i + 9, j + 23, k + 40, Block.sandStone.blockID);
		world.setBlock(i + 9, j + 23, k + 41, Block.sandStone.blockID);
		world.setBlock(i + 9, j + 23, k + 42, Block.sandStone.blockID);
		world.setBlock(i + 9, j + 23, k + 43, Block.planks.blockID);
		world.setBlockAndMetadata(i + 9, j + 23, k + 44, Block.stairsWoodOak.blockID, 3);
		world.setBlock(i + 9, j + 24, k + 9, Block.stairsWoodOak.blockID);
		world.setBlock(i + 9, j + 24, k + 10, Block.stairsWoodOak.blockID);
		world.setBlock(i + 9, j + 24, k + 11, Block.stairsWoodOak.blockID);
		world.setBlock(i + 9, j + 24, k + 39, Block.stairsWoodOak.blockID);
		world.setBlock(i + 9, j + 24, k + 40, Block.stairsWoodOak.blockID);
		world.setBlock(i + 9, j + 24, k + 41, Block.stairsWoodOak.blockID);
		world.setBlock(i + 9, j + 24, k + 42, Block.stairsWoodOak.blockID);
		world.setBlock(i + 10, j + 0, k + 0, Block.grass.blockID);
		world.setBlock(i + 10, j + 0, k + 1, Block.grass.blockID);
		world.setBlock(i + 10, j + 0, k + 2, Block.grass.blockID);
		world.setBlock(i + 10, j + 0, k + 3, Block.grass.blockID);
		world.setBlock(i + 10, j + 0, k + 4, Block.cobblestone.blockID);
		world.setBlock(i + 10, j + 0, k + 8, Block.cobblestone.blockID);
		world.setBlock(i + 10, j + 0, k + 12, Block.sandStone.blockID);
		world.setBlock(i + 10, j + 0, k + 13, Block.cobblestone.blockID);
		world.setBlock(i + 10, j + 0, k + 14, Block.cobblestone.blockID);
		world.setBlock(i + 10, j + 0, k + 15, Block.cobblestone.blockID);
		world.setBlock(i + 10, j + 0, k + 16, Block.cobblestone.blockID);
		world.setBlock(i + 10, j + 0, k + 17, Block.cobblestone.blockID);
		world.setBlock(i + 10, j + 0, k + 18, Block.cobblestone.blockID);
		world.setBlock(i + 10, j + 0, k + 19, Block.cobblestone.blockID);
		world.setBlock(i + 10, j + 0, k + 20, Block.cobblestone.blockID);
		world.setBlock(i + 10, j + 0, k + 21, Block.cobblestone.blockID);
		world.setBlock(i + 10, j + 0, k + 22, Block.cobblestone.blockID);
		world.setBlock(i + 10, j + 0, k + 23, Block.cobblestone.blockID);
		world.setBlock(i + 10, j + 0, k + 24, Block.cobblestone.blockID);
		world.setBlock(i + 10, j + 0, k + 25, Block.cobblestone.blockID);
		world.setBlock(i + 10, j + 0, k + 26, Block.cobblestone.blockID);
		world.setBlock(i + 10, j + 0, k + 27, Block.cobblestone.blockID);
		world.setBlock(i + 10, j + 0, k + 28, Block.cobblestone.blockID);
		world.setBlock(i + 10, j + 0, k + 29, Block.cobblestone.blockID);
		world.setBlock(i + 10, j + 0, k + 30, Block.cobblestone.blockID);
		world.setBlock(i + 10, j + 0, k + 31, Block.cobblestone.blockID);
		world.setBlock(i + 10, j + 0, k + 32, Block.cobblestone.blockID);
		world.setBlock(i + 10, j + 0, k + 33, Block.cobblestone.blockID);
		world.setBlock(i + 10, j + 0, k + 34, Block.cobblestone.blockID);
		world.setBlock(i + 10, j + 0, k + 35, Block.cobblestone.blockID);
		world.setBlock(i + 10, j + 0, k + 36, Block.cobblestone.blockID);
		world.setBlock(i + 10, j + 0, k + 37, Block.cobblestone.blockID);
		world.setBlock(i + 10, j + 0, k + 38, Block.cobblestone.blockID);
		world.setBlock(i + 10, j + 0, k + 43, Block.cobblestone.blockID);
		world.setBlock(i + 10, j + 0, k + 47, Block.cobblestone.blockID);
		world.setBlock(i + 10, j + 0, k + 48, Block.grass.blockID);
		world.setBlock(i + 10, j + 0, k + 49, Block.grass.blockID);
		world.setBlock(i + 10, j + 0, k + 50, Block.grass.blockID);
		world.setBlock(i + 10, j + 0, k + 51, Block.grass.blockID);
		world.setBlock(i + 10, j + 1, k + 8, Block.cobblestone.blockID);
		world.setBlock(i + 10, j + 1, k + 9, Block.cobblestone.blockID);
		world.setBlock(i + 10, j + 1, k + 10, Block.cobblestone.blockID);
		world.setBlock(i + 10, j + 1, k + 11, Block.cobblestone.blockID);
		world.setBlock(i + 10, j + 1, k + 12, Block.cobblestone.blockID);
		world.setBlock(i + 10, j + 1, k + 13, Block.cobblestone.blockID);
		world.setBlock(i + 10, j + 1, k + 14, Block.cobblestone.blockID);
		world.setBlock(i + 10, j + 1, k + 15, Block.cobblestone.blockID);
		world.setBlock(i + 10, j + 1, k + 16, Block.cobblestone.blockID);
		world.setBlock(i + 10, j + 1, k + 17, Block.cobblestone.blockID);
		world.setBlock(i + 10, j + 1, k + 18, Block.cobblestone.blockID);
		world.setBlock(i + 10, j + 1, k + 19, Block.cobblestone.blockID);
		world.setBlock(i + 10, j + 1, k + 20, Block.cobblestone.blockID);
		world.setBlock(i + 10, j + 1, k + 21, Block.cobblestone.blockID);
		world.setBlock(i + 10, j + 1, k + 22, Block.cobblestone.blockID);
		world.setBlock(i + 10, j + 1, k + 23, Block.cobblestone.blockID);
		world.setBlock(i + 10, j + 1, k + 24, Block.cobblestone.blockID);
		world.setBlock(i + 10, j + 1, k + 25, Block.cobblestone.blockID);
		world.setBlock(i + 10, j + 1, k + 26, Block.cobblestone.blockID);
		world.setBlock(i + 10, j + 1, k + 27, Block.cobblestone.blockID);
		world.setBlock(i + 10, j + 1, k + 28, Block.cobblestone.blockID);
		world.setBlock(i + 10, j + 1, k + 29, Block.cobblestone.blockID);
		world.setBlock(i + 10, j + 1, k + 30, Block.cobblestone.blockID);
		world.setBlock(i + 10, j + 1, k + 31, Block.cobblestone.blockID);
		world.setBlock(i + 10, j + 1, k + 32, Block.cobblestone.blockID);
		world.setBlock(i + 10, j + 1, k + 33, Block.cobblestone.blockID);
		world.setBlock(i + 10, j + 1, k + 34, Block.cobblestone.blockID);
		world.setBlock(i + 10, j + 1, k + 35, Block.cobblestone.blockID);
		world.setBlock(i + 10, j + 1, k + 36, Block.cobblestone.blockID);
		world.setBlock(i + 10, j + 1, k + 37, Block.cobblestone.blockID);
		world.setBlock(i + 10, j + 1, k + 38, Block.cobblestone.blockID);
		world.setBlock(i + 10, j + 1, k + 39, Block.cobblestone.blockID);
		world.setBlock(i + 10, j + 1, k + 40, Block.cobblestone.blockID);
		world.setBlock(i + 10, j + 1, k + 41, Block.cobblestone.blockID);
		world.setBlock(i + 10, j + 1, k + 42, Block.cobblestone.blockID);
		world.setBlock(i + 10, j + 1, k + 43, Block.cobblestone.blockID);
		world.setBlock(i + 10, j + 2, k + 8, Block.cobblestone.blockID);
		world.setBlock(i + 10, j + 2, k + 9, Block.cobblestone.blockID);
		world.setBlock(i + 10, j + 2, k + 10, Block.cobblestone.blockID);
		world.setBlock(i + 10, j + 2, k + 11, Block.cobblestone.blockID);
		world.setBlock(i + 10, j + 2, k + 12, Block.cobblestone.blockID);
		world.setBlock(i + 10, j + 2, k + 13, Block.cobblestone.blockID);
		world.setBlock(i + 10, j + 2, k + 14, Block.cobblestone.blockID);
		world.setBlock(i + 10, j + 2, k + 15, Block.cobblestone.blockID);
		world.setBlock(i + 10, j + 2, k + 16, Block.cobblestone.blockID);
		world.setBlock(i + 10, j + 2, k + 17, Block.cobblestone.blockID);
		world.setBlock(i + 10, j + 2, k + 18, Block.cobblestone.blockID);
		world.setBlock(i + 10, j + 2, k + 19, Block.cobblestone.blockID);
		world.setBlock(i + 10, j + 2, k + 20, Block.cobblestone.blockID);
		world.setBlock(i + 10, j + 2, k + 21, Block.cobblestone.blockID);
		world.setBlock(i + 10, j + 2, k + 22, Block.cobblestone.blockID);
		world.setBlock(i + 10, j + 2, k + 23, Block.cobblestone.blockID);
		world.setBlock(i + 10, j + 2, k + 24, Block.cobblestone.blockID);
		world.setBlock(i + 10, j + 2, k + 25, Block.cobblestone.blockID);
		world.setBlock(i + 10, j + 2, k + 26, Block.cobblestone.blockID);
		world.setBlock(i + 10, j + 2, k + 27, Block.cobblestone.blockID);
		world.setBlock(i + 10, j + 2, k + 28, Block.cobblestone.blockID);
		world.setBlock(i + 10, j + 2, k + 29, Block.cobblestone.blockID);
		world.setBlock(i + 10, j + 2, k + 30, Block.cobblestone.blockID);
		world.setBlock(i + 10, j + 2, k + 31, Block.cobblestone.blockID);
		world.setBlock(i + 10, j + 2, k + 32, Block.cobblestone.blockID);
		world.setBlock(i + 10, j + 2, k + 33, Block.cobblestone.blockID);
		world.setBlock(i + 10, j + 2, k + 34, Block.cobblestone.blockID);
		world.setBlock(i + 10, j + 2, k + 35, Block.cobblestone.blockID);
		world.setBlock(i + 10, j + 2, k + 36, Block.cobblestone.blockID);
		world.setBlock(i + 10, j + 2, k + 37, Block.cobblestone.blockID);
		world.setBlock(i + 10, j + 2, k + 38, Block.cobblestone.blockID);
		world.setBlock(i + 10, j + 2, k + 39, Block.cobblestone.blockID);
		world.setBlock(i + 10, j + 2, k + 40, Block.cobblestone.blockID);
		world.setBlock(i + 10, j + 2, k + 41, Block.cobblestone.blockID);
		world.setBlock(i + 10, j + 2, k + 42, Block.cobblestone.blockID);
		world.setBlock(i + 10, j + 2, k + 43, Block.cobblestone.blockID);
		world.setBlock(i + 10, j + 3, k + 7, Block.cobblestone.blockID);
		world.setBlock(i + 10, j + 3, k + 8, Block.cobblestone.blockID);
		world.setBlock(i + 10, j + 3, k + 9, Block.cobblestone.blockID);
		world.setBlock(i + 10, j + 3, k + 10, Block.cobblestone.blockID);
		world.setBlock(i + 10, j + 3, k + 11, Block.cobblestone.blockID);
		world.setBlock(i + 10, j + 3, k + 12, Block.cobblestone.blockID);
		world.setBlock(i + 10, j + 3, k + 13, Block.cobblestone.blockID);
		world.setBlock(i + 10, j + 3, k + 14, Block.cobblestone.blockID);
		world.setBlock(i + 10, j + 3, k + 15, Block.cobblestone.blockID);
		world.setBlock(i + 10, j + 3, k + 16, Block.cobblestone.blockID);
		world.setBlock(i + 10, j + 3, k + 17, Block.cobblestone.blockID);
		world.setBlock(i + 10, j + 3, k + 18, Block.cobblestone.blockID);
		world.setBlock(i + 10, j + 3, k + 19, Block.cobblestone.blockID);
		world.setBlock(i + 10, j + 3, k + 20, Block.cobblestone.blockID);
		world.setBlock(i + 10, j + 3, k + 21, Block.cobblestone.blockID);
		world.setBlock(i + 10, j + 3, k + 22, Block.cobblestone.blockID);
		world.setBlock(i + 10, j + 3, k + 23, Block.cobblestone.blockID);
		world.setBlock(i + 10, j + 3, k + 24, Block.cobblestone.blockID);
		world.setBlock(i + 10, j + 3, k + 25, Block.cobblestone.blockID);
		world.setBlock(i + 10, j + 3, k + 26, Block.cobblestone.blockID);
		world.setBlock(i + 10, j + 3, k + 27, Block.cobblestone.blockID);
		world.setBlock(i + 10, j + 3, k + 28, Block.cobblestone.blockID);
		world.setBlock(i + 10, j + 3, k + 29, Block.cobblestone.blockID);
		world.setBlock(i + 10, j + 3, k + 30, Block.cobblestone.blockID);
		world.setBlock(i + 10, j + 3, k + 31, Block.cobblestone.blockID);
		world.setBlock(i + 10, j + 3, k + 32, Block.cobblestone.blockID);
		world.setBlock(i + 10, j + 3, k + 33, Block.cobblestone.blockID);
		world.setBlock(i + 10, j + 3, k + 34, Block.cobblestone.blockID);
		world.setBlock(i + 10, j + 3, k + 35, Block.cobblestone.blockID);
		world.setBlock(i + 10, j + 3, k + 36, Block.cobblestone.blockID);
		world.setBlock(i + 10, j + 3, k + 37, Block.cobblestone.blockID);
		world.setBlock(i + 10, j + 3, k + 38, Block.cobblestone.blockID);
		world.setBlock(i + 10, j + 3, k + 39, Block.cobblestone.blockID);
		world.setBlock(i + 10, j + 3, k + 40, Block.cobblestone.blockID);
		world.setBlock(i + 10, j + 3, k + 41, Block.cobblestone.blockID);
		world.setBlock(i + 10, j + 3, k + 42, Block.cobblestone.blockID);
		world.setBlock(i + 10, j + 3, k + 43, Block.cobblestone.blockID);
		world.setBlock(i + 10, j + 3, k + 44, Block.cobblestone.blockID);
		world.setBlock(i + 10, j + 4, k + 7, Block.cobblestone.blockID);
		world.setBlock(i + 10, j + 4, k + 8, Block.cobblestone.blockID);
		world.setBlock(i + 10, j + 4, k + 9, Block.cobblestone.blockID);
		world.setBlock(i + 10, j + 4, k + 10, Block.cobblestone.blockID);
		world.setBlock(i + 10, j + 4, k + 11, Block.cobblestone.blockID);
		world.setBlock(i + 10, j + 4, k + 12, Block.cobblestone.blockID);
		world.setBlock(i + 10, j + 4, k + 13, Block.cobblestone.blockID);
		world.setBlock(i + 10, j + 4, k + 14, Block.cobblestone.blockID);
		world.setBlock(i + 10, j + 4, k + 15, Block.cobblestone.blockID);
		world.setBlock(i + 10, j + 4, k + 16, Block.cobblestone.blockID);
		world.setBlock(i + 10, j + 4, k + 17, Block.cobblestone.blockID);
		world.setBlock(i + 10, j + 4, k + 18, Block.cobblestone.blockID);
		world.setBlock(i + 10, j + 4, k + 19, Block.cobblestone.blockID);
		world.setBlock(i + 10, j + 4, k + 20, Block.cobblestone.blockID);
		world.setBlock(i + 10, j + 4, k + 21, Block.cobblestone.blockID);
		world.setBlock(i + 10, j + 4, k + 22, Block.cobblestone.blockID);
		world.setBlock(i + 10, j + 4, k + 23, Block.cobblestone.blockID);
		world.setBlock(i + 10, j + 4, k + 24, Block.cobblestone.blockID);
		world.setBlock(i + 10, j + 4, k + 25, Block.cobblestone.blockID);
		world.setBlock(i + 10, j + 4, k + 26, Block.cobblestone.blockID);
		world.setBlock(i + 10, j + 4, k + 27, Block.cobblestone.blockID);
		world.setBlock(i + 10, j + 4, k + 28, Block.cobblestone.blockID);
		world.setBlock(i + 10, j + 4, k + 29, Block.cobblestone.blockID);
		world.setBlock(i + 10, j + 4, k + 30, Block.cobblestone.blockID);
		world.setBlock(i + 10, j + 4, k + 31, Block.cobblestone.blockID);
		world.setBlock(i + 10, j + 4, k + 32, Block.cobblestone.blockID);
		world.setBlock(i + 10, j + 4, k + 33, Block.cobblestone.blockID);
		world.setBlock(i + 10, j + 4, k + 34, Block.cobblestone.blockID);
		world.setBlock(i + 10, j + 4, k + 35, Block.cobblestone.blockID);
		world.setBlock(i + 10, j + 4, k + 36, Block.cobblestone.blockID);
		world.setBlock(i + 10, j + 4, k + 37, Block.cobblestone.blockID);
		world.setBlock(i + 10, j + 4, k + 38, Block.cobblestone.blockID);
		world.setBlock(i + 10, j + 4, k + 39, Block.cobblestone.blockID);
		world.setBlock(i + 10, j + 4, k + 40, Block.cobblestone.blockID);
		world.setBlock(i + 10, j + 4, k + 41, Block.cobblestone.blockID);
		world.setBlock(i + 10, j + 4, k + 42, Block.cobblestone.blockID);
		world.setBlock(i + 10, j + 4, k + 43, Block.cobblestone.blockID);
		world.setBlock(i + 10, j + 4, k + 44, Block.cobblestone.blockID);
		world.setBlock(i + 10, j + 5, k + 5, Block.cobblestone.blockID);
		world.setBlock(i + 10, j + 5, k + 6, Block.cobblestone.blockID);
		world.setBlock(i + 10, j + 5, k + 7, Block.planks.blockID);
		world.setBlock(i + 10, j + 5, k + 8, Block.planks.blockID);
		world.setBlock(i + 10, j + 5, k + 9, Block.planks.blockID);
		world.setBlock(i + 10, j + 5, k + 10, Block.planks.blockID);
		world.setBlock(i + 10, j + 5, k + 11, Block.planks.blockID);
		world.setBlock(i + 10, j + 5, k + 12, Block.planks.blockID);
		world.setBlock(i + 10, j + 5, k + 13, Block.planks.blockID);
		world.setBlock(i + 10, j + 5, k + 14, Block.cobblestone.blockID);
		world.setBlock(i + 10, j + 5, k + 15, Block.cobblestone.blockID);
		world.setBlock(i + 10, j + 5, k + 16, Block.cobblestone.blockID);
		world.setBlock(i + 10, j + 5, k + 17, Block.cobblestone.blockID);
		world.setBlock(i + 10, j + 5, k + 19, Block.cobblestone.blockID);
		world.setBlock(i + 10, j + 5, k + 20, Block.cobblestone.blockID);
		world.setBlock(i + 10, j + 5, k + 21, Block.cobblestone.blockID);
		world.setBlock(i + 10, j + 5, k + 23, Block.cobblestone.blockID);
		world.setBlock(i + 10, j + 5, k + 24, Block.cobblestone.blockID);
		world.setBlock(i + 10, j + 5, k + 25, Block.cobblestone.blockID);
		world.setBlock(i + 10, j + 5, k + 27, Block.cobblestone.blockID);
		world.setBlock(i + 10, j + 5, k + 28, Block.cobblestone.blockID);
		world.setBlock(i + 10, j + 5, k + 29, Block.cobblestone.blockID);
		world.setBlock(i + 10, j + 5, k + 31, Block.cobblestone.blockID);
		world.setBlock(i + 10, j + 5, k + 32, Block.cobblestone.blockID);
		world.setBlock(i + 10, j + 5, k + 33, Block.cobblestone.blockID);
		world.setBlock(i + 10, j + 5, k + 35, Block.cobblestone.blockID);

		generate2(world, rand, i, j, k);
		return true;
	}

	public boolean generate2(World world, Random rand, int i, int j, int k) {
		world.setBlock(i + 10, j + 5, k + 36, Block.cobblestone.blockID);
